Workbook

Sheet Sheet1
B1: xxx | C1: M2访谈数据/Assumption
B2: xxx | C2: 引用数据
B3: xxx | C3: 计算所得数据

Sheet >现货情境下
B1: xxx | C1: M2访谈数据/Assumption
B2: xxx | C2: 引用数据
B3: xxx | C3: 计算所得数据
D6: h1: 峰有多高由发电量/负荷缺口来决定的（True） | N6: h1: 谷有多低是风光占比决定的（False）
D7: 各省用电量（亿千瓦时） | N7: 各省风光装机量（万千瓦）
B8: 现货开展 | C8: Sum-Ranking 理论峰谷价差高 | D8: 倒RANKING - 发电量 | E8: 省份 | F8: 22年3月电网代购峰谷价差 | G8: 22年4月电网代购峰谷价差 | H8: 2021年各省用电量（亿千瓦时） | I8: 2021年各省GDP（亿元） | J8: 2021年kWh: GDP（kWh/元） | K8: 2021用电量占全国比重 | L8: 2025年 | M8: 2030年 | N8: RANKING-光伏发电占比 | O8: 省份 | P8: 2021年各区域风光总装机量 | Q8: 2021年各区域风光占电源总装机比重 | R8: 2021光伏发电量占本地区电力供应比重% | S8: 2025年
B9: 第一批 | C9: =(D9+N9)^(1/2) -> 7.4161985 | D9: 30 | E9: 广东省 | F9: 0.9545999 | G9: 0.9952 | H9: 7866.63 | I9: 124369.67 | J9: =H9/I9 -> 0.063251997 | K9: 0.098128963 | L9: 9027.8646 | M9: 10499.799 | N9: 25 | O9: 广东省 | P9: 2215 | Q9: 0.141 | R9: 0.017 | S9: 0.2333
C10: =(D10+N10)^(1/2) -> 6.3245553 | D10: 29 | E10: 山东省 | F10: 0.5547 | G10: 0.5502 | H10: 7382.93 | I10: 83095.9 | J10: =H10/I10 -> 0.088848307 | K10: 0.092095251 | L10: 8472.7631 | M10: 9854.1919 | N10: 11 | O10: 山东省 | P10: 5285 | Q10: 0.305 | R10: 0.05 | S10: 0.42
B11: 第一批 | C11: =(D11+N11)^(1/2) -> 6.4807407 | D11: 28 | E11: 江苏省 | F11: 0.8368 | G11: 0.8389 | H11: 7001.16 | I11: 116364.2 | J11: =H11/I11 -> 0.060165927 | K11: 0.087333022 | L11: 8034.638 | M11: 9344.6334 | N11: 14 | O11: 江苏省 | P11: 4150 | Q11: 0.269 | R11: 0.033 | S11: 0.34363636
C12: =(D12+N12)^(1/2) -> 6.78233 | D12: 27 | E12: 浙江省 | F12: 0.5915 | G12: 0.622 | H12: 5514.11 | I12: 73516 | J12: =H12/I12 -> 0.075005577 | K12: 0.068783443 | L12: 6328.0768 | M12: 7359.8284 | N12: 19 | O12: 浙江省 | P12: 2206 | Q12: 0.204 | R12: 0.037 | S12: 0.36
C13: =(D13+N13)^(1/2) -> 5.5677644 | D13: 26 | E13: 内蒙古自治区 | F13: 0.598588 | G13: 0.590095 | H13: 4154.98 | I13: 20514.2 | J13: =H13/I13 -> 0.20254165 | K13: 0.051829548 | L13: 4768.3184 | M13: 5545.7617 | N13: 5 | O13: 内蒙古自治区 | P13: 5408 | Q13: 0.349 | R13: 0.035 | S13: 0.622
B14: 第二批 | C14: =(D14+N14)^(1/2) -> 5.9160798 | D14: 25 | E14: 河南省 | F14: 0.661431 | G14: 0.665818 | H14: 3646.91 | I14: 58887.41 | J14: =H14/I14 -> 0.061930216 | K14: 0.045491843 | L14: 4185.2496 | M14: 4867.6272 | N14: 10 | O14: 河南省 | P14: 3406 | Q14: 0.306 | R14: 0.046 | S14: 0.3846
B15: 第一批 | C15: =(D15+N15)^(1/2) -> 7.3484692 | D15: 24 | E15: 四川省 | F15: 0.78948 | G15: 0.792 | H15: 3274.81 | I15: 53850.79 | J15: =H15/I15 -> 0.060812664 | K15: 0.040850238 | L15: 3758.2219 | M15: 4370.9755 | N15: 30 | O15: 四川省 | P15: 723 | Q15: 0.063 | R15: 0.007 | S15: 0.1467
B16: 第一批-蒙西 | C16: =(D16+N16)^(1/2) -> 6.78233 | D16: 23 | E16: 福建省 | F16: 0.5681 | G16: 0.5653 | H16: 2836.66 | I16: 48810 | J16: =H16/I16 -> 0.05811637 | K16: 0.035384721 | L16: 3255.3943 | M16: 3786.1651 | N16: 23 | O16: 福建省 | P16: 1012 | Q16: 0.145 | R16: 0.009 | S16: 0.23
C17: =(D17+N17)^(1/2) -> 5.2915026 | D17: 22 | E17: 新疆维吾尔自治区 | F17: 0 | G17: 0 | H17: 2734.18 | I17: 16000 | J17: =H17/I17 -> 0.17088625 | K17: 0.034106377 | L17: 3137.7867 | M17: 3649.3823 | N17: 6 | O17: 新疆省 | P17: 3762 | Q17: 0.326 | R17: 0.044 | S17: 0.38
B18: 第二批 | C18: =(D18+N18)^(1/2) -> 6 | D18: 21 | E18: 安徽省 | F18: 0.8279 | G18: 0.8279 | H18: 2715.47 | I18: 42959.2 | J18: =H18/I18 -> 0.063210442 | K18: 0.033872987 | L18: 3116.3148 | M18: 3624.4096 | N18: 15 | O18: 安徽省 | P18: 2218 | Q18: 0.262 | R18: 0.051 | S18: 0.4
B19: 第一批 | C19: =(D19+N19)^(1/2) -> 6 | D19: 20 | E19: 山西省 | F19: 0.64983 | G19: 0.511179 | H19: 2607.91 | I19: 22590.16 | J19: =H19/I19 -> 0.11544451 | K19: 0.032531275 | L19: 2992.8773 | M19: 3480.8464 | N19: 16 | O19: 山西省 | P19: 1565 | Q19: 0.253 | R19: 0.026 | S19: 0.4
C20: =(D20+N20)^(1/2) -> 5.1961524 | D20: 19 | E20: 辽宁省 | F20: 0.553506 | G20: 0.64485 | H20: 2575.61 | I20: 27584.1 | J20: =H20/I20 -> 0.093372994 | K20: 0.032128362 | L20: 2955.8093 | M20: 3437.7348 | N20: 8 | O20: 辽宁省 | P20: 3581 | Q20: 0.316 | R20: 0.049 | S20: 0.5
B21: 第二批 | C21: =(D21+N21)^(1/2) -> 6.244998 | D21: 18 | E21: 湖北省 | F21: 0.712151 | G21: 0.671852 | H21: 2470.76 | I21: 50012.94 | J21: =H21/I21 -> 0.049402415 | K21: 0.030820455 | L21: 2835.4819 | M21: 3297.7887 | N21: 21 | O21: 湖北省 | P21: 1673 | Q21: 0.19 | R21: 0.025 | S21: 0.25
C22: =(D22+N22)^(1/2) -> 4.3588989 | D22: 17 | E22: 河北省 | F22: 0.4052 | G22: 0.4024 | H22: 2431.43 | I22: 40391.3 | J22: =H22/I22 -> 0.060196874 | K22: 0.03032985 | L22: 2790.3462 | M22: 3245.2939 | N22: 2 | O22: 河北省 | P22: 5467 | Q22: 0.494 | R22: 0.091 | S22: 0.55
C23: =(D23+N23)^(1/2) -> 6 | D23: 16 | E23: 广西壮族自治区 | F23: 0.558375 | G23: 0.576575 | H23: 2236.23 | I23: 24740.86 | J23: =H23/I23 -> 0.090386106 | K23: 0.027894909 | L23: 2566.3317 | M23: 2984.7553 | N23: 20 | O23: 广西壮族自治区 | P23: 1053 | Q23: 0.192 | R23: 0.014 | S23: 0.51
B24: 第一批 | C24: =(D24+N24)^(1/2) -> 5.6568542 | D24: 15 | E24: 湖南省 | F24: 0.83305 | G24: 0.576575 | H24: 2154.54 | I24: 46063.09 | J24: =H24/I24 -> 0.046773675 | K24: 0.026875902 | L24: 2472.583 | M24: 2875.7215 | N24: 17 | O24: 湖南省 | P24: 1254 | Q24: 0.234 | R24: 0.022 | S24: 0.57
C25: =(D25+N25)^(1/2) -> 6.3245553 | D25: 14 | E25: 云南省 | F25: 0.46815 | G25: 0.46815 | H25: 2138.25 | I25: 27100 | J25: =H25/I25 -> 0.078902214 | K25: 0.026672699 | L25: 2453.8883 | M25: 2853.9788 | N25: 26 | O25: 云南省 | P25: 1278 | Q25: 0.12 | R25: 0.014 | S25: 0.26
C26: =(D26+N26)^(1/2) -> 5 | D26: 13 | E26: 江西省 | F26: 0.388656 | G26: 0.388656 | H26: 1862.52 | I26: 29619.7 | J26: =H26/I26 -> 0.062881123 | K26: 0.023233221 | L26: 2137.4564 | M26: 2485.9547 | N26: 12 | O26: 江西省 | P26: 1458 | Q26: 0.301 | R26: 0.049 | S26: 0.475
C27: =(D27+N27)^(1/2) -> 6.244998 | D27: 12 | E27: 上海市 | F27: 0.5039 | G27: 0.4931 | H27: 1749.62 | I27: 43214.85 | J27: =H27/I27 -> 0.040486546 | K27: 0.021824898 | L27: 2007.8906 | M27: 2335.2641 | N27: 27 | O27: 上海市 | P27: 275 | Q27: 0.098 | R27: 0.015 | S27: 0.17
C28: =(D28+N28)^(1/2) -> 5.3851648 | D28: 11 | E28: 贵州省 | F28: 0 | G28: 0 | H28: 1742.75 | I28: 19586.42 | J28: =H28/I28 -> 0.088977465 | K28: 0.021739201 | L28: 2000.0065 | M28: 2326.0945 | N28: 18 | O28: 贵州省 | P28: 1717 | Q28: 0.227 | R28: 0.034 | S28: 0.4
B29: 第二批 | C29: =(D29+N29)^(1/2) -> 4.3588989 | D29: 10 | E29: 陕西省 | F29: 0.5414 | G29: 0.5261 | H29: 1736.73 | I29: 29800.98 | J29: =H29/I29 -> 0.058277614 | K29: 0.021664107 | L29: 1993.0978 | M29: 2318.0594 | N29: 9 | O29: 陕西省 | P29: 2335 | Q29: 0.306 | R29: 0.051 | S29: 0.5
B30: 第一批 | C30: =(D30+N30)^(1/2) -> 3.4641016 | D30: 9 | E30: 甘肃省 | F30: 0.2563 | G30: 0.356 | H30: 1494.7 | I30: 10243.3 | J30: =H30/I30 -> 0.14591977 | K30: 0.018645006 | L30: 1715.3405 | M30: 1995.0156 | N30: 3 | O30: 甘肃省 | P30: 2871 | Q30: 0.466 | R30: 0.078 | S30: 0.65
B31: 第二批 | C31: =(D31+N31)^(1/2) -> 6.0827625 | D31: 8 | E31: 北京市 | F31: 0.632901 | G31: 0.57259 | H31: 1232.92 | I31: 40269.6 | J31: =H31/I31 -> 0.030616644 | K31: 0.015379541 | L31: 1414.9178 | M31: 1645.6109 | N31: 29 | O31: 北京市 | P31: 104 | Q31: 0.078 | R31: 0.013 | S31: 0.14
C32: =(D32+N32)^(1/2) -> 5.9160798 | D32: 7 | E32: 重庆市 | F32: 0.784269 | G32: 0.75874 | H32: 1167.55 | I32: 27894.02 | J32: =H32/I32 -> 0.041856642 | K32: 0.014564111 | L32: 1339.8982 | M32: 1558.3599 | N32: 28 | O32: 重庆市 | P32: 228 | Q32: 0.09 | R32: 0.005 | S32: 0.193
C33: =(D33+N33)^(1/2) -> 3.1622777 | D33: 6 | E33: 宁夏回族自治区 | F33: 0.3942 | G33: 0.4682 | H33: 1158.49 | I33: 4522.3 | J33: =H33/I33 -> 0.25617274 | K33: 0.014451096 | L33: 1329.5008 | M33: 1546.2672 | N33: 4 | O33: 宁夏回族自治区 | P33: 2839 | Q33: 0.457 | R33: 0.092 | S33: 0.5
C34: =(D34+N34)^(1/2) -> 3.4641016 | D34: 5 | E34: 黑龙江省 | F34: 0.721331 | G34: 0.721065 | H34: 1088.75 | I34: 14879.2 | J34: =H34/I34 -> 0.073172617 | K34: 0.013581153 | L34: 1249.4661 | M34: 1453.1834 | N34: 7 | O34: 黑龙江省 | P34: 1255 | Q34: 0.317 | R34: 0.045 | S34: 0.5
C35: =(D35+N35)^(1/2) -> 5.2915026 | D35: 4 | E35: 天津市 | F35: 0.6485 | G35: 0.6475 | H35: 982.29 | I35: 15695.05 | J35: =H35/I35 -> 0.062585975 | K35: 0.012253163 | L35: 1127.291 | M35: 1311.0884 | N35: 24 | O35: 天津市 | P35: 308 | Q35: 0.141 | R35: 0.026 | S35: 0.3
C36: =(D36+N36)^(1/2) -> 2 | D36: 3 | E36: 青海省 | F36: 0.148995 | G36: 0.298368 | H36: 857.64 | I36: 3346.63 | J36: =H36/I36 -> 0.25626974 | K36: 0.010698269 | L36: 984.24075 | M36: 1144.7148 | N36: 1 | O36: 青海省 | P36: 2528 | Q36: 0.615 | R36: 0.213 | S36: 0.67
C37: =(D37+N37)^(1/2) -> 3.8729833 | D37: 2 | E37: 吉林省 | F37: 0.71114 | G37: 0.71106 | H37: 843.18 | I37: 13235.52 | J37: =H37/I37 -> 0.063705846 | K37: 0.010517894 | L37: 967.64623 | M37: 1125.4146 | N37: 13 | O37: 吉林省 | P37: 1011 | Q37: 0.29 | R37: 0.053 | S37: 0.224
B38: 第一批 | C38: =(D38+N38)^(1/2) -> 4.7958315 | D38: 1 | E38: 海南省 | F38: 0.8417 | G38: 0.8489 | H38: 405.47 | I38: 6475.2 | J38: =H38/I38 -> 0.062618915 | K38: 0.0050578648 | L38: 465.32356 | M38: 541.19153 | N38: 22 | O38: 海南省 | P38: 176 | Q38: 0.166 | R38: 0.041 | S38: 0.3
K40: 高：用电量占全国比重>4.1% | O40: 高：2025年风光装机占本地电力总装机量比重>40%
K41: 中：2.6-4.1% | O41: 中：20~40%
K42: 低：<2.6% | O42: 低：<20%

Sheet 表后_现货价差高
B1: xxx | C1: M2访谈数据/Assumption
B2: xxx | C2: 引用数据
B3: xxx | C3: 计算所得数据
C4: 自变量 | D4: *表后用户侧储能主要通过现货形式进行峰谷套利，收益部分由峰负荷时的用户分摊
C5: 支出项 | D5: 关键假设：
C6: 收入项 | D6: 1）电池充放电循环次数~6525次
D7: 2）PCS成本：0.21元/W；电池充放电循环次数~6525次；容量型储能电站运维费用：0.1%；PCS效率：98%；线损：98%；系统使用天数：350天；充放循环次数（1次为1充1放）(次/天）：1次
B8: 更新处：标绿色的单元格 | D8: 3）充放策略：一充一放（1*谷-1*峰）
B11: 基本数据 | E11: 计算结果
B12: 充放策略：一充一放（1*谷-1*峰） | E12: LCOS（元/kWh) | F12: =F43 -> 0.65629663
B13: 谷 | C13: 1 | E13: 投资回报率 | F13: =F48 -> -0.25538842
B14: 平 | C14: 0 | E14: NPV(折现率=7%） | F14: =SUM(F47:O47) -> -3.1165991 | H14: 价差为0.8时： | I14: 0.096140341
B15: 峰 | C15: =C13+C14 -> 1 | E15: IRR | F15: =V48 -> 0.023663328 | H15: 价差为0.7时： | I15: 0.074401405
B16: 基本数据 | E16: 折现率 | F16: 0.07 | U16: 折现率 | V16: 0
B17: PCS(KW） | C17: 1200 | E17: 所得税率 | F17: 0.25 | U17: 所得税率 | V17: 0.25
B18: PCS成本（元/kW) | C18: 210 | E18: 增值税率 | F18: 0 | G18: 暂不考虑 | U18: 增值税率 | V18: 0 | W18: 暂不考虑
B19: ESS(KWh) | C19: 4800 | E19: 储能系统经济效益估算表（元） | U19: 储能系统经济效益估算表（元）
B20: ESS成本（元/kWh) | C20: 1400 | E20: 储能平准化成本LCOS（Levelized Cost of Storage） | G20: 1 | H20: 2 | I20: 3 | J20: 4 | K20: 5 | L20: 6 | M20: 7 | N20: 8 | O20: 9 | P20: 10 | Q20: 11 | R20: 12 | S20: 13 | U20: 储能平准化成本LCOS（Levelized Cost of Storage） | W20: 1 | X20: 2 | Y20: 3 | Z20: 4 | AA20: 5 | AB20: 6 | AC20: 7 | AD20: 8 | AE20: 9 | AF20: 10 | AG20: 11 | AH20: 12 | AI20: 13
B21: PCS效率 | C21: 0.98 | F21: 基准年 | G21: 第1年 | H21: 第2年 | I21: 第3年 | J21: 第4年 | K21: 第5年 | L21: 第6年 | M21: 第7年 | N21: 第8年 | O21: 第9年 | P21: 第10年 | Q21: 第11年 | R21: 第12年 | S21: 第13年 | V21: 基准年 | W21: 第1年 | X21: 第2年 | Y21: 第3年 | Z21: 第4年 | AA21: 第5年 | AB21: 第6年 | AC21: 第7年 | AD21: 第8年 | AE21: 第9年 | AF21: 第10年 | AG21: 第11年 | AH21: 第12年 | AI21: 第13年
B22: 线损 | C22: 0.98 | E22: 初始投资成本（Mn RMB） | F22: =C46/1000000 -> 7.442 | U22: 初始投资成本（Mn RMB） | V22: =C46/1000000 -> 7.442
B23: 峰价（元/KWh) | C23: 0.6 | E23: 折旧现值和（Mn RMB） | F23: =SUM(G24:S24) -> 3.1183056 | U23: 折旧现值和（Mn RMB） | V23: =SUM(W24:AI24) -> 4.8504028
B24: 平价（元/KWh) | C24: 0 | E24: 折旧现值（Mn RMB） | G24: =($C$41+$C$42+$C$32)*(1-$C$35)/$C$40/1000000/(1+$F$16)^G20 -> 0.34869898 | H24: =($C$41+$C$42+$C$32)*(1-$C$35)/$C$40/1000000/(1+$F$16)^H20 -> 0.3258869 | I24: =($C$41+$C$42+$C$32)*(1-$C$35)/$C$40/1000000/(1+$F$16)^I20 -> 0.30456719 | J24: =($C$41+$C$42+$C$32)*(1-$C$35)/$C$40/1000000/(1+$F$16)^J20 -> 0.28464224 | K24: =($C$41+$C$42+$C$32)*(1-$C$35)/$C$40/1000000/(1+$F$16)^K20 -> 0.26602078 | L24: =($C$41+$C$42+$C$32)*(1-$C$35)/$C$40/1000000/(1+$F$16)^L20 -> 0.24861755 | M24: =($C$41+$C$42+$C$32)*(1-$C$35)/$C$40/1000000/(1+$F$16)^M20 -> 0.23235285 | N24: =($C$41+$C$42+$C$32)*(1-$C$35)/$C$40/1000000/(1+$F$16)^N20 -> 0.2171522 | ... S24: =($C$41+$C$42+$C$32)*(1-$C$35)/$C$40/1000000/(1+$F$16)^S20 -> 0.15482652 | U24: 折旧现值（Mn RMB） | W24: =($C$41+$C$42+$C$32)*(1-$C$35)/$C$40/1000000/(1+$V$16)^W20 -> 0.37310791 | X24: =($C$41+$C$42+$C$32)*(1-$C$35)/$C$40/1000000/(1+$V$16)^X20 -> 0.37310791 | Y24: =($C$41+$C$42+$C$32)*(1-$C$35)/$C$40/1000000/(1+$V$16)^Y20 -> 0.37310791 | Z24: =($C$41+$C$42+$C$32)*(1-$C$35)/$C$40/1000000/(1+$V$16)^Z20 -> 0.37310791 | AA24: =($C$41+$C$42+$C$32)*(1-$C$35)/$C$40/1000000/(1+$V$16)^AA20 -> 0.37310791 | AB24: =($C$41+$C$42+$C$32)*(1-$C$35)/$C$40/1000000/(1+$V$16)^AB20 -> 0.37310791 | AC24: =($C$41+$C$42+$C$32)*(1-$C$35)/$C$40/1000000/(1+$V$16)^AC20 -> 0.37310791 | AD24: =($C$41+$C$42+$C$32)*(1-$C$35)/$C$40/1000000/(1+$V$16)^AD20 -> 0.37310791 | ... AI24: =($C$41+$C$42+$C$32)*(1-$C$35)/$C$40/1000000/(1+$V$16)^AI20 -> 0.37310791
B25: 谷价（元/KWh) | C25: 0 | E25: 运行成本现值和（Mn RMB） | F25: =SUM(G26:S26) -> 0.062197637 | U25: 运行成本现值和（Mn RMB） | V25: =SUM(W26:AI26) -> 0.096746
B26: 系统年使用天数 (天) | C26: 350 | E26: 运行成本现值（Mn RMB） | G26: =($C$34*$F$22)/((1+$F$16)^G20) -> 0.0069551402 | H26: =($C$34*$F$22)/((1+$F$16)^H20) -> 0.006500131 | I26: =($C$34*$F$22)/((1+$F$16)^I20) -> 0.0060748888 | J26: =($C$34*$F$22)/((1+$F$16)^J20) -> 0.0056774662 | K26: =($C$34*$F$22)/((1+$F$16)^K20) -> 0.0053060431 | L26: =($C$34*$F$22)/((1+$F$16)^L20) -> 0.0049589188 | M26: =($C$34*$F$22)/((1+$F$16)^M20) -> 0.0046345036 | N26: =($C$34*$F$22)/((1+$F$16)^N20) -> 0.0043313118 | ... S26: =($C$34*$F$22)/((1+$F$16)^S20) -> 0.0030881654 | U26: 运行成本现值（Mn RMB） | W26: =($C$34*$V$22)/((1+$V$16)^W20) -> 0.007442 | X26: =($C$34*$V$22)/((1+$V$16)^X20) -> 0.007442 | Y26: =($C$34*$V$22)/((1+$V$16)^Y20) -> 0.007442 | Z26: =($C$34*$V$22)/((1+$V$16)^Z20) -> 0.007442 | AA26: =($C$34*$V$22)/((1+$V$16)^AA20) -> 0.007442 | AB26: =($C$34*$V$22)/((1+$V$16)^AB20) -> 0.007442 | AC26: =($C$34*$V$22)/((1+$V$16)^AC20) -> 0.007442 | AD26: =($C$34*$V$22)/((1+$V$16)^AD20) -> 0.007442 | ... AI26: =($C$34*$V$22)/((1+$V$16)^AI20) -> 0.007442
B27: DOD% | C27: 0.95 | E27: 固定资产残值现值 (Mn RMB) | S27: =(C41+C42)*C35/((1+F16)^S20)/1000000 -> 0.14465661 | U27: 固定资产残值现值 (Mn RMB) | AI27: =(C41+C42)*C35/((1+V16)^AI20)/1000000 -> 0.3486
B28: 单次循环衰减率 | C28: 4.68e-05 | E28: 充电电量现值和(KWh) | F28: =SUM(G29:S29) -> 13339597 | U28: 充电电量现值和(KWh) | V28: =SUM(W29:AI29) -> 20435477
B29: 系统报废终止标准 | C29: 0.7 | E29: 充电电量现值(KWh) | G29: =$C$19*$C$36*$C$26/$C$37*($C$27*(1-$C$28)^((G20-1)*$C$26*$C$36))/$C$21/$C$22/((1+$F$16)^G20) -> 1617803.3 | H29: =$C$19*$C$36*$C$26/$C$37*($C$27*(1-$C$28)^((H20-1)*$C$26*$C$36))/$C$21/$C$22/((1+$F$16)^H20) -> 1487400.9 | I29: =$C$19*$C$36*$C$26/$C$37*($C$27*(1-$C$28)^((I20-1)*$C$26*$C$36))/$C$21/$C$22/((1+$F$16)^I20) -> 1367509.5 | J29: =$C$19*$C$36*$C$26/$C$37*($C$27*(1-$C$28)^((J20-1)*$C$26*$C$36))/$C$21/$C$22/((1+$F$16)^J20) -> 1257281.9 | K29: =$C$19*$C$36*$C$26/$C$37*($C$27*(1-$C$28)^((K20-1)*$C$26*$C$36))/$C$21/$C$22/((1+$F$16)^K20) -> 1155939.2 | L29: =$C$19*$C$36*$C$26/$C$37*($C$27*(1-$C$28)^((L20-1)*$C$26*$C$36))/$C$21/$C$22/((1+$F$16)^L20) -> 1062765.1 | M29: =$C$19*$C$36*$C$26/$C$37*($C$27*(1-$C$28)^((M20-1)*$C$26*$C$36))/$C$21/$C$22/((1+$F$16)^M20) -> 977101.32 | N29: =$C$19*$C$36*$C$26/$C$37*($C$27*(1-$C$28)^((N20-1)*$C$26*$C$36))/$C$21/$C$22/((1+$F$16)^N20) -> 898342.43 | ... S29: =$C$19*$C$36*$C$26/$C$37*($C$27*(1-$C$28)^((S20-1)*$C$26*$C$36))/$C$21/$C$22/((1+$F$16)^S20) -> 590137.85 | U29: 充电电量现值(KWh) | W29: =$C$19*$C$36*$C$26/$C$37*($C$27*(1-$C$28)^((W20-1)*$C$26*$C$36))/$C$21/$C$22/((1+$V$16)^W20) -> 1731049.6 | X29: =$C$19*$C$36*$C$26/$C$37*($C$27*(1-$C$28)^((X20-1)*$C$26*$C$36))/$C$21/$C$22/((1+$V$16)^X20) -> 1702925.3 | Y29: =$C$19*$C$36*$C$26/$C$37*($C$27*(1-$C$28)^((Y20-1)*$C$26*$C$36))/$C$21/$C$22/((1+$V$16)^Y20) -> 1675257.9 | Z29: =$C$19*$C$36*$C$26/$C$37*($C$27*(1-$C$28)^((Z20-1)*$C$26*$C$36))/$C$21/$C$22/((1+$V$16)^Z20) -> 1648040.1 | AA29: =$C$19*$C$36*$C$26/$C$37*($C$27*(1-$C$28)^((AA20-1)*$C$26*$C$36))/$C$21/$C$22/((1+$V$16)^AA20) -> 1621264.5 | AB29: =$C$19*$C$36*$C$26/$C$37*($C$27*(1-$C$28)^((AB20-1)*$C$26*$C$36))/$C$21/$C$22/((1+$V$16)^AB20) -> 1594923.8 | AC29: =$C$19*$C$36*$C$26/$C$37*($C$27*(1-$C$28)^((AC20-1)*$C$26*$C$36))/$C$21/$C$22/((1+$V$16)^AC20) -> 1569011.2 | AD29: =$C$19*$C$36*$C$26/$C$37*($C$27*(1-$C$28)^((AD20-1)*$C$26*$C$36))/$C$21/$C$22/((1+$V$16)^AD20) -> 1543519.5 | ... AI29: =$C$19*$C$36*$C$26/$C$37*($C$27*(1-$C$28)^((AI20-1)*$C$26*$C$36))/$C$21/$C$22/((1+$V$16)^AI20) -> 1422140.8
B30: 土建成本(元/Wh) | C30: 0.015 | E30: 放电电量现值和(KWh) | F30: =SUM(G31:S31) -> 11339385 | U30: 放电电量现值和(KWh) | V30: =SUM(W31:AI31) -> 17371269
B31: 土建残值率（%） | C31: 0 | E31: 放电电量现值(KWh) | G31: =$C$19*$C$36*$C$26*$C$37*($C$27*(1-$C$28)^((G20-1)*$C$26*$C$36))*$C$21*$C$22/((1+$F$16)^G20) -> 1375221 | H31: =$C$19*$C$36*$C$26*$C$37*($C$27*(1-$C$28)^((H20-1)*$C$26*$C$36))*$C$21*$C$22/((1+$F$16)^H20) -> 1264371.8 | I31: =$C$19*$C$36*$C$26*$C$37*($C$27*(1-$C$28)^((I20-1)*$C$26*$C$36))*$C$21*$C$22/((1+$F$16)^I20) -> 1162457.6 | J31: =$C$19*$C$36*$C$26*$C$37*($C$27*(1-$C$28)^((J20-1)*$C$26*$C$36))*$C$21*$C$22/((1+$F$16)^J20) -> 1068758.1 | K31: =$C$19*$C$36*$C$26*$C$37*($C$27*(1-$C$28)^((K20-1)*$C$26*$C$36))*$C$21*$C$22/((1+$F$16)^K20) -> 982611.27 | L31: =$C$19*$C$36*$C$26*$C$37*($C$27*(1-$C$28)^((L20-1)*$C$26*$C$36))*$C$21*$C$22/((1+$F$16)^L20) -> 903408.26 | M31: =$C$19*$C$36*$C$26*$C$37*($C$27*(1-$C$28)^((M20-1)*$C$26*$C$36))*$C$21*$C$22/((1+$F$16)^M20) -> 830589.37 | N31: =$C$19*$C$36*$C$26*$C$37*($C$27*(1-$C$28)^((N20-1)*$C$26*$C$36))*$C$21*$C$22/((1+$F$16)^N20) -> 763640.02 | ... S31: =$C$19*$C$36*$C$26*$C$37*($C$27*(1-$C$28)^((S20-1)*$C$26*$C$36))*$C$21*$C$22/((1+$F$16)^S20) -> 501649.33 | U31: 放电电量现值(KWh) | W31: =$C$19*$C$36*$C$26*$C$37*($C$27*(1-$C$28)^((W20-1)*$C$26*$C$36))*$C$21*$C$22/((1+$V$16)^W20) -> 1471486.5 | X31: =$C$19*$C$36*$C$26*$C$37*($C$27*(1-$C$28)^((X20-1)*$C$26*$C$36))*$C$21*$C$22/((1+$V$16)^X20) -> 1447579.3 | Y31: =$C$19*$C$36*$C$26*$C$37*($C$27*(1-$C$28)^((Y20-1)*$C$26*$C$36))*$C$21*$C$22/((1+$V$16)^Y20) -> 1424060.5 | Z31: =$C$19*$C$36*$C$26*$C$37*($C$27*(1-$C$28)^((Z20-1)*$C$26*$C$36))*$C$21*$C$22/((1+$V$16)^Z20) -> 1400923.9 | AA31: =$C$19*$C$36*$C$26*$C$37*($C$27*(1-$C$28)^((AA20-1)*$C$26*$C$36))*$C$21*$C$22/((1+$V$16)^AA20) -> 1378163.1 | AB31: =$C$19*$C$36*$C$26*$C$37*($C$27*(1-$C$28)^((AB20-1)*$C$26*$C$36))*$C$21*$C$22/((1+$V$16)^AB20) -> 1355772.2 | AC31: =$C$19*$C$36*$C$26*$C$37*($C$27*(1-$C$28)^((AC20-1)*$C$26*$C$36))*$C$21*$C$22/((1+$V$16)^AC20) -> 1333745 | AD31: =$C$19*$C$36*$C$26*$C$37*($C$27*(1-$C$28)^((AD20-1)*$C$26*$C$36))*$C$21*$C$22/((1+$V$16)^AD20) -> 1312075.7 | ... AI31: =$C$19*$C$36*$C$26*$C$37*($C$27*(1-$C$28)^((AI20-1)*$C$26*$C$36))*$C$21*$C$22/((1+$V$16)^AI20) -> 1208897.1
B32: 其它设备投资费用（升压变等） | C32: 350000 | E32: 充电成本现值和（Mn RMB） | F32: =SUM(G33:S33) -> 0 | U32: 充电成本现值和（Mn RMB） | V32: =SUM(W33:AI33) -> 0
B33: 其它成本：入网检测费、项目管理费等（元/Wh） | C33: 0.01 | E33: 充电成本现值（Mn RMB） | G33: =($C$13*$C$25*G29/($C$13+$C$14)+$C$14*$C$24*G29/($C$13+$C$14))/1000000 -> 0 | H33: =($C$13*$C$25*H29/($C$13+$C$14)+$C$14*$C$24*H29/($C$13+$C$14))/1000000 -> 0 | I33: =($C$13*$C$25*I29/($C$13+$C$14)+$C$14*$C$24*I29/($C$13+$C$14))/1000000 -> 0 | J33: =($C$13*$C$25*J29/($C$13+$C$14)+$C$14*$C$24*J29/($C$13+$C$14))/1000000 -> 0 | K33: =($C$13*$C$25*K29/($C$13+$C$14)+$C$14*$C$24*K29/($C$13+$C$14))/1000000 -> 0 | L33: =($C$13*$C$25*L29/($C$13+$C$14)+$C$14*$C$24*L29/($C$13+$C$14))/1000000 -> 0 | M33: =($C$13*$C$25*M29/($C$13+$C$14)+$C$14*$C$24*M29/($C$13+$C$14))/1000000 -> 0 | N33: =($C$13*$C$25*N29/($C$13+$C$14)+$C$14*$C$24*N29/($C$13+$C$14))/1000000 -> 0 | ... S33: =($C$13*$C$25*S29/($C$13+$C$14)+$C$14*$C$24*S29/($C$13+$C$14))/1000000 -> 0 | U33: 充电成本现值（Mn RMB） | W33: =($C$13*$C$25*W29/($C$13+$C$14)+$C$14*$C$24*W29/($C$13+$C$14))/1000000 -> 0 | X33: =($C$13*$C$25*X29/($C$13+$C$14)+$C$14*$C$24*X29/($C$13+$C$14))/1000000 -> 0 | Y33: =($C$13*$C$25*Y29/($C$13+$C$14)+$C$14*$C$24*Y29/($C$13+$C$14))/1000000 -> 0 | Z33: =($C$13*$C$25*Z29/($C$13+$C$14)+$C$14*$C$24*Z29/($C$13+$C$14))/1000000 -> 0 | AA33: =($C$13*$C$25*AA29/($C$13+$C$14)+$C$14*$C$24*AA29/($C$13+$C$14))/1000000 -> 0 | AB33: =($C$13*$C$25*AB29/($C$13+$C$14)+$C$14*$C$24*AB29/($C$13+$C$14))/1000000 -> 0 | AC33: =($C$13*$C$25*AC29/($C$13+$C$14)+$C$14*$C$24*AC29/($C$13+$C$14))/1000000 -> 0 | AD33: =($C$13*$C$25*AD29/($C$13+$C$14)+$C$14*$C$24*AD29/($C$13+$C$14))/1000000 -> 0 | ... AI33: =($C$13*$C$25*AI29/($C$13+$C$14)+$C$14*$C$24*AI29/($C$13+$C$14))/1000000 -> 0
B34: 容量型储能电站运维费用 | C34: 0.001 | E34: 放电收益现值和（Mn RMB） | F34: =SUM(G35:S35) -> 6.8036309 | U34: 放电收益现值和（Mn RMB） | V34: =SUM(W35:AI35) -> 10.422762
B35: 储能系统残值 | C35: 0.05 | E35: 放电收益现值（Mn RMB） | G35: =G31*$C$23/1000000 -> 0.8251326 | H35: =H31*$C$23/1000000 -> 0.75862309 | I35: =I31*$C$23/1000000 -> 0.69747456 | J35: =J31*$C$23/1000000 -> 0.64125488 | K35: =K31*$C$23/1000000 -> 0.58956676 | L35: =L31*$C$23/1000000 -> 0.54204495 | M35: =M31*$C$23/1000000 -> 0.49835362 | N35: =N31*$C$23/1000000 -> 0.45818401 | ... S35: =S31*$C$23/1000000 -> 0.3009896 | U35: 放电收益现值（Mn RMB） | W35: =W31*$C$23/1000000 -> 0.88289188 | X35: =X31*$C$23/1000000 -> 0.86854757 | Y35: =Y31*$C$23/1000000 -> 0.85443632 | Z35: =Z31*$C$23/1000000 -> 0.84055433 | AA35: =AA31*$C$23/1000000 -> 0.82689789 | AB35: =AB31*$C$23/1000000 -> 0.81346331 | AC35: =AC31*$C$23/1000000 -> 0.80024701 | AD35: =AD31*$C$23/1000000 -> 0.78724544 | ... AI35: =AI31*$C$23/1000000 -> 0.72533828
B36: 充放循环次数（1次为1充1放）(次/天） | C36: =C13+C14 -> 1 | E36: 所得税现值和（Mn RMB） | F36: =SUM(G37:S37) -> 0.90578192 | U36: 所得税现值和（Mn RMB） | V36: =SUM(W37:AI37) -> 1.3689032
B37: 充放电效率RTE（%） | C37: 0.96 | E37: 所得税现值（Mn RMB） | G37: =(G35-G33-G26-G24)*$F$17 -> 0.11736962 | H37: =(H35-H33-H26-H24)*$F$17 -> 0.10655902 | I37: =(I35-I33-I26-I24)*$F$17 -> 0.096708118 | J37: =(J35-J33-J26-J24)*$F$17 -> 0.087733794 | K37: =(K35-K33-K26-K24)*$F$17 -> 0.079559985 | L37: =(L35-L33-L26-L24)*$F$17 -> 0.07211712 | M37: =(M35-M33-M26-M24)*$F$17 -> 0.065341566 | N37: =(N35-N33-N26-N24)*$F$17 -> 0.059175125 | ... S37: =(S35-S33-S26-S24)*$F$17 -> 0.03576873 | U37: 所得税现值（Mn RMB） | W37: =(W35-W33-W26-W24)*$V$17 -> 0.12558549 | X37: =(X35-X33-X26-X24)*$V$17 -> 0.12199942 | Y37: =(Y35-Y33-Y26-Y24)*$V$17 -> 0.1184716 | Z37: =(Z35-Z33-Z26-Z24)*$V$17 -> 0.11500111 | AA37: =(AA35-AA33-AA26-AA24)*$V$17 -> 0.11158699 | AB37: =(AB35-AB33-AB26-AB24)*$V$17 -> 0.10822835 | AC37: =(AC35-AC33-AC26-AC24)*$V$17 -> 0.10492428 | AD37: =(AD35-AD33-AD26-AD24)*$V$17 -> 0.10167388 | ... AI37: =(AI35-AI33-AI26-AI24)*$V$17 -> 0.086197094
B38: 用户分成比例（%） | C38: 0.1 | E38: 增值税现值和（Mn RMB） | F38: =SUM(G39:S39) -> 0 | U38: 增值税现值和（Mn RMB） | V38: =SUM(W39:AI39) -> 0
B39: 充放循环总次数（次数） | C39: =LOG(C29/C27,(1-C28)) -> 6525.0962 | E39: 增值税现值（Mn RMB） | G39: =(G35-G33)*$F$18 -> 0 | H39: =(H35-H33)*$F$18 -> 0 | I39: =(I35-I33)*$F$18 -> 0 | J39: =(J35-J33)*$F$18 -> 0 | K39: =(K35-K33)*$F$18 -> 0 | L39: =(L35-L33)*$F$18 -> 0 | M39: =(M35-M33)*$F$18 -> 0 | N39: =(N35-N33)*$F$18 -> 0 | ... S39: =(S35-S33)*$F$18 -> 0 | U39: 增值税现值（Mn RMB） | W39: =(W35-W33)*$V$18 -> 0 | X39: =(X35-X33)*$V$18 -> 0 | Y39: =(Y35-Y33)*$V$18 -> 0 | Z39: =(Z35-Z33)*$V$18 -> 0 | AA39: =(AA35-AA33)*$V$18 -> 0 | AB39: =(AB35-AB33)*$V$18 -> 0 | AC39: =(AC35-AC33)*$V$18 -> 0 | AD39: =(AD35-AD33)*$V$18 -> 0 | ... AI39: =(AI35-AI33)*$V$18 -> 0
B40: 系统寿命（年） | C40: =C39/C36/C26 -> 18.643132 | E40: 放电利润现值和（Mn RMB） | F40: =SUM(G41:S41) -> 5.8356513 | U40: 放电利润现值和（Mn RMB） | V40: =SUM(W41:AI41) -> 8.9571124
B41: PCS总成本（元） | C41: =C18*C17 -> 252000 | E41: 放电利润现值和（Mn RMB） | G41: =G35-G33-G37-G39-G26 -> 0.70080784 | H41: =H35-H33-H37-H39-H26 -> 0.64556394 | I41: =I35-I33-I37-I39-I26 -> 0.59469155 | J41: =J35-J33-J37-J39-J26 -> 0.54784362 | K41: =K35-K33-K37-K39-K26 -> 0.50470074 | L41: =L35-L33-L37-L39-L26 -> 0.46496891 | M41: =M35-M33-M37-M39-M26 -> 0.42837755 | N41: =N35-N33-N37-N39-N26 -> 0.39467757 | ... S41: =S35-S33-S37-S39-S26 -> 0.26213271 | U41: 放电利润现值和（Mn RMB） | W41: =W35-W33-W37-W39-W26 -> 0.74986439 | X41: =X35-X33-X37-X39-X26 -> 0.73910616 | Y41: =Y35-Y33-Y37-Y39-Y26 -> 0.72852272 | Z41: =Z35-Z33-Z37-Z39-Z26 -> 0.71811123 | AA41: =AA35-AA33-AA37-AA39-AA26 -> 0.70786889 | AB41: =AB35-AB33-AB37-AB39-AB26 -> 0.69779296 | AC41: =AC35-AC33-AC37-AC39-AC26 -> 0.68788074 | AD41: =AD35-AD33-AD37-AD39-AD26 -> 0.67812955 | ... AI41: =AI35-AI33-AI37-AI39-AI26 -> 0.63169919
B42: ESS总成本（元） | C42: =C19*C20 -> 6720000 | E42: 度电收益（元/kWh) | F42: =C23 -> 0.6 | U42: 度电收益（元/kWh) | V42: =C23 -> 0.6
...

Sheet 表后_现货价差中
B1: xxx | C1: M2访谈数据/Assumption
B2: xxx | C2: 引用数据
B3: xxx | C3: 计算所得数据
C4: 自变量 | D4: *表后用户侧储能主要通过现货形式进行峰谷套利，收益部分由峰负荷时的用户分摊
C5: 支出项 | D5: 关键假设：
C6: 收入项 | D6: 1）电池充放电循环次数~6525次
D7: 2）PCS成本：0.21元/W；电池充放电循环次数~6525次；容量型储能电站运维费用：0.1%；PCS效率：98%；线损：98%；系统使用天数：350天；充放循环次数（1次为1充1放）(次/天）：1次
B8: 更新处：标绿色的单元格 | D8: 3）充放策略：一充一放（1*谷-1*峰）
B11: 基本数据 | E11: 计算结果
B12: 充放策略：一充一放（1*谷-1*峰） | E12: LCOS（元/kWh) | F12: =F43 -> 0.65629663
B13: 谷 | C13: 1 | E13: 投资回报率 | F13: =F48 -> -0.25538842
B14: 平 | C14: 0 | E14: NPV(折现率=7%） | F14: =SUM(F47:O47) -> -3.1165991 | H14: 价差为0.65时： | I14: 0.063152031
B15: 峰 | C15: =C13+C14 -> 1 | E15: IRR | F15: =V48 -> 0.023663328 | H15: 价差为0.6时： | I15: 0.051605782
B16: 基本数据 | E16: 折现率 | F16: 0.07 | H16: 价差为0.55时： | I16: 0.039722393 | U16: 折现率 | V16: 0
B17: PCS(KW） | C17: 1200 | E17: 所得税率 | F17: 0.25 | U17: 所得税率 | V17: 0.25
B18: PCS成本（元/kW) | C18: 210 | E18: 增值税率 | F18: 0 | G18: 暂不考虑 | U18: 增值税率 | V18: 0 | W18: 暂不考虑
B19: ESS(KWh) | C19: 4800 | E19: 储能系统经济效益估算表（元） | U19: 储能系统经济效益估算表（元）
B20: ESS成本（元/kWh) | C20: 1400 | E20: 储能平准化成本LCOS（Levelized Cost of Storage） | G20: 1 | H20: 2 | I20: 3 | J20: 4 | K20: 5 | L20: 6 | M20: 7 | N20: 8 | O20: 9 | P20: 10 | Q20: 11 | R20: 12 | S20: 13 | U20: 储能平准化成本LCOS（Levelized Cost of Storage） | W20: 1 | X20: 2 | Y20: 3 | Z20: 4 | AA20: 5 | AB20: 6 | AC20: 7 | AD20: 8 | AE20: 9 | AF20: 10 | AG20: 11 | AH20: 12 | AI20: 13
B21: PCS效率 | C21: 0.98 | F21: 基准年 | G21: 第1年 | H21: 第2年 | I21: 第3年 | J21: 第4年 | K21: 第5年 | L21: 第6年 | M21: 第7年 | N21: 第8年 | O21: 第9年 | P21: 第10年 | Q21: 第11年 | R21: 第12年 | S21: 第13年 | V21: 基准年 | W21: 第1年 | X21: 第2年 | Y21: 第3年 | Z21: 第4年 | AA21: 第5年 | AB21: 第6年 | AC21: 第7年 | AD21: 第8年 | AE21: 第9年 | AF21: 第10年 | AG21: 第11年 | AH21: 第12年 | AI21: 第13年
B22: 线损 | C22: 0.98 | E22: 初始投资成本（Mn RMB） | F22: =C46/1000000 -> 7.442 | U22: 初始投资成本（Mn RMB） | V22: =C46/1000000 -> 7.442
B23: 峰价（元/KWh) | C23: 0.6 | E23: 折旧现值和（Mn RMB） | F23: =SUM(G24:S24) -> 3.1183056 | U23: 折旧现值和（Mn RMB） | V23: =SUM(W24:AI24) -> 4.8504028
B24: 平价（元/KWh) | C24: 0 | E24: 折旧现值（Mn RMB） | G24: =($C$41+$C$42+$C$32)*(1-$C$35)/$C$40/1000000/(1+$F$16)^G20 -> 0.34869898 | H24: =($C$41+$C$42+$C$32)*(1-$C$35)/$C$40/1000000/(1+$F$16)^H20 -> 0.3258869 | I24: =($C$41+$C$42+$C$32)*(1-$C$35)/$C$40/1000000/(1+$F$16)^I20 -> 0.30456719 | J24: =($C$41+$C$42+$C$32)*(1-$C$35)/$C$40/1000000/(1+$F$16)^J20 -> 0.28464224 | K24: =($C$41+$C$42+$C$32)*(1-$C$35)/$C$40/1000000/(1+$F$16)^K20 -> 0.26602078 | L24: =($C$41+$C$42+$C$32)*(1-$C$35)/$C$40/1000000/(1+$F$16)^L20 -> 0.24861755 | M24: =($C$41+$C$42+$C$32)*(1-$C$35)/$C$40/1000000/(1+$F$16)^M20 -> 0.23235285 | N24: =($C$41+$C$42+$C$32)*(1-$C$35)/$C$40/1000000/(1+$F$16)^N20 -> 0.2171522 | ... S24: =($C$41+$C$42+$C$32)*(1-$C$35)/$C$40/1000000/(1+$F$16)^S20 -> 0.15482652 | U24: 折旧现值（Mn RMB） | W24: =($C$41+$C$42+$C$32)*(1-$C$35)/$C$40/1000000/(1+$V$16)^W20 -> 0.37310791 | X24: =($C$41+$C$42+$C$32)*(1-$C$35)/$C$40/1000000/(1+$V$16)^X20 -> 0.37310791 | Y24: =($C$41+$C$42+$C$32)*(1-$C$35)/$C$40/1000000/(1+$V$16)^Y20 -> 0.37310791 | Z24: =($C$41+$C$42+$C$32)*(1-$C$35)/$C$40/1000000/(1+$V$16)^Z20 -> 0.37310791 | AA24: =($C$41+$C$42+$C$32)*(1-$C$35)/$C$40/1000000/(1+$V$16)^AA20 -> 0.37310791 | AB24: =($C$41+$C$42+$C$32)*(1-$C$35)/$C$40/1000000/(1+$V$16)^AB20 -> 0.37310791 | AC24: =($C$41+$C$42+$C$32)*(1-$C$35)/$C$40/1000000/(1+$V$16)^AC20 -> 0.37310791 | AD24: =($C$41+$C$42+$C$32)*(1-$C$35)/$C$40/1000000/(1+$V$16)^AD20 -> 0.37310791 | ... AI24: =($C$41+$C$42+$C$32)*(1-$C$35)/$C$40/1000000/(1+$V$16)^AI20 -> 0.37310791
B25: 谷价（元/KWh) | C25: 0 | E25: 运行成本现值和（Mn RMB） | F25: =SUM(G26:S26) -> 0.062197637 | U25: 运行成本现值和（Mn RMB） | V25: =SUM(W26:AI26) -> 0.096746
B26: 系统年使用天数 (天) | C26: 350 | E26: 运行成本现值（Mn RMB） | G26: =($C$34*$F$22)/((1+$F$16)^G20) -> 0.0069551402 | H26: =($C$34*$F$22)/((1+$F$16)^H20) -> 0.006500131 | I26: =($C$34*$F$22)/((1+$F$16)^I20) -> 0.0060748888 | J26: =($C$34*$F$22)/((1+$F$16)^J20) -> 0.0056774662 | K26: =($C$34*$F$22)/((1+$F$16)^K20) -> 0.0053060431 | L26: =($C$34*$F$22)/((1+$F$16)^L20) -> 0.0049589188 | M26: =($C$34*$F$22)/((1+$F$16)^M20) -> 0.0046345036 | N26: =($C$34*$F$22)/((1+$F$16)^N20) -> 0.0043313118 | ... S26: =($C$34*$F$22)/((1+$F$16)^S20) -> 0.0030881654 | U26: 运行成本现值（Mn RMB） | W26: =($C$34*$V$22)/((1+$V$16)^W20) -> 0.007442 | X26: =($C$34*$V$22)/((1+$V$16)^X20) -> 0.007442 | Y26: =($C$34*$V$22)/((1+$V$16)^Y20) -> 0.007442 | Z26: =($C$34*$V$22)/((1+$V$16)^Z20) -> 0.007442 | AA26: =($C$34*$V$22)/((1+$V$16)^AA20) -> 0.007442 | AB26: =($C$34*$V$22)/((1+$V$16)^AB20) -> 0.007442 | AC26: =($C$34*$V$22)/((1+$V$16)^AC20) -> 0.007442 | AD26: =($C$34*$V$22)/((1+$V$16)^AD20) -> 0.007442 | ... AI26: =($C$34*$V$22)/((1+$V$16)^AI20) -> 0.007442
B27: DOD% | C27: 0.95 | E27: 固定资产残值现值 (Mn RMB) | S27: =(C41+C42)*C35/((1+F16)^S20)/1000000 -> 0.14465661 | U27: 固定资产残值现值 (Mn RMB) | AI27: =(C41+C42)*C35/((1+V16)^AI20)/1000000 -> 0.3486
B28: 单次循环衰减率 | C28: 4.68e-05 | E28: 充电电量现值和(KWh) | F28: =SUM(G29:S29) -> 13339597 | U28: 充电电量现值和(KWh) | V28: =SUM(W29:AI29) -> 20435477
B29: 系统报废终止标准 | C29: 0.7 | E29: 充电电量现值(KWh) | G29: =$C$19*$C$36*$C$26/$C$37*($C$27*(1-$C$28)^((G20-1)*$C$26*$C$36))/$C$21/$C$22/((1+$F$16)^G20) -> 1617803.3 | H29: =$C$19*$C$36*$C$26/$C$37*($C$27*(1-$C$28)^((H20-1)*$C$26*$C$36))/$C$21/$C$22/((1+$F$16)^H20) -> 1487400.9 | I29: =$C$19*$C$36*$C$26/$C$37*($C$27*(1-$C$28)^((I20-1)*$C$26*$C$36))/$C$21/$C$22/((1+$F$16)^I20) -> 1367509.5 | J29: =$C$19*$C$36*$C$26/$C$37*($C$27*(1-$C$28)^((J20-1)*$C$26*$C$36))/$C$21/$C$22/((1+$F$16)^J20) -> 1257281.9 | K29: =$C$19*$C$36*$C$26/$C$37*($C$27*(1-$C$28)^((K20-1)*$C$26*$C$36))/$C$21/$C$22/((1+$F$16)^K20) -> 1155939.2 | L29: =$C$19*$C$36*$C$26/$C$37*($C$27*(1-$C$28)^((L20-1)*$C$26*$C$36))/$C$21/$C$22/((1+$F$16)^L20) -> 1062765.1 | M29: =$C$19*$C$36*$C$26/$C$37*($C$27*(1-$C$28)^((M20-1)*$C$26*$C$36))/$C$21/$C$22/((1+$F$16)^M20) -> 977101.32 | N29: =$C$19*$C$36*$C$26/$C$37*($C$27*(1-$C$28)^((N20-1)*$C$26*$C$36))/$C$21/$C$22/((1+$F$16)^N20) -> 898342.43 | ... S29: =$C$19*$C$36*$C$26/$C$37*($C$27*(1-$C$28)^((S20-1)*$C$26*$C$36))/$C$21/$C$22/((1+$F$16)^S20) -> 590137.85 | U29: 充电电量现值(KWh) | W29: =$C$19*$C$36*$C$26/$C$37*($C$27*(1-$C$28)^((W20-1)*$C$26*$C$36))/$C$21/$C$22/((1+$V$16)^W20) -> 1731049.6 | X29: =$C$19*$C$36*$C$26/$C$37*($C$27*(1-$C$28)^((X20-1)*$C$26*$C$36))/$C$21/$C$22/((1+$V$16)^X20) -> 1702925.3 | Y29: =$C$19*$C$36*$C$26/$C$37*($C$27*(1-$C$28)^((Y20-1)*$C$26*$C$36))/$C$21/$C$22/((1+$V$16)^Y20) -> 1675257.9 | Z29: =$C$19*$C$36*$C$26/$C$37*($C$27*(1-$C$28)^((Z20-1)*$C$26*$C$36))/$C$21/$C$22/((1+$V$16)^Z20) -> 1648040.1 | AA29: =$C$19*$C$36*$C$26/$C$37*($C$27*(1-$C$28)^((AA20-1)*$C$26*$C$36))/$C$21/$C$22/((1+$V$16)^AA20) -> 1621264.5 | AB29: =$C$19*$C$36*$C$26/$C$37*($C$27*(1-$C$28)^((AB20-1)*$C$26*$C$36))/$C$21/$C$22/((1+$V$16)^AB20) -> 1594923.8 | AC29: =$C$19*$C$36*$C$26/$C$37*($C$27*(1-$C$28)^((AC20-1)*$C$26*$C$36))/$C$21/$C$22/((1+$V$16)^AC20) -> 1569011.2 | AD29: =$C$19*$C$36*$C$26/$C$37*($C$27*(1-$C$28)^((AD20-1)*$C$26*$C$36))/$C$21/$C$22/((1+$V$16)^AD20) -> 1543519.5 | ... AI29: =$C$19*$C$36*$C$26/$C$37*($C$27*(1-$C$28)^((AI20-1)*$C$26*$C$36))/$C$21/$C$22/((1+$V$16)^AI20) -> 1422140.8
B30: 土建成本(元/Wh) | C30: 0.015 | E30: 放电电量现值和(KWh) | F30: =SUM(G31:S31) -> 11339385 | U30: 放电电量现值和(KWh) | V30: =SUM(W31:AI31) -> 17371269
B31: 土建残值率（%） | C31: 0 | E31: 放电电量现值(KWh) | G31: =$C$19*$C$36*$C$26*$C$37*($C$27*(1-$C$28)^((G20-1)*$C$26*$C$36))*$C$21*$C$22/((1+$F$16)^G20) -> 1375221 | H31: =$C$19*$C$36*$C$26*$C$37*($C$27*(1-$C$28)^((H20-1)*$C$26*$C$36))*$C$21*$C$22/((1+$F$16)^H20) -> 1264371.8 | I31: =$C$19*$C$36*$C$26*$C$37*($C$27*(1-$C$28)^((I20-1)*$C$26*$C$36))*$C$21*$C$22/((1+$F$16)^I20) -> 1162457.6 | J31: =$C$19*$C$36*$C$26*$C$37*($C$27*(1-$C$28)^((J20-1)*$C$26*$C$36))*$C$21*$C$22/((1+$F$16)^J20) -> 1068758.1 | K31: =$C$19*$C$36*$C$26*$C$37*($C$27*(1-$C$28)^((K20-1)*$C$26*$C$36))*$C$21*$C$22/((1+$F$16)^K20) -> 982611.27 | L31: =$C$19*$C$36*$C$26*$C$37*($C$27*(1-$C$28)^((L20-1)*$C$26*$C$36))*$C$21*$C$22/((1+$F$16)^L20) -> 903408.26 | M31: =$C$19*$C$36*$C$26*$C$37*($C$27*(1-$C$28)^((M20-1)*$C$26*$C$36))*$C$21*$C$22/((1+$F$16)^M20) -> 830589.37 | N31: =$C$19*$C$36*$C$26*$C$37*($C$27*(1-$C$28)^((N20-1)*$C$26*$C$36))*$C$21*$C$22/((1+$F$16)^N20) -> 763640.02 | ... S31: =$C$19*$C$36*$C$26*$C$37*($C$27*(1-$C$28)^((S20-1)*$C$26*$C$36))*$C$21*$C$22/((1+$F$16)^S20) -> 501649.33 | U31: 放电电量现值(KWh) | W31: =$C$19*$C$36*$C$26*$C$37*($C$27*(1-$C$28)^((W20-1)*$C$26*$C$36))*$C$21*$C$22/((1+$V$16)^W20) -> 1471486.5 | X31: =$C$19*$C$36*$C$26*$C$37*($C$27*(1-$C$28)^((X20-1)*$C$26*$C$36))*$C$21*$C$22/((1+$V$16)^X20) -> 1447579.3 | Y31: =$C$19*$C$36*$C$26*$C$37*($C$27*(1-$C$28)^((Y20-1)*$C$26*$C$36))*$C$21*$C$22/((1+$V$16)^Y20) -> 1424060.5 | Z31: =$C$19*$C$36*$C$26*$C$37*($C$27*(1-$C$28)^((Z20-1)*$C$26*$C$36))*$C$21*$C$22/((1+$V$16)^Z20) -> 1400923.9 | AA31: =$C$19*$C$36*$C$26*$C$37*($C$27*(1-$C$28)^((AA20-1)*$C$26*$C$36))*$C$21*$C$22/((1+$V$16)^AA20) -> 1378163.1 | AB31: =$C$19*$C$36*$C$26*$C$37*($C$27*(1-$C$28)^((AB20-1)*$C$26*$C$36))*$C$21*$C$22/((1+$V$16)^AB20) -> 1355772.2 | AC31: =$C$19*$C$36*$C$26*$C$37*($C$27*(1-$C$28)^((AC20-1)*$C$26*$C$36))*$C$21*$C$22/((1+$V$16)^AC20) -> 1333745 | AD31: =$C$19*$C$36*$C$26*$C$37*($C$27*(1-$C$28)^((AD20-1)*$C$26*$C$36))*$C$21*$C$22/((1+$V$16)^AD20) -> 1312075.7 | ... AI31: =$C$19*$C$36*$C$26*$C$37*($C$27*(1-$C$28)^((AI20-1)*$C$26*$C$36))*$C$21*$C$22/((1+$V$16)^AI20) -> 1208897.1
B32: 其它设备投资费用（升压变等） | C32: 350000 | E32: 充电成本现值和（Mn RMB） | F32: =SUM(G33:S33) -> 0 | U32: 充电成本现值和（Mn RMB） | V32: =SUM(W33:AI33) -> 0
B33: 其它成本：入网检测费、项目管理费等（元/Wh） | C33: 0.01 | E33: 充电成本现值（Mn RMB） | G33: =($C$13*$C$25*G29/($C$13+$C$14)+$C$14*$C$24*G29/($C$13+$C$14))/1000000 -> 0 | H33: =($C$13*$C$25*H29/($C$13+$C$14)+$C$14*$C$24*H29/($C$13+$C$14))/1000000 -> 0 | I33: =($C$13*$C$25*I29/($C$13+$C$14)+$C$14*$C$24*I29/($C$13+$C$14))/1000000 -> 0 | J33: =($C$13*$C$25*J29/($C$13+$C$14)+$C$14*$C$24*J29/($C$13+$C$14))/1000000 -> 0 | K33: =($C$13*$C$25*K29/($C$13+$C$14)+$C$14*$C$24*K29/($C$13+$C$14))/1000000 -> 0 | L33: =($C$13*$C$25*L29/($C$13+$C$14)+$C$14*$C$24*L29/($C$13+$C$14))/1000000 -> 0 | M33: =($C$13*$C$25*M29/($C$13+$C$14)+$C$14*$C$24*M29/($C$13+$C$14))/1000000 -> 0 | N33: =($C$13*$C$25*N29/($C$13+$C$14)+$C$14*$C$24*N29/($C$13+$C$14))/1000000 -> 0 | ... S33: =($C$13*$C$25*S29/($C$13+$C$14)+$C$14*$C$24*S29/($C$13+$C$14))/1000000 -> 0 | U33: 充电成本现值（Mn RMB） | W33: =($C$13*$C$25*W29/($C$13+$C$14)+$C$14*$C$24*W29/($C$13+$C$14))/1000000 -> 0 | X33: =($C$13*$C$25*X29/($C$13+$C$14)+$C$14*$C$24*X29/($C$13+$C$14))/1000000 -> 0 | Y33: =($C$13*$C$25*Y29/($C$13+$C$14)+$C$14*$C$24*Y29/($C$13+$C$14))/1000000 -> 0 | Z33: =($C$13*$C$25*Z29/($C$13+$C$14)+$C$14*$C$24*Z29/($C$13+$C$14))/1000000 -> 0 | AA33: =($C$13*$C$25*AA29/($C$13+$C$14)+$C$14*$C$24*AA29/($C$13+$C$14))/1000000 -> 0 | AB33: =($C$13*$C$25*AB29/($C$13+$C$14)+$C$14*$C$24*AB29/($C$13+$C$14))/1000000 -> 0 | AC33: =($C$13*$C$25*AC29/($C$13+$C$14)+$C$14*$C$24*AC29/($C$13+$C$14))/1000000 -> 0 | AD33: =($C$13*$C$25*AD29/($C$13+$C$14)+$C$14*$C$24*AD29/($C$13+$C$14))/1000000 -> 0 | ... AI33: =($C$13*$C$25*AI29/($C$13+$C$14)+$C$14*$C$24*AI29/($C$13+$C$14))/1000000 -> 0
B34: 容量型储能电站运维费用 | C34: 0.001 | E34: 放电收益现值和（Mn RMB） | F34: =SUM(G35:S35) -> 6.8036309 | U34: 放电收益现值和（Mn RMB） | V34: =SUM(W35:AI35) -> 10.422762
B35: 储能系统残值 | C35: 0.05 | E35: 放电收益现值（Mn RMB） | G35: =G31*$C$23/1000000 -> 0.8251326 | H35: =H31*$C$23/1000000 -> 0.75862309 | I35: =I31*$C$23/1000000 -> 0.69747456 | J35: =J31*$C$23/1000000 -> 0.64125488 | K35: =K31*$C$23/1000000 -> 0.58956676 | L35: =L31*$C$23/1000000 -> 0.54204495 | M35: =M31*$C$23/1000000 -> 0.49835362 | N35: =N31*$C$23/1000000 -> 0.45818401 | ... S35: =S31*$C$23/1000000 -> 0.3009896 | U35: 放电收益现值（Mn RMB） | W35: =W31*$C$23/1000000 -> 0.88289188 | X35: =X31*$C$23/1000000 -> 0.86854757 | Y35: =Y31*$C$23/1000000 -> 0.85443632 | Z35: =Z31*$C$23/1000000 -> 0.84055433 | AA35: =AA31*$C$23/1000000 -> 0.82689789 | AB35: =AB31*$C$23/1000000 -> 0.81346331 | AC35: =AC31*$C$23/1000000 -> 0.80024701 | AD35: =AD31*$C$23/1000000 -> 0.78724544 | ... AI35: =AI31*$C$23/1000000 -> 0.72533828
B36: 充放循环次数（1次为1充1放）(次/天） | C36: =C13+C14 -> 1 | E36: 所得税现值和（Mn RMB） | F36: =SUM(G37:S37) -> 0.90578192 | U36: 所得税现值和（Mn RMB） | V36: =SUM(W37:AI37) -> 1.3689032
B37: 充放电效率RTE（%） | C37: 0.96 | E37: 所得税现值（Mn RMB） | G37: =(G35-G33-G26-G24)*$F$17 -> 0.11736962 | H37: =(H35-H33-H26-H24)*$F$17 -> 0.10655902 | I37: =(I35-I33-I26-I24)*$F$17 -> 0.096708118 | J37: =(J35-J33-J26-J24)*$F$17 -> 0.087733794 | K37: =(K35-K33-K26-K24)*$F$17 -> 0.079559985 | L37: =(L35-L33-L26-L24)*$F$17 -> 0.07211712 | M37: =(M35-M33-M26-M24)*$F$17 -> 0.065341566 | N37: =(N35-N33-N26-N24)*$F$17 -> 0.059175125 | ... S37: =(S35-S33-S26-S24)*$F$17 -> 0.03576873 | U37: 所得税现值（Mn RMB） | W37: =(W35-W33-W26-W24)*$V$17 -> 0.12558549 | X37: =(X35-X33-X26-X24)*$V$17 -> 0.12199942 | Y37: =(Y35-Y33-Y26-Y24)*$V$17 -> 0.1184716 | Z37: =(Z35-Z33-Z26-Z24)*$V$17 -> 0.11500111 | AA37: =(AA35-AA33-AA26-AA24)*$V$17 -> 0.11158699 | AB37: =(AB35-AB33-AB26-AB24)*$V$17 -> 0.10822835 | AC37: =(AC35-AC33-AC26-AC24)*$V$17 -> 0.10492428 | AD37: =(AD35-AD33-AD26-AD24)*$V$17 -> 0.10167388 | ... AI37: =(AI35-AI33-AI26-AI24)*$V$17 -> 0.086197094
B38: 用户分成比例（%） | C38: 0.1 | E38: 增值税现值和（Mn RMB） | F38: =SUM(G39:S39) -> 0 | U38: 增值税现值和（Mn RMB） | V38: =SUM(W39:AI39) -> 0
B39: 充放循环总次数（次数） | C39: =LOG(C29/C27,(1-C28)) -> 6525.0962 | E39: 增值税现值（Mn RMB） | G39: =(G35-G33)*$F$18 -> 0 | H39: =(H35-H33)*$F$18 -> 0 | I39: =(I35-I33)*$F$18 -> 0 | J39: =(J35-J33)*$F$18 -> 0 | K39: =(K35-K33)*$F$18 -> 0 | L39: =(L35-L33)*$F$18 -> 0 | M39: =(M35-M33)*$F$18 -> 0 | N39: =(N35-N33)*$F$18 -> 0 | ... S39: =(S35-S33)*$F$18 -> 0 | U39: 增值税现值（Mn RMB） | W39: =(W35-W33)*$V$18 -> 0 | X39: =(X35-X33)*$V$18 -> 0 | Y39: =(Y35-Y33)*$V$18 -> 0 | Z39: =(Z35-Z33)*$V$18 -> 0 | AA39: =(AA35-AA33)*$V$18 -> 0 | AB39: =(AB35-AB33)*$V$18 -> 0 | AC39: =(AC35-AC33)*$V$18 -> 0 | AD39: =(AD35-AD33)*$V$18 -> 0 | ... AI39: =(AI35-AI33)*$V$18 -> 0
B40: 系统寿命（年） | C40: =C39/C36/C26 -> 18.643132 | E40: 放电利润现值和（Mn RMB） | F40: =SUM(G41:S41) -> 5.8356513 | U40: 放电利润现值和（Mn RMB） | V40: =SUM(W41:AI41) -> 8.9571124
B41: PCS总成本（元） | C41: =C18*C17 -> 252000 | E41: 放电利润现值和（Mn RMB） | G41: =G35-G33-G37-G39-G26 -> 0.70080784 | H41: =H35-H33-H37-H39-H26 -> 0.64556394 | I41: =I35-I33-I37-I39-I26 -> 0.59469155 | J41: =J35-J33-J37-J39-J26 -> 0.54784362 | K41: =K35-K33-K37-K39-K26 -> 0.50470074 | L41: =L35-L33-L37-L39-L26 -> 0.46496891 | M41: =M35-M33-M37-M39-M26 -> 0.42837755 | N41: =N35-N33-N37-N39-N26 -> 0.39467757 | ... S41: =S35-S33-S37-S39-S26 -> 0.26213271 | U41: 放电利润现值和（Mn RMB） | W41: =W35-W33-W37-W39-W26 -> 0.74986439 | X41: =X35-X33-X37-X39-X26 -> 0.73910616 | Y41: =Y35-Y33-Y37-Y39-Y26 -> 0.72852272 | Z41: =Z35-Z33-Z37-Z39-Z26 -> 0.71811123 | AA41: =AA35-AA33-AA37-AA39-AA26 -> 0.70786889 | AB41: =AB35-AB33-AB37-AB39-AB26 -> 0.69779296 | AC41: =AC35-AC33-AC37-AC39-AC26 -> 0.68788074 | AD41: =AD35-AD33-AD37-AD39-AD26 -> 0.67812955 | ... AI41: =AI35-AI33-AI37-AI39-AI26 -> 0.63169919
B42: ESS总成本（元） | C42: =C19*C20 -> 6720000 | E42: 度电收益（元/kWh) | F42: =C23 -> 0.6 | U42: 度电收益（元/kWh) | V42: =C23 -> 0.6
...

Sheet 表后_现货价差低
B1: xxx | C1: M2访谈数据/Assumption
B2: xxx | C2: 引用数据
B3: xxx | C3: 计算所得数据
C4: 自变量 | D4: *表后用户侧储能主要通过现货形式进行峰谷套利，收益部分由峰负荷时的用户分摊
C5: 支出项 | D5: 关键假设：
C6: 收入项 | D6: 1）电池充放电循环次数~6525次
D7: 2）PCS成本：0.21元/W；电池充放电循环次数~6525次；容量型储能电站运维费用：0.1%；PCS效率：98%；线损：98%；系统使用天数：350天；充放循环次数（1次为1充1放）(次/天）：1次
B8: 更新处：标绿色的单元格 | D8: 3）充放策略：一充一放（1*谷-1*峰）
B11: 基本数据 | E11: 计算结果
B12: 充放策略：一充一放（1*谷-1*峰） | E12: LCOS（元/kWh) | F12: =F43 -> 0.52930561
B13: 谷 | C13: 1 | E13: 投资回报率 | F13: =F48 -> -0.49091018
B14: 平 | C14: 0 | E14: NPV(折现率=7%） | F14: =SUM(F47:O47) -> -3.6409726 | H14: 价差为0.45时： | I14: 0.014741147
B15: 峰 | C15: =C13+C14 -> 1 | E15: IRR | F15: =V48 -> -0.026870407 | H15: 价差为0.3时： | I15: -0.026870407
B16: 基本数据 | E16: 折现率 | F16: 0.07 | U16: 折现率 | V16: 0
B17: PCS(KW） | C17: 1200 | E17: 所得税率 | F17: 0.25 | U17: 所得税率 | V17: 0.25
B18: PCS成本（元/kW) | C18: 210 | E18: 增值税率 | F18: 0 | G18: 暂不考虑 | U18: 增值税率 | V18: 0 | W18: 暂不考虑
B19: ESS(KWh) | C19: 4800 | E19: 储能系统经济效益估算表（元） | U19: 储能系统经济效益估算表（元）
B20: ESS成本（元/kWh) | C20: 1100 | E20: 储能平准化成本LCOS（Levelized Cost of Storage） | G20: 1 | H20: 2 | I20: 3 | J20: 4 | K20: 5 | L20: 6 | M20: 7 | N20: 8 | O20: 9 | P20: 10 | Q20: 11 | R20: 12 | S20: 13 | U20: 储能平准化成本LCOS（Levelized Cost of Storage） | W20: 1 | X20: 2 | Y20: 3 | Z20: 4 | AA20: 5 | AB20: 6 | AC20: 7 | AD20: 8 | AE20: 9 | AF20: 10 | AG20: 11 | AH20: 12 | AI20: 13
B21: PCS效率 | C21: 0.98 | F21: 基准年 | G21: 第1年 | H21: 第2年 | I21: 第3年 | J21: 第4年 | K21: 第5年 | L21: 第6年 | M21: 第7年 | N21: 第8年 | O21: 第9年 | P21: 第10年 | Q21: 第11年 | R21: 第12年 | S21: 第13年 | V21: 基准年 | W21: 第1年 | X21: 第2年 | Y21: 第3年 | Z21: 第4年 | AA21: 第5年 | AB21: 第6年 | AC21: 第7年 | AD21: 第8年 | AE21: 第9年 | AF21: 第10年 | AG21: 第11年 | AH21: 第12年 | AI21: 第13年
B22: 线损 | C22: 0.98 | E22: 初始投资成本（Mn RMB） | F22: =C46/1000000 -> 6.002 | U22: 初始投资成本（Mn RMB） | V22: =C46/1000000 -> 6.002
B23: 峰价（元/KWh) | C23: 0.3 | E23: 折旧现值和（Mn RMB） | F23: =SUM(G24:S24) -> 2.505036 | U23: 折旧现值和（Mn RMB） | V23: =SUM(W24:AI24) -> 3.8964858
B24: 平价（元/KWh) | C24: 0 | E24: 折旧现值（Mn RMB） | G24: =($C$41+$C$42+$C$32)*(1-$C$35)/$C$40/1000000/(1+$F$16)^G20 -> 0.2801212 | H24: =($C$41+$C$42+$C$32)*(1-$C$35)/$C$40/1000000/(1+$F$16)^H20 -> 0.26179551 | I24: =($C$41+$C$42+$C$32)*(1-$C$35)/$C$40/1000000/(1+$F$16)^I20 -> 0.2446687 | J24: =($C$41+$C$42+$C$32)*(1-$C$35)/$C$40/1000000/(1+$F$16)^J20 -> 0.22866234 | K24: =($C$41+$C$42+$C$32)*(1-$C$35)/$C$40/1000000/(1+$F$16)^K20 -> 0.21370312 | L24: =($C$41+$C$42+$C$32)*(1-$C$35)/$C$40/1000000/(1+$F$16)^L20 -> 0.19972254 | M24: =($C$41+$C$42+$C$32)*(1-$C$35)/$C$40/1000000/(1+$F$16)^M20 -> 0.18665658 | N24: =($C$41+$C$42+$C$32)*(1-$C$35)/$C$40/1000000/(1+$F$16)^N20 -> 0.1744454 | ... S24: =($C$41+$C$42+$C$32)*(1-$C$35)/$C$40/1000000/(1+$F$16)^S20 -> 0.12437716 | U24: 折旧现值（Mn RMB） | W24: =($C$41+$C$42+$C$32)*(1-$C$35)/$C$40/1000000/(1+$V$16)^W20 -> 0.29972968 | X24: =($C$41+$C$42+$C$32)*(1-$C$35)/$C$40/1000000/(1+$V$16)^X20 -> 0.29972968 | Y24: =($C$41+$C$42+$C$32)*(1-$C$35)/$C$40/1000000/(1+$V$16)^Y20 -> 0.29972968 | Z24: =($C$41+$C$42+$C$32)*(1-$C$35)/$C$40/1000000/(1+$V$16)^Z20 -> 0.29972968 | AA24: =($C$41+$C$42+$C$32)*(1-$C$35)/$C$40/1000000/(1+$V$16)^AA20 -> 0.29972968 | AB24: =($C$41+$C$42+$C$32)*(1-$C$35)/$C$40/1000000/(1+$V$16)^AB20 -> 0.29972968 | AC24: =($C$41+$C$42+$C$32)*(1-$C$35)/$C$40/1000000/(1+$V$16)^AC20 -> 0.29972968 | AD24: =($C$41+$C$42+$C$32)*(1-$C$35)/$C$40/1000000/(1+$V$16)^AD20 -> 0.29972968 | ... AI24: =($C$41+$C$42+$C$32)*(1-$C$35)/$C$40/1000000/(1+$V$16)^AI20 -> 0.29972968
B25: 谷价（元/KWh) | C25: 0 | E25: 运行成本现值和（Mn RMB） | F25: =SUM(G26:S26) -> 0.05016262 | U25: 运行成本现值和（Mn RMB） | V25: =SUM(W26:AI26) -> 0.078026
B26: 系统年使用天数 (天) | C26: 350 | E26: 运行成本现值（Mn RMB） | G26: =($C$34*$F$22)/((1+$F$16)^G20) -> 0.0056093458 | H26: =($C$34*$F$22)/((1+$F$16)^H20) -> 0.0052423792 | I26: =($C$34*$F$22)/((1+$F$16)^I20) -> 0.0048994199 | J26: =($C$34*$F$22)/((1+$F$16)^J20) -> 0.0045788971 | K26: =($C$34*$F$22)/((1+$F$16)^K20) -> 0.004279343 | L26: =($C$34*$F$22)/((1+$F$16)^L20) -> 0.003999386 | M26: =($C$34*$F$22)/((1+$F$16)^M20) -> 0.003737744 | N26: =($C$34*$F$22)/((1+$F$16)^N20) -> 0.0034932186 | ... S26: =($C$34*$F$22)/((1+$F$16)^S20) -> 0.0024906166 | U26: 运行成本现值（Mn RMB） | W26: =($C$34*$V$22)/((1+$V$16)^W20) -> 0.006002 | X26: =($C$34*$V$22)/((1+$V$16)^X20) -> 0.006002 | Y26: =($C$34*$V$22)/((1+$V$16)^Y20) -> 0.006002 | Z26: =($C$34*$V$22)/((1+$V$16)^Z20) -> 0.006002 | AA26: =($C$34*$V$22)/((1+$V$16)^AA20) -> 0.006002 | AB26: =($C$34*$V$22)/((1+$V$16)^AB20) -> 0.006002 | AC26: =($C$34*$V$22)/((1+$V$16)^AC20) -> 0.006002 | AD26: =($C$34*$V$22)/((1+$V$16)^AD20) -> 0.006002 | ... AI26: =($C$34*$V$22)/((1+$V$16)^AI20) -> 0.006002
B27: DOD% | C27: 0.95 | E27: 固定资产残值现值 (Mn RMB) | S27: =(C41+C42)*C35/((1+F16)^S20)/1000000 -> 0.11477917 | U27: 固定资产残值现值 (Mn RMB) | AI27: =(C41+C42)*C35/((1+V16)^AI20)/1000000 -> 0.2766
B28: 单次循环衰减率 | C28: 4.68e-05 | E28: 充电电量现值和(KWh) | F28: =SUM(G29:S29) -> 13339597 | U28: 充电电量现值和(KWh) | V28: =SUM(W29:AI29) -> 20435477
B29: 系统报废终止标准 | C29: 0.7 | E29: 充电电量现值(KWh) | G29: =$C$19*$C$36*$C$26/$C$37*($C$27*(1-$C$28)^((G20-1)*$C$26*$C$36))/$C$21/$C$22/((1+$F$16)^G20) -> 1617803.3 | H29: =$C$19*$C$36*$C$26/$C$37*($C$27*(1-$C$28)^((H20-1)*$C$26*$C$36))/$C$21/$C$22/((1+$F$16)^H20) -> 1487400.9 | I29: =$C$19*$C$36*$C$26/$C$37*($C$27*(1-$C$28)^((I20-1)*$C$26*$C$36))/$C$21/$C$22/((1+$F$16)^I20) -> 1367509.5 | J29: =$C$19*$C$36*$C$26/$C$37*($C$27*(1-$C$28)^((J20-1)*$C$26*$C$36))/$C$21/$C$22/((1+$F$16)^J20) -> 1257281.9 | K29: =$C$19*$C$36*$C$26/$C$37*($C$27*(1-$C$28)^((K20-1)*$C$26*$C$36))/$C$21/$C$22/((1+$F$16)^K20) -> 1155939.2 | L29: =$C$19*$C$36*$C$26/$C$37*($C$27*(1-$C$28)^((L20-1)*$C$26*$C$36))/$C$21/$C$22/((1+$F$16)^L20) -> 1062765.1 | M29: =$C$19*$C$36*$C$26/$C$37*($C$27*(1-$C$28)^((M20-1)*$C$26*$C$36))/$C$21/$C$22/((1+$F$16)^M20) -> 977101.32 | N29: =$C$19*$C$36*$C$26/$C$37*($C$27*(1-$C$28)^((N20-1)*$C$26*$C$36))/$C$21/$C$22/((1+$F$16)^N20) -> 898342.43 | ... S29: =$C$19*$C$36*$C$26/$C$37*($C$27*(1-$C$28)^((S20-1)*$C$26*$C$36))/$C$21/$C$22/((1+$F$16)^S20) -> 590137.85 | U29: 充电电量现值(KWh) | W29: =$C$19*$C$36*$C$26/$C$37*($C$27*(1-$C$28)^((W20-1)*$C$26*$C$36))/$C$21/$C$22/((1+$V$16)^W20) -> 1731049.6 | X29: =$C$19*$C$36*$C$26/$C$37*($C$27*(1-$C$28)^((X20-1)*$C$26*$C$36))/$C$21/$C$22/((1+$V$16)^X20) -> 1702925.3 | Y29: =$C$19*$C$36*$C$26/$C$37*($C$27*(1-$C$28)^((Y20-1)*$C$26*$C$36))/$C$21/$C$22/((1+$V$16)^Y20) -> 1675257.9 | Z29: =$C$19*$C$36*$C$26/$C$37*($C$27*(1-$C$28)^((Z20-1)*$C$26*$C$36))/$C$21/$C$22/((1+$V$16)^Z20) -> 1648040.1 | AA29: =$C$19*$C$36*$C$26/$C$37*($C$27*(1-$C$28)^((AA20-1)*$C$26*$C$36))/$C$21/$C$22/((1+$V$16)^AA20) -> 1621264.5 | AB29: =$C$19*$C$36*$C$26/$C$37*($C$27*(1-$C$28)^((AB20-1)*$C$26*$C$36))/$C$21/$C$22/((1+$V$16)^AB20) -> 1594923.8 | AC29: =$C$19*$C$36*$C$26/$C$37*($C$27*(1-$C$28)^((AC20-1)*$C$26*$C$36))/$C$21/$C$22/((1+$V$16)^AC20) -> 1569011.2 | AD29: =$C$19*$C$36*$C$26/$C$37*($C$27*(1-$C$28)^((AD20-1)*$C$26*$C$36))/$C$21/$C$22/((1+$V$16)^AD20) -> 1543519.5 | ... AI29: =$C$19*$C$36*$C$26/$C$37*($C$27*(1-$C$28)^((AI20-1)*$C$26*$C$36))/$C$21/$C$22/((1+$V$16)^AI20) -> 1422140.8
B30: 土建成本(元/Wh) | C30: 0.015 | E30: 放电电量现值和(KWh) | F30: =SUM(G31:S31) -> 11339385 | U30: 放电电量现值和(KWh) | V30: =SUM(W31:AI31) -> 17371269
B31: 土建残值率（%） | C31: 0 | E31: 放电电量现值(KWh) | G31: =$C$19*$C$36*$C$26*$C$37*($C$27*(1-$C$28)^((G20-1)*$C$26*$C$36))*$C$21*$C$22/((1+$F$16)^G20) -> 1375221 | H31: =$C$19*$C$36*$C$26*$C$37*($C$27*(1-$C$28)^((H20-1)*$C$26*$C$36))*$C$21*$C$22/((1+$F$16)^H20) -> 1264371.8 | I31: =$C$19*$C$36*$C$26*$C$37*($C$27*(1-$C$28)^((I20-1)*$C$26*$C$36))*$C$21*$C$22/((1+$F$16)^I20) -> 1162457.6 | J31: =$C$19*$C$36*$C$26*$C$37*($C$27*(1-$C$28)^((J20-1)*$C$26*$C$36))*$C$21*$C$22/((1+$F$16)^J20) -> 1068758.1 | K31: =$C$19*$C$36*$C$26*$C$37*($C$27*(1-$C$28)^((K20-1)*$C$26*$C$36))*$C$21*$C$22/((1+$F$16)^K20) -> 982611.27 | L31: =$C$19*$C$36*$C$26*$C$37*($C$27*(1-$C$28)^((L20-1)*$C$26*$C$36))*$C$21*$C$22/((1+$F$16)^L20) -> 903408.26 | M31: =$C$19*$C$36*$C$26*$C$37*($C$27*(1-$C$28)^((M20-1)*$C$26*$C$36))*$C$21*$C$22/((1+$F$16)^M20) -> 830589.37 | N31: =$C$19*$C$36*$C$26*$C$37*($C$27*(1-$C$28)^((N20-1)*$C$26*$C$36))*$C$21*$C$22/((1+$F$16)^N20) -> 763640.02 | ... S31: =$C$19*$C$36*$C$26*$C$37*($C$27*(1-$C$28)^((S20-1)*$C$26*$C$36))*$C$21*$C$22/((1+$F$16)^S20) -> 501649.33 | U31: 放电电量现值(KWh) | W31: =$C$19*$C$36*$C$26*$C$37*($C$27*(1-$C$28)^((W20-1)*$C$26*$C$36))*$C$21*$C$22/((1+$V$16)^W20) -> 1471486.5 | X31: =$C$19*$C$36*$C$26*$C$37*($C$27*(1-$C$28)^((X20-1)*$C$26*$C$36))*$C$21*$C$22/((1+$V$16)^X20) -> 1447579.3 | Y31: =$C$19*$C$36*$C$26*$C$37*($C$27*(1-$C$28)^((Y20-1)*$C$26*$C$36))*$C$21*$C$22/((1+$V$16)^Y20) -> 1424060.5 | Z31: =$C$19*$C$36*$C$26*$C$37*($C$27*(1-$C$28)^((Z20-1)*$C$26*$C$36))*$C$21*$C$22/((1+$V$16)^Z20) -> 1400923.9 | AA31: =$C$19*$C$36*$C$26*$C$37*($C$27*(1-$C$28)^((AA20-1)*$C$26*$C$36))*$C$21*$C$22/((1+$V$16)^AA20) -> 1378163.1 | AB31: =$C$19*$C$36*$C$26*$C$37*($C$27*(1-$C$28)^((AB20-1)*$C$26*$C$36))*$C$21*$C$22/((1+$V$16)^AB20) -> 1355772.2 | AC31: =$C$19*$C$36*$C$26*$C$37*($C$27*(1-$C$28)^((AC20-1)*$C$26*$C$36))*$C$21*$C$22/((1+$V$16)^AC20) -> 1333745 | AD31: =$C$19*$C$36*$C$26*$C$37*($C$27*(1-$C$28)^((AD20-1)*$C$26*$C$36))*$C$21*$C$22/((1+$V$16)^AD20) -> 1312075.7 | ... AI31: =$C$19*$C$36*$C$26*$C$37*($C$27*(1-$C$28)^((AI20-1)*$C$26*$C$36))*$C$21*$C$22/((1+$V$16)^AI20) -> 1208897.1
B32: 其它设备投资费用（升压变等） | C32: 350000 | E32: 充电成本现值和（Mn RMB） | F32: =SUM(G33:S33) -> 0 | U32: 充电成本现值和（Mn RMB） | V32: =SUM(W33:AI33) -> 0
B33: 其它成本：入网检测费、项目管理费等（元/Wh） | C33: 0.01 | E33: 充电成本现值（Mn RMB） | G33: =($C$13*$C$25*G29/($C$13+$C$14)+$C$14*$C$24*G29/($C$13+$C$14))/1000000 -> 0 | H33: =($C$13*$C$25*H29/($C$13+$C$14)+$C$14*$C$24*H29/($C$13+$C$14))/1000000 -> 0 | I33: =($C$13*$C$25*I29/($C$13+$C$14)+$C$14*$C$24*I29/($C$13+$C$14))/1000000 -> 0 | J33: =($C$13*$C$25*J29/($C$13+$C$14)+$C$14*$C$24*J29/($C$13+$C$14))/1000000 -> 0 | K33: =($C$13*$C$25*K29/($C$13+$C$14)+$C$14*$C$24*K29/($C$13+$C$14))/1000000 -> 0 | L33: =($C$13*$C$25*L29/($C$13+$C$14)+$C$14*$C$24*L29/($C$13+$C$14))/1000000 -> 0 | M33: =($C$13*$C$25*M29/($C$13+$C$14)+$C$14*$C$24*M29/($C$13+$C$14))/1000000 -> 0 | N33: =($C$13*$C$25*N29/($C$13+$C$14)+$C$14*$C$24*N29/($C$13+$C$14))/1000000 -> 0 | ... S33: =($C$13*$C$25*S29/($C$13+$C$14)+$C$14*$C$24*S29/($C$13+$C$14))/1000000 -> 0 | U33: 充电成本现值（Mn RMB） | W33: =($C$13*$C$25*W29/($C$13+$C$14)+$C$14*$C$24*W29/($C$13+$C$14))/1000000 -> 0 | X33: =($C$13*$C$25*X29/($C$13+$C$14)+$C$14*$C$24*X29/($C$13+$C$14))/1000000 -> 0 | Y33: =($C$13*$C$25*Y29/($C$13+$C$14)+$C$14*$C$24*Y29/($C$13+$C$14))/1000000 -> 0 | Z33: =($C$13*$C$25*Z29/($C$13+$C$14)+$C$14*$C$24*Z29/($C$13+$C$14))/1000000 -> 0 | AA33: =($C$13*$C$25*AA29/($C$13+$C$14)+$C$14*$C$24*AA29/($C$13+$C$14))/1000000 -> 0 | AB33: =($C$13*$C$25*AB29/($C$13+$C$14)+$C$14*$C$24*AB29/($C$13+$C$14))/1000000 -> 0 | AC33: =($C$13*$C$25*AC29/($C$13+$C$14)+$C$14*$C$24*AC29/($C$13+$C$14))/1000000 -> 0 | AD33: =($C$13*$C$25*AD29/($C$13+$C$14)+$C$14*$C$24*AD29/($C$13+$C$14))/1000000 -> 0 | ... AI33: =($C$13*$C$25*AI29/($C$13+$C$14)+$C$14*$C$24*AI29/($C$13+$C$14))/1000000 -> 0
B34: 容量型储能电站运维费用 | C34: 0.001 | E34: 放电收益现值和（Mn RMB） | F34: =SUM(G35:S35) -> 3.4018154 | U34: 放电收益现值和（Mn RMB） | V34: =SUM(W35:AI35) -> 5.2113808
B35: 储能系统残值 | C35: 0.05 | E35: 放电收益现值（Mn RMB） | G35: =G31*$C$23/1000000 -> 0.4125663 | H35: =H31*$C$23/1000000 -> 0.37931154 | I35: =I31*$C$23/1000000 -> 0.34873728 | J35: =J31*$C$23/1000000 -> 0.32062744 | K35: =K31*$C$23/1000000 -> 0.29478338 | L35: =L31*$C$23/1000000 -> 0.27102248 | M35: =M31*$C$23/1000000 -> 0.24917681 | N35: =N31*$C$23/1000000 -> 0.22909201 | ... S35: =S31*$C$23/1000000 -> 0.1504948 | U35: 放电收益现值（Mn RMB） | W35: =W31*$C$23/1000000 -> 0.44144594 | X35: =X31*$C$23/1000000 -> 0.43427379 | Y35: =Y31*$C$23/1000000 -> 0.42721816 | Z35: =Z31*$C$23/1000000 -> 0.42027717 | AA35: =AA31*$C$23/1000000 -> 0.41344894 | AB35: =AB31*$C$23/1000000 -> 0.40673166 | AC35: =AC31*$C$23/1000000 -> 0.40012351 | AD35: =AD31*$C$23/1000000 -> 0.39362272 | ... AI35: =AI31*$C$23/1000000 -> 0.36266914
B36: 充放循环次数（1次为1充1放）(次/天） | C36: =C13+C14 -> 1 | E36: 所得税现值和（Mn RMB） | F36: =SUM(G37:S37) -> 0.21165421 | U36: 所得税现值和（Mn RMB） | V36: =SUM(W37:AI37) -> 0.30921724
B37: 充放电效率RTE（%） | C37: 0.96 | E37: 所得税现值（Mn RMB） | G37: =(G35-G33-G26-G24)*$F$17 -> 0.031708939 | H37: =(H35-H33-H26-H24)*$F$17 -> 0.028068414 | I37: =(I35-I33-I26-I24)*$F$17 -> 0.024792289 | J37: =(J35-J33-J26-J24)*$F$17 -> 0.021846551 | K37: =(K35-K33-K26-K24)*$F$17 -> 0.01920023 | L37: =(L35-L33-L26-L24)*$F$17 -> 0.016825137 | M37: =(M35-M33-M26-M24)*$F$17 -> 0.014695621 | N37: =(N35-N33-N26-N24)*$F$17 -> 0.012788346 | ... S37: =(S35-S33-S26-S24)*$F$17 -> 0.0059067557 | U37: 所得税现值（Mn RMB） | W37: =(W35-W33-W26-W24)*$V$17 -> 0.033928565 | X37: =(X35-X33-X26-X24)*$V$17 -> 0.032135527 | Y37: =(Y35-Y33-Y26-Y24)*$V$17 -> 0.03037162 | Z37: =(Z35-Z33-Z26-Z24)*$V$17 -> 0.028636372 | AA37: =(AA35-AA33-AA26-AA24)*$V$17 -> 0.026929316 | AB37: =(AB35-AB33-AB26-AB24)*$V$17 -> 0.025249994 | AC37: =(AC35-AC33-AC26-AC24)*$V$17 -> 0.023597957 | AD37: =(AD35-AD33-AD26-AD24)*$V$17 -> 0.02197276 | ... AI37: =(AI35-AI33-AI26-AI24)*$V$17 -> 0.014234366
B38: 用户分成比例（%） | C38: 0.1 | E38: 增值税现值和（Mn RMB） | F38: =SUM(G39:S39) -> 0 | U38: 增值税现值和（Mn RMB） | V38: =SUM(W39:AI39) -> 0
B39: 充放循环总次数（次数） | C39: =LOG(C29/C27,(1-C28)) -> 6525.0962 | E39: 增值税现值（Mn RMB） | G39: =(G35-G33)*$F$18 -> 0 | H39: =(H35-H33)*$F$18 -> 0 | I39: =(I35-I33)*$F$18 -> 0 | J39: =(J35-J33)*$F$18 -> 0 | K39: =(K35-K33)*$F$18 -> 0 | L39: =(L35-L33)*$F$18 -> 0 | M39: =(M35-M33)*$F$18 -> 0 | N39: =(N35-N33)*$F$18 -> 0 | ... S39: =(S35-S33)*$F$18 -> 0 | U39: 增值税现值（Mn RMB） | W39: =(W35-W33)*$V$18 -> 0 | X39: =(X35-X33)*$V$18 -> 0 | Y39: =(Y35-Y33)*$V$18 -> 0 | Z39: =(Z35-Z33)*$V$18 -> 0 | AA39: =(AA35-AA33)*$V$18 -> 0 | AB39: =(AB35-AB33)*$V$18 -> 0 | AC39: =(AC35-AC33)*$V$18 -> 0 | AD39: =(AD35-AD33)*$V$18 -> 0 | ... AI39: =(AI35-AI33)*$V$18 -> 0
B40: 系统寿命（年） | C40: =C39/C36/C26 -> 18.643132 | E40: 放电利润现值和（Mn RMB） | F40: =SUM(G41:S41) -> 3.1399986 | U40: 放电利润现值和（Mn RMB） | V40: =SUM(W41:AI41) -> 4.8241376
B41: PCS总成本（元） | C41: =C18*C17 -> 252000 | E41: 放电利润现值和（Mn RMB） | G41: =G35-G33-G37-G39-G26 -> 0.37524801 | H41: =H35-H33-H37-H39-H26 -> 0.34600075 | I41: =I35-I33-I37-I39-I26 -> 0.31904557 | J41: =J35-J33-J37-J39-J26 -> 0.29420199 | K41: =K35-K33-K37-K39-K26 -> 0.27130381 | L41: =L35-L33-L37-L39-L26 -> 0.25019795 | M41: =M35-M33-M37-M39-M26 -> 0.23074344 | N41: =N35-N33-N37-N39-N26 -> 0.21281044 | ... S41: =S35-S33-S37-S39-S26 -> 0.14209743 | U41: 放电利润现值和（Mn RMB） | W41: =W35-W33-W37-W39-W26 -> 0.40151537 | X41: =X35-X33-X37-X39-X26 -> 0.39613626 | Y41: =Y35-Y33-Y37-Y39-Y26 -> 0.39084454 | Z41: =Z35-Z33-Z37-Z39-Z26 -> 0.38563879 | AA41: =AA35-AA33-AA37-AA39-AA26 -> 0.38051763 | AB41: =AB35-AB33-AB37-AB39-AB26 -> 0.37547966 | AC41: =AC35-AC33-AC37-AC39-AC26 -> 0.37052355 | AD41: =AD35-AD33-AD37-AD39-AD26 -> 0.36564796 | ... AI41: =AI35-AI33-AI37-AI39-AI26 -> 0.34243278
B42: ESS总成本（元） | C42: =C19*C20 -> 5280000 | E42: 度电收益（元/kWh) | F42: =C23 -> 0.3 | U42: 度电收益（元/kWh) | V42: =C23 -> 0.3
...

Sheet 表前_共享储能_现货
C1: 自变量 | D1: *表前储能主要通过现货形式进行峰谷套利、容量租赁等方式活力
C2: 支出项 | D2: 关键假定：
C3: 收入项 | D3: 1）电池充放电循环次数~6525次
D4: 2）PCS成本：0.21元/W；电池充放电循环次数~6525次；容量型储能电站运维费用：0.1%；PCS效率：98%；线损：98%；系统使用天数：350天；充放循环次数（1次为1充1放）(次/天）：1次
B5: Updated-新增表前结合现货盈利模型 | D5: 3）一充一放（一谷一峰）
B6: Base | E6: 计算结果
B7: 储能电站:一充一放（一谷一峰） | E7: LCOS（元/kWh) | F7: =F42 -> 0.65232481 | I7: 价差为0.8时： | K7: 0.17612056
B8: 基本数据 | E8: 投资回报率 | F8: =F46 -> 0.044444708 | I8: 价差为0.7时： | K8: 0.15935511
B9: PCS(KW） | C9: 100000 | E9: NPV(折现率=7%） | F9: =SUM(F45:S45) -> 116.93111 | I9: 价差为0.65时： | K9: 0.15086564
B10: PCS成本（元/kW) | C10: 210 | E10: IRR | F10: =V46 -> 0.13015744 | I10: 价差为0.55时： | K10: 0.13364414
B11: ESS(KWh) | C11: 200000 | E11: 折现率 | F11: 0.07 | I11: 价差为0.5时： | K11: 0.12489873 | U11: 折现率 | V11: 0
B12: ESS成本（元/kWh) | C12: 1100 | E12: 所得税率 | F12: 0.25 | I12: 价差为0.45时： | K12: 0.11605349 | U12: 所得税率 | V12: 0.25
B13: PCS效率 | C13: 0.98 | E13: 增值税率 | F13: 0 | G13: 暂不考虑 | I13: 价差为0.3时： | K13: 0.088828898 | U13: 增值税率 | V13: 0 | W13: 暂不考虑
B14: 线损 | C14: 0.98 | E14: 储能系统经济效益估算表（元） | U14: 储能系统经济效益估算表（元）
B15: 峰价（元/KWh) | C15: 0.53 | E15: 储能平准化成本LCOS（Levelized Cost of Storage） | G15: 1 | H15: 2 | I15: 3 | J15: 4 | K15: 5 | L15: 6 | M15: 7 | N15: 8 | O15: 9 | P15: 10 | Q15: 11 | R15: 12 | S15: 13 | U15: 储能平准化成本LCOS（Levelized Cost of Storage） | W15: 1 | X15: 2 | Y15: 3 | Z15: 4 | AA15: 5 | AB15: 6 | AC15: 7 | AD15: 8 | AE15: 9 | AF15: 10 | AG15: 11 | AH15: 12 | AI15: 13
B16: 平价（元/KWh) | C16: 0 | F16: 基准年 | G16: 第1年 | H16: 第2年 | I16: 第3年 | J16: 第4年 | K16: 第5年 | L16: 第6年 | M16: 第7年 | N16: 第8年 | O16: 第9年 | P16: 第10年 | Q16: 第11年 | R16: 第12年 | S16: 第13年 | V16: 基准年 | W16: 第1年 | X16: 第2年 | Y16: 第3年 | Z16: 第4年 | AA16: 第5年 | AB16: 第6年 | AC16: 第7年 | AD16: 第8年 | AE16: 第9年 | AF16: 第10年 | AG16: 第11年 | AH16: 第12年 | AI16: 第13年
B17: 谷价（元/KWh) | C17: 0 | E17: 初始投资成本（Mn RMB） | F17: =C37/1000000 -> 311 | U17: 初始投资成本（Mn RMB） | V17: =C37/1000000 -> 311
B18: 系统年使用天数 (天) | C18: 350 | D18: =C15-C17 -> 0.53 | E18: 折旧现值和（Mn RMB） | F18: =SUM(G19:S19) -> 108.91363 | U18: 折旧现值和（Mn RMB） | V18: =SUM(W19:AI19) -> 169.41091
B19: DOD% | C19: 0.95 | E19: 折旧现值（Mn RMB） | G19: =($C$33+$C$34+$C$24)*(1-$C$27)/$C$32/1000000/(1+$F$11)^G15+($C$35)*(1-$C$23)/$C$32/1000000/(1+$F$11)^G15 -> 12.179073 | H19: =($C$33+$C$34+$C$24)*(1-$C$27)/$C$32/1000000/(1+$F$11)^H15+($C$35)*(1-$C$23)/$C$32/1000000/(1+$F$11)^H15 -> 11.382312 | I19: =($C$33+$C$34+$C$24)*(1-$C$27)/$C$32/1000000/(1+$F$11)^I15+($C$35)*(1-$C$23)/$C$32/1000000/(1+$F$11)^I15 -> 10.637674 | J19: =($C$33+$C$34+$C$24)*(1-$C$27)/$C$32/1000000/(1+$F$11)^J15+($C$35)*(1-$C$23)/$C$32/1000000/(1+$F$11)^J15 -> 9.9417518 | K19: =($C$33+$C$34+$C$24)*(1-$C$27)/$C$32/1000000/(1+$F$11)^K15+($C$35)*(1-$C$23)/$C$32/1000000/(1+$F$11)^K15 -> 9.2913568 | L19: =($C$33+$C$34+$C$24)*(1-$C$27)/$C$32/1000000/(1+$F$11)^L15+($C$35)*(1-$C$23)/$C$32/1000000/(1+$F$11)^L15 -> 8.683511 | M19: =($C$33+$C$34+$C$24)*(1-$C$27)/$C$32/1000000/(1+$F$11)^M15+($C$35)*(1-$C$23)/$C$32/1000000/(1+$F$11)^M15 -> 8.1154309 | N19: =($C$33+$C$34+$C$24)*(1-$C$27)/$C$32/1000000/(1+$F$11)^N15+($C$35)*(1-$C$23)/$C$32/1000000/(1+$F$11)^N15 -> 7.5845148 | ... S19: =($C$33+$C$34+$C$24)*(1-$C$27)/$C$32/1000000/(1+$F$11)^S15+($C$35)*(1-$C$23)/$C$32/1000000/(1+$F$11)^S15 -> 5.4076543 | U19: 折旧现值（Mn RMB） | W19: =($C$33+$C$34+$C$24)*(1-$C$27)/$C$32/1000000/(1+$V$11)^W15+($C$35)*(1-$C$23)/$C$32/1000000/(1+$V$11)^W15 -> 13.031609 | X19: =($C$33+$C$34+$C$24)*(1-$C$27)/$C$32/1000000/(1+$V$11)^X15+($C$35)*(1-$C$23)/$C$32/1000000/(1+$V$11)^X15 -> 13.031609 | Y19: =($C$33+$C$34+$C$24)*(1-$C$27)/$C$32/1000000/(1+$V$11)^Y15+($C$35)*(1-$C$23)/$C$32/1000000/(1+$V$11)^Y15 -> 13.031609 | Z19: =($C$33+$C$34+$C$24)*(1-$C$27)/$C$32/1000000/(1+$V$11)^Z15+($C$35)*(1-$C$23)/$C$32/1000000/(1+$V$11)^Z15 -> 13.031609 | AA19: =($C$33+$C$34+$C$24)*(1-$C$27)/$C$32/1000000/(1+$V$11)^AA15+($C$35)*(1-$C$23)/$C$32/1000000/(1+$V$11)^AA15 -> 13.031609 | AB19: =($C$33+$C$34+$C$24)*(1-$C$27)/$C$32/1000000/(1+$V$11)^AB15+($C$35)*(1-$C$23)/$C$32/1000000/(1+$V$11)^AB15 -> 13.031609 | AC19: =($C$33+$C$34+$C$24)*(1-$C$27)/$C$32/1000000/(1+$V$11)^AC15+($C$35)*(1-$C$23)/$C$32/1000000/(1+$V$11)^AC15 -> 13.031609 | AD19: =($C$33+$C$34+$C$24)*(1-$C$27)/$C$32/1000000/(1+$V$11)^AD15+($C$35)*(1-$C$23)/$C$32/1000000/(1+$V$11)^AD15 -> 13.031609 | ... AI19: =($C$33+$C$34+$C$24)*(1-$C$27)/$C$32/1000000/(1+$V$11)^AI15+($C$35)*(1-$C$23)/$C$32/1000000/(1+$V$11)^AI15 -> 13.031609
B20: 单次循环衰减率 | C20: 4.68e-05 | E20: 运行成本现值和（Mn RMB） | F20: =SUM(G21:S21) -> 12.996147 | U20: 运行成本现值和（Mn RMB） | V20: =SUM(W21:AI21) -> 20.215
B21: 系统报废终止标准 | C21: 0.7 | E21: 运行成本现值（Mn RMB） | G21: =($C$26*$F$17)/((1+$F$11)^G15) -> 1.453271 | H21: =($C$26*$F$17)/((1+$F$11)^H15) -> 1.3581972 | I21: =($C$26*$F$17)/((1+$F$11)^I15) -> 1.2693432 | J21: =($C$26*$F$17)/((1+$F$11)^J15) -> 1.1863021 | K21: =($C$26*$F$17)/((1+$F$11)^K15) -> 1.1086935 | L21: =($C$26*$F$17)/((1+$F$11)^L15) -> 1.0361622 | M21: =($C$26*$F$17)/((1+$F$11)^M15) -> 0.96837585 | N21: =($C$26*$F$17)/((1+$F$11)^N15) -> 0.90502416 | ... S21: =($C$26*$F$17)/((1+$F$11)^S15) -> 0.64526972 | U21: 运行成本现值（Mn RMB） | W21: =($C$26*$V$17)/((1+$V$11)^W15) -> 1.555 | X21: =($C$26*$V$17)/((1+$V$11)^X15) -> 1.555 | Y21: =($C$26*$V$17)/((1+$V$11)^Y15) -> 1.555 | Z21: =($C$26*$V$17)/((1+$V$11)^Z15) -> 1.555 | AA21: =($C$26*$V$17)/((1+$V$11)^AA15) -> 1.555 | AB21: =($C$26*$V$17)/((1+$V$11)^AB15) -> 1.555 | AC21: =($C$26*$V$17)/((1+$V$11)^AC15) -> 1.555 | AD21: =($C$26*$V$17)/((1+$V$11)^AD15) -> 1.555 | ... AI21: =($C$26*$V$17)/((1+$V$11)^AI15) -> 1.555
B22: 土建成本(元/Wh) | C22: 0.2 | E22: 固定资产残值现值 (Mn RMB) | S22: =($C$33+$C$34)*$C$27/((1+$F$11)^$S$15)/1000000+($C$35)*$C$23/((1+$F$11)^$S$15)/1000000 -> 15.789397 | U22: 固定资产残值现值 (Mn RMB) | AI22: =($C$33+$C$34)*$C$27/((1+$V$11)^$AI$15)/1000000+($C$35)*$C$23/((1+$V$11)^$AI$15)/1000000 -> 38.05
