Workbook

Sheet 分布式光伏电站IRR汇总
A1: 基本假设 | E1: 年利用小时数 | F1: IRR（%） | G1: 度电成本（元/kWh)-折现率=0% | H1: 度电成本（元/kWh)-折现率=7% | I1: NPV-折现率=7%（Mn RMB）
A2: 总装机规模（MW） | B2: 6 | D2: 全国 | E2: ='分布式光伏经济性模型-分地区'!D2 -> 1163 | F2: ='分布式光伏经济性模型-分地区'!D7 -> 0.1100902 | G2: ='分布式光伏经济性模型-分地区'!D3 -> 0.21682188 | H2: ='分布式光伏经济性模型-分地区'!D4 -> 0.40532963 | I2: ='分布式光伏经济性模型-分地区'!D6 -> 8.0004551
A3: 单位面积光伏板容量（w/㎡) | B3: 120 | D3: I类区域 | E3: ='分布式光伏经济性模型-分地区'!D48 -> 1600 | F3: ='分布式光伏经济性模型-分地区'!D53 -> 0.16372554 | G3: ='分布式光伏经济性模型-分地区'!D49 -> 0.31572436 | H3: ='分布式光伏经济性模型-分地区'!D50 -> 0.43598196 | I3: ='分布式光伏经济性模型-分地区'!D52 -> 19.807756
A4: 单位面积光伏板占地面积（㎡） | B4: 3 | D4: II类区域 | E4: ='分布式光伏经济性模型-分地区'!D94 -> 1300 | F4: ='分布式光伏经济性模型-分地区'!D99 -> 0.12743037 | G4: ='分布式光伏经济性模型-分地区'!D95 -> 0.34877613 | H4: ='分布式光伏经济性模型-分地区'!D96 -> 0.50213268 | I4: ='分布式光伏经济性模型-分地区'!D98 -> 11.702057
A5: 光伏板制造面积（万㎡） | B5: =B2/B3*1000000/10000 -> 5 | D5: III类区域 | E5: ='分布式光伏经济性模型-分地区'!D140 -> 1100 | F5: ='分布式光伏经济性模型-分地区'!D145 -> 0.10189969 | G5: ='分布式光伏经济性模型-分地区'!D141 -> 0.38082633 | H5: ='分布式光伏经济性模型-分地区'!D142 -> 0.56627884 | I5: ='分布式光伏经济性模型-分地区'!D144 -> 6.2982584
A6: 光伏实际占地面积（万㎡） | B6: =B5*B4 -> 15 | D6: 内蒙古I类 | E6: ='分布式光伏经济性模型-分地区'!D186 -> 1626 | F6: ='分布式光伏经济性模型-分地区'!D191 -> 0.14453729 | G6: ='分布式光伏经济性模型-分地区'!D187 -> 0.29363846 | H6: ='分布式光伏经济性模型-分地区'!D188 -> 0.41426168 | I6: ='分布式光伏经济性模型-分地区'!D190 -> 15.46861
A7: 项目初始投资成本（元/W) | B7: =SUM(B8:B18) -> 4.102 | D7: 内蒙古II类 | E7: ='分布式光伏经济性模型-分地区'!D232 -> 1619 | F7: ='分布式光伏经济性模型-分地区'!D237 -> 0.14378662 | G7: ='分布式光伏经济性模型-分地区'!D233 -> 0.29424781 | H7: ='分布式光伏经济性模型-分地区'!D234 -> 0.41548126 | I7: ='分布式光伏经济性模型-分地区'!D236 -> 15.301181
A8: 组件（元/W) | B8: 1.887 | D8: 新疆I类 | E8: ='分布式光伏经济性模型-分地区'!D278 -> 1655 | F8: ='分布式光伏经济性模型-分地区'!D283 -> 0.0881612 | G8: ='分布式光伏经济性模型-分地区'!D279 -> 0.24238963 | H8: ='分布式光伏经济性模型-分地区'!D280 -> 0.36709211 | I8: ='分布式光伏经济性模型-分地区'!D282 -> 3.5173968
A9: 逆变器（元/W) | B9: 0.185 | D9: 新疆II类 | E9: ='分布式光伏经济性模型-分地区'!D324 -> 1414 | F9: ='分布式光伏经济性模型-分地区'!D329 -> 0.06783842 | G9: ='分布式光伏经济性模型-分地区'!D325 -> 0.26598933 | H9: ='分布式光伏经济性模型-分地区'!D326 -> 0.41432519 | I9: ='分布式光伏经济性模型-分地区'!D328 -> -0.40559293
A10: 支架（元/W) | B10: 0.222 | D10: 甘肃I类 | E10: ='分布式光伏经济性模型-分地区'!D370 -> 1535 | F10: ='分布式光伏经济性模型-分地区'!D375 -> 0.15284889 | G10: ='分布式光伏经济性模型-分地区'!D371 -> 0.31880715 | H10: ='分布式光伏经济性模型-分地区'!D372 -> 0.44553885 | I10: ='分布式光伏经济性模型-分地区'!D374 -> 17.334539
A11: 电缆（元/W) | B11: 0.444 | D11: 甘肃II类 | E11: ='分布式光伏经济性模型-分地区'!D416 -> 1263 | F11: ='分布式光伏经济性模型-分地区'!D421 -> 0.12005585 | G11: ='分布式光伏经济性模型-分地区'!D417 -> 0.35095811 | H11: ='分布式光伏经济性模型-分地区'!D418 -> 0.50988668 | I11: ='分布式光伏经济性模型-分地区'!D420 -> 10.112421
A12: 建安费用（元/W) | B12: 0.222 | D12: 青海I类 | E12: ='分布式光伏经济性模型-分地区'!D462 -> 1436 | F12: ='分布式光伏经济性模型-分地区'!D467 -> 0.069719373 | G12: ='分布式光伏经济性模型-分地区'!D463 -> 0.2634827 | H12: ='分布式光伏经济性模型-分地区'!D464 -> 0.40933533 | I12: ='分布式光伏经济性模型-分地区'!D466 -> -0.052819616
A13: 屋顶租赁（元/W) | B13: 0.15 | D13: 青海II类 | E13: ='分布式光伏经济性模型-分地区'!D508 -> 1387 | F13: ='分布式光伏经济性模型-分地区'!D513 -> 0.065450509 | G13: ='分布式光伏经济性模型-分地区'!D509 -> 0.26912041 | H13: ='分布式光伏经济性模型-分地区'!D510 -> 0.42061878 | I13: ='分布式光伏经济性模型-分地区'!D512 -> -0.85025766
A14: 电网接入（元/W) | B14: 0.037 | D14: 宁夏I类 | E14: ='分布式光伏经济性模型-分地区'!D554 -> 1390 | F14: ='分布式光伏经济性模型-分地区'!D559 -> 0.084737541 | G14: ='分布式光伏经济性模型-分地区'!D555 -> 0.28548882 | H14: ='分布式光伏经济性模型-分地区'!D556 -> 0.4343835 | I14: ='分布式光伏经济性模型-分地区'!D558 -> 2.8399033
A15: 房顶加固（元/W) | B15: 0.259 | D15: 陕西II类 | E15: ='分布式光伏经济性模型-分地区'!D600 -> 1466 | F15: ='分布式光伏经济性模型-分地区'!D605 -> 0.11985932 | G15: ='分布式光伏经济性模型-分地区'!D601 -> 0.30217705 | H15: ='分布式光伏经济性模型-分地区'!D602 -> 0.43912306 | I15: ='分布式光伏经济性模型-分地区'!D604 -> 10.07036
A16: 二次设备（元/W) | B16: 0.074 | D16: 黑龙江II类 | E16: ='分布式光伏经济性模型-分地区'!D646 -> 1507 | F16: ='分布式光伏经济性模型-分地区'!D651 -> 0.16416035 | G16: ='分布式光伏经济性模型-分地区'!D647 -> 0.33563013 | H16: ='分布式光伏经济性模型-分地区'!D648 -> 0.46325242 | I16: ='分布式光伏经济性模型-分地区'!D650 -> 19.907318
A17: 一次设备（元/W) | B17: 0.222 | D17: 吉林II类 | E17: ='分布式光伏经济性模型-分地区'!D692 -> 1477 | F17: ='分布式光伏经济性模型-分地区'!D697 -> 0.16601345 | G17: ='分布式光伏经济性模型-分地区'!D693 -> 0.34428389 | H17: ='分布式光伏经济性模型-分地区'!D694 -> 0.47425166 | I17: ='分布式光伏经济性模型-分地区'!D696 -> 20.332212
A18: 其它（元/W) | B18: 0.4 | D18: 辽宁II类 | E18: ='分布式光伏经济性模型-分地区'!D738 -> 1388 | F18: ='分布式光伏经济性模型-分地区'!D743 -> 0.13732419 | G18: ='分布式光伏经济性模型-分地区'!D739 -> 0.33662487 | H18: ='分布式光伏经济性模型-分地区'!D740 -> 0.47892046 | I18: ='分布式光伏经济性模型-分地区'!D742 -> 13.867705
A19: 系统运行效率（%） | B19: 0.866 | D19: 河北II类 | E19: ='分布式光伏经济性模型-分地区'!D784 -> 1485 | F19: ='分布式光伏经济性模型-分地区'!D789 -> 0.12839616 | G19: ='分布式光伏经济性模型-分地区'!D785 -> 0.3062278 | H19: ='分布式光伏经济性模型-分地区'!D786 -> 0.44035818 | I19: ='分布式光伏经济性模型-分地区'!D788 -> 11.911838
A20: 系统寿命（年） | B20: 20 | D20: 山西II类 | E20: ='分布式光伏经济性模型-分地区'!D830 -> 1470 | F20: ='分布式光伏经济性模型-分地区'!D835 -> 0.1086839 | G20: ='分布式光伏经济性模型-分地区'!D831 -> 0.29108594 | H20: ='分布式光伏经济性模型-分地区'!D832 -> 0.42903868 | I20: ='分布式光伏经济性模型-分地区'!D834 -> 7.7059653
A21: 组件光衰率（%）-首年） | B21: 0.02 | D21: 四川II类 | E21: ='分布式光伏经济性模型-分地区'!D876 -> 1466 | F21: ='分布式光伏经济性模型-分地区'!D881 -> 0.1521578 | G21: ='分布式光伏经济性模型-分地区'!D877 -> 0.33313314 | H21: ='分布式光伏经济性模型-分地区'!D878 -> 0.46592094 | I21: ='分布式光伏经济性模型-分地区'!D880 -> 17.178567
A22: 组件光衰率（%）-逐年光衰 | B22: 0.0045 | D22: 河北II/III类 | E22: ='分布式光伏经济性模型-分地区'!D922 -> 1336 | F22: ='分布式光伏经济性模型-分地区'!D927 -> 0.11183224 | G22: ='分布式光伏经济性模型-分地区'!D923 -> 0.32343817 | H22: ='分布式光伏经济性模型-分地区'!D924 -> 0.47480349 | I22: ='分布式光伏经济性模型-分地区'!D926 -> 8.3664931
A23: 运维成本（元/W) | B23: 0.04 | D23: 云南III类 | E23: ='分布式光伏经济性模型-分地区'!D968 -> 1332 | F23: ='分布式光伏经济性模型-分地区'!D973 -> 0.092340545 | G23: ='分布式光伏经济性模型-分地区'!D969 -> 0.30517252 | H23: ='分布式光伏经济性模型-分地区'!D970 -> 0.4595764 | I23: ='分布式光伏经济性模型-分地区'!D972 -> 4.3530199
A24: 系统残值率（元/W) | B24: 0.05 | D24: 天津III类 | E24: ='分布式光伏经济性模型-分地区'!D1014 -> 1265 | F24: ='分布式光伏经济性模型-分地区'!D1019 -> 0.12337944 | G24: ='分布式光伏经济性模型-分地区'!D1015 -> 0.35400533 | H24: ='分布式光伏经济性模型-分地区'!D1016 -> 0.51219877 | I24: ='分布式光伏经济性模型-分地区'!D1018 -> 10.826138
A25: 初始投资成本（Mn RMB） | B25: =B2*B7 -> 24.612 | D25: 北京II类 | E25: ='分布式光伏经济性模型-分地区'!D1060 -> 1242 | F25: ='分布式光伏经济性模型-分地区'!D1065 -> 0.14900503 | G25: ='分布式光伏经济性模型-分地区'!D1061 -> 0.38956708 | H25: ='分布式光伏经济性模型-分地区'!D1062 -> 0.54679376 | I25: ='分布式光伏经济性模型-分地区'!D1064 -> 16.468888
A26: 标杆上网电价（元/kWh) | B26: 0.3598 | D26: 山东III类 | E26: ='分布式光伏经济性模型-分地区'!D1106 -> 1225 | F26: ='分布式光伏经济性模型-分地区'!D1111 -> 0.11527281 | G26: ='分布式光伏经济性模型-分地区'!D1107 -> 0.35653406 | H26: ='分布式光伏经济性模型-分地区'!D1108 -> 0.52110605 | I26: ='分布式光伏经济性模型-分地区'!D1110 -> 9.0933944
A27: 电价优惠比例（%） | B27: 1 | D27: 江苏III类 | E27: ='分布式光伏经济性模型-分地区'!D1152 -> 1165 | F27: ='分布式光伏经济性模型-分地区'!D1157 -> 0.11280945 | G27: ='分布式光伏经济性模型-分地区'!D1153 -> 0.37204131 | H27: ='分布式光伏经济性模型-分地区'!D1154 -> 0.54547261 | I27: ='分布式光伏经济性模型-分地区'!D1156 -> 8.5724211
D28: 西藏III类 | E28: ='分布式光伏经济性模型-分地区'!D1198 -> 1116 | F28: ='分布式光伏经济性模型-分地区'!D1203 -> 0.074061503 | G28: ='分布式光伏经济性模型-分地区'!D1199 -> 0.34373958 | H28: ='分布式光伏经济性模型-分地区'!D1200 -> 0.53078157 | I28: ='分布式光伏经济性模型-分地区'!D1202 -> 0.76984301
D29: 广西III类 | E29: ='分布式光伏经济性模型-分地区'!D1244 -> 1103 | F29: ='分布式光伏经济性模型-分地区'!D1249 -> 0.095422001 | G29: ='分布式光伏经济性模型-分地区'!D1245 -> 0.37213133 | H29: ='分布式光伏经济性模型-分地区'!D1246 -> 0.55810827 | I29: ='分布式光伏经济性模型-分地区'!D1248 -> 4.9750157
D30: 安徽III类 | E30: ='分布式光伏经济性模型-分地区'!D1290 -> 1071 | F30: ='分布式光伏经济性模型-分地区'!D1295 -> 0.0997014 | G30: ='分布式光伏经济性模型-分地区'!D1291 -> 0.38844729 | H30: ='分布式光伏经济性模型-分地区'!D1292 -> 0.57928284 | I30: ='分布式光伏经济性模型-分地区'!D1294 -> 5.8468579
D31: 海南III类 | E31: ='分布式光伏经济性模型-分地区'!D1336 -> 1063 | F31: ='分布式光伏经济性模型-分地区'!D1341 -> 0.098787316 | G31: ='分布式光伏经济性模型-分地区'!D1337 -> 0.39024758 | H31: ='分布式光伏经济性模型-分地区'!D1338 -> 0.5826702 | I31: ='分布式光伏经济性模型-分地区'!D1340 -> 5.6598598
D32: 福建III类 | E32: ='分布式光伏经济性模型-分地区'!D1382 -> 1063 | F32: ='分布式光伏经济性模型-分地区'!D1387 -> 0.077314954 | G32: ='分布式光伏经济性模型-分地区'!D1383 -> 0.36462477 | H32: ='分布式光伏经济性模型-分地区'!D1384 -> 0.56048919 | I32: ='分布式光伏经济性模型-分地区'!D1386 -> 1.3936704
D33: 河南III类 | E33: ='分布式光伏经济性模型-分地区'!D1428 -> 1055 | F33: ='分布式光伏经济性模型-分地区'!D1433 -> 0.090538482 | G33: ='分布式光伏经济性模型-分地区'!D1429 -> 0.38311106 | H33: ='分布式光伏经济性模型-分地区'!D1430 -> 0.57834892 | I33: ='分布式光伏经济性模型-分地区'!D1432 -> 3.9915722
D34: 贵州III类 | E34: ='分布式光伏经济性模型-分地区'!D1474 -> 1032 | F34: ='分布式光伏经济性模型-分地区'!D1479 -> 0.058857916 | G34: ='分布式光伏经济性模型-分地区'!D1475 -> 0.35421826 | H34: ='分布式光伏经济性模型-分地区'!D1476 -> 0.55883532 | I34: ='分布式光伏经济性模型-分地区'!D1478 -> -2.0589471
D35: 湖北III类 | E35: ='分布式光伏经济性模型-分地区'!D1520 -> 1013 | F35: ='分布式光伏经济性模型-分地区'!D1525 -> 0.097768514 | G35: ='分布式光伏经济性模型-分地区'!D1521 -> 0.40819908 | H35: ='分布式光伏经济性模型-分地区'!D1522 -> 0.61029539 | I35: ='分布式光伏经济性模型-分地区'!D1524 -> 5.4519298
D36: 浙江III类 | E36: ='分布式光伏经济性模型-分地区'!D1566 -> 998 | F36: ='分布式光伏经济性模型-分地区'!D1571 -> 0.12763245 | G36: ='分布式光伏经济性模型-分地区'!D1567 -> 0.4545982 | H36: ='分布式光伏经济性模型-分地区'!D1568 -> 0.65432356 | I36: ='分布式光伏经济性模型-分地区'!D1570 -> 11.745921
D37: 广东III类 | E37: ='分布式光伏经济性模型-分地区'!D1612 -> 993 | F37: ='分布式光伏经济性模型-分地区'!D1617 -> 0.10081514 | G37: ='分布式光伏经济性模型-分地区'!D1613 -> 0.42042825 | H37: ='分布式光伏经济性模型-分地区'!D1614 -> 0.62605665 | I37: ='分布式光伏经济性模型-分地区'!D1616 -> 6.0752586
D38: 江西III类 | E38: ='分布式光伏经济性模型-分地区'!D1658 -> 917 | F38: ='分布式光伏经济性模型-分地区'!D1663 -> 0.074208781 | G38: ='分布式光伏经济性模型-分地区'!D1659 -> 0.41853085 | H38: ='分布式光伏经济性模型-分地区'!D1660 -> 0.64613692 | I38: ='分布式光伏经济性模型-分地区'!D1662 -> 0.79794662
D39: 湖南III类 | E39: ='分布式光伏经济性模型-分地区'!D1704 -> 902 | F39: ='分布式光伏经济性模型-分地区'!D1709 -> 0.08233381 | G39: ='分布式光伏经济性模型-分地区'!D1705 -> 0.43660467 | H39: ='分布式光伏经济性模型-分地区'!D1706 -> 0.6665029 | I39: ='分布式光伏经济性模型-分地区'!D1708 -> 2.3681217
D40: 上海III类 | E40: ='分布式光伏经济性模型-分地区'!D1750 -> 861 | F40: ='分布式光伏经济性模型-分地区'!D1755 -> 0.070000415 | G40: ='分布式光伏经济性模型-分地区'!D1751 -> 0.4398361 | H40: ='分布式光伏经济性模型-分地区'!D1752 -> 0.68304052 | I40: ='分布式光伏经济性模型-分地区'!D1754 -> 7.8094694e-05
...

Sheet 自发自用比例=70%
B1: 全国 | C1: 工商业——分布式光伏
C2: 年利用小时数 | D2: =D33 -> 1163
C3: 度电成本（元/kWh)-折现率=0% | D3: =G27/G33*1000 -> 0.21682188 | F3: LCOE(LevelizedCost of Electricity,平准发电成本)
C4: 度电成本（元/kWh)-折现率=7% | D4: =G8/G14*1000 -> 0.40532963 | F4: 折现率 | G4: 0.07
C5: 投资回报率 | D5: =G21 -> 0.14176792 | F5: 所得税率 | G5: 0.25
C6: NPV-折现率=7%（Mn RMB） | D6: =SUM(G20:AA20) -> 3.4891921 | F6: 光伏项目经济性测算 | H6: 1 | I6: 2 | J6: 3 | K6: 4 | L6: 5 | M6: 6 | N6: 7 | O6: 8 | P6: 9 | Q6: 10 | R6: 11 | S6: 12 | T6: 13 | U6: 14 | V6: 15 | W6: 16 | X6: 17 | Y6: 18 | Z6: 19 | AA6: 20
C7: IRR | D7: =G40 -> 0.088019313 | G7: 基准年 | H7: 第1年 | I7: 第2年 | J7: 第3年 | K7: 第4年 | L7: 第5年 | M7: 第6年 | N7: 第7年 | O7: 第8年 | P7: 第9年 | Q7: 第10年 | R7: 第11年 | S7: 第12年 | T7: 第13年 | U7: 第14年 | V7: 第15年 | W7: 第16年 | X7: 第17年 | Y7: 第18年 | Z7: 第19年 | AA7: 第20年
F8: 初始投资成本（Mn RMB） | G8: =D34 -> 24.612
C9: 基本假设 | F9: 折旧现值和（Mn RMB） | G9: =SUM(H10:AA10) -> 12.385144
C10: 总装机规模（MW） | D10: =分布式光伏电站IRR汇总!$B$2 -> 6 | F10: 折旧现值（Mn RMB） | H10: =D34*(1-D32)/D28/((1+G4)^H6) -> 1.0925888 | I10: =D34*(1-D32)/D28/((1+G4)^I6) -> 1.021111 | J10: =D34*(1-D32)/D28/((1+G4)^J6) -> 0.95430936 | K10: =D34*(1-D32)/D28/((1+G4)^K6) -> 0.89187791 | L10: =D34*(1-D32)/D28/((1+G4)^L6) -> 0.83353075 | M10: =D34*(1-D32)/D28/((1+G4)^M6) -> 0.7790007 | N10: =D34*(1-D32)/D28/((1+G4)^N6) -> 0.72803804 | O10: =D34*(1-D32)/D28/((1+G4)^O6) -> 0.68040938 | P10: =D34*(1-D32)/D28/((1+G4)^P6) -> 0.63589662 | Q10: =D34*(1-D32)/D28/((1+G4)^Q6) -> 0.59429591 | R10: =D34*(1-D32)/D28/((1+G4)^R6) -> 0.55541674 | S10: =D34*(1-D32)/D28/((1+G4)^S6) -> 0.51908106 | T10: =D34*(1-D32)/D28/((1+G4)^T6) -> 0.48512249 | U10: =D34*(1-D32)/D28/((1+G4)^U6) -> 0.4533855 | V10: =D34*(1-D32)/D28/((1+G4)^V6) -> 0.42372477 | W10: =D34*(1-D32)/D28/((1+G4)^W6) -> 0.39600446 | X10: =D34*(1-D32)/D28/((1+G4)^X6) -> 0.37009762 | Y10: =D34*(1-D32)/D28/((1+G4)^Y6) -> 0.34588563 | Z10: =D34*(1-D32)/D28/((1+G4)^Z6) -> 0.3232576 | AA10: =D34*(1-D32)/D28/((1+G4)^AA6) -> 0.3021099
C11: 单位面积光伏板容量（w/㎡) | D11: =分布式光伏电站IRR汇总!$B$3 -> 120 | F11: 运行成本现值和（Mn RMB） | G11: =SUM(H12:AA12) -> 2.5425634
C12: 单位面积光伏板占地面积（㎡） | D12: =分布式光伏电站IRR汇总!$B$4 -> 3 | F12: 运行成本现值（Mn RMB） | H12: =D31*D10/((1+G4)^H6) -> 0.22429907 | I12: =D31*D10/((1+G4)^I6) -> 0.20962529 | J12: =D31*D10/((1+G4)^J6) -> 0.19591149 | K12: =D31*D10/((1+G4)^K6) -> 0.18309485 | L12: =D31*D10/((1+G4)^L6) -> 0.17111668 | M12: =D31*D10/((1+G4)^M6) -> 0.15992213 | N12: =D31*D10/((1+G4)^N6) -> 0.14945994 | O12: =D31*D10/((1+G4)^O6) -> 0.13968219 | P12: =D31*D10/((1+G4)^P6) -> 0.1305441 | Q12: =D31*D10/((1+G4)^Q6) -> 0.12200383 | R12: =D31*D10/((1+G4)^R6) -> 0.11402227 | S12: =D31*D10/((1+G4)^S6) -> 0.10656287 | T12: =D31*D10/((1+G4)^T6) -> 0.099591467 | U12: =D31*D10/((1+G4)^U6) -> 0.093076138 | V12: =D31*D10/((1+G4)^V6) -> 0.086987045 | W12: =D31*D10/((1+G4)^W6) -> 0.081296303 | X12: =D31*D10/((1+G4)^X6) -> 0.075977854 | Y12: =D31*D10/((1+G4)^Y6) -> 0.07100734 | Z12: =D31*D10/((1+G4)^Z6) -> 0.066362 | AA12: =D31*D10/((1+G4)^AA6) -> 0.062020561
C13: 光伏板制造面积（万㎡） | D13: =分布式光伏电站IRR汇总!$B$5 -> 5 | F13: 固定资产残值现值 (Mn RMB) | AA13: =D31*D34/((1+G4)^AA6) -> 0.25440834
C14: 光伏实际占地面积（万㎡） | D14: =分布式光伏电站IRR汇总!$B$6 -> 15 | F14: 发电电量现值和(MWh) | G14: =SUM(H15:AA15) -> 60720.95
C15: 项目初始投资成本（元/W) | D15: =分布式光伏电站IRR汇总!$B$7 -> 4.102 | F15: 发电电量现值(MWh) | H15: =D10*D27*(1-D29)*D33/((1+G4)^H6) -> 5534.6627 | I15: =D10*D27*(1-D29)*(1-D30)^(I6-1)*D33/((1+G4)^I6) -> 5149.3053 | J15: =D10*D27*(1-D29)*(1-D30)^(J6-1)*D33/((1+G4)^J6) -> 4790.7789 | K15: =D10*D27*(1-D29)*(1-D30)^(K6-1)*D33/((1+G4)^K6) -> 4457.2153 | L15: =D10*D27*(1-D29)*(1-D30)^(L6-1)*D33/((1+G4)^L6) -> 4146.8765 | M15: =D10*D27*(1-D29)*(1-D30)^(M6-1)*D33/((1+G4)^M6) -> 3858.1454 | N15: =D10*D27*(1-D29)*(1-D30)^(N6-1)*D33/((1+G4)^N6) -> 3589.5175 | O15: =D10*D27*(1-D29)*(1-D30)^(O6-1)*D33/((1+G4)^O6) -> 3339.5932 | P15: =D10*D27*(1-D29)*(1-D30)^(P6-1)*D33/((1+G4)^P6) -> 3107.0701 | Q15: =D10*D27*(1-D29)*(1-D30)^(Q6-1)*D33/((1+G4)^Q6) -> 2890.7367 | R15: =D10*D27*(1-D29)*(1-D30)^(R6-1)*D33/((1+G4)^R6) -> 2689.4658 | S15: =D10*D27*(1-D29)*(1-D30)^(S6-1)*D33/((1+G4)^S6) -> 2502.2086 | T15: =D10*D27*(1-D29)*(1-D30)^(T6-1)*D33/((1+G4)^T6) -> 2327.9894 | U15: =D10*D27*(1-D29)*(1-D30)^(U6-1)*D33/((1+G4)^U6) -> 2165.9004 | V15: =D10*D27*(1-D29)*(1-D30)^(V6-1)*D33/((1+G4)^V6) -> 2015.0971 | W15: =D10*D27*(1-D29)*(1-D30)^(W6-1)*D33/((1+G4)^W6) -> 1874.7936 | X15: =D10*D27*(1-D29)*(1-D30)^(X6-1)*D33/((1+G4)^X6) -> 1744.2589 | Y15: =D10*D27*(1-D29)*(1-D30)^(Y6-1)*D33/((1+G4)^Y6) -> 1622.8128 | Z15: =D10*D27*(1-D29)*(1-D30)^(Z6-1)*D33/((1+G4)^Z6) -> 1509.8226 | AA15: =D10*D27*(1-D29)*(1-D30)^(AA6-1)*D33/((1+G4)^AA6) -> 1404.6994
C16: 组件（元/W) | D16: =分布式光伏电站IRR汇总!$B$8 -> 1.887 | F16: 发电收益现值和（Mn RMB） | G16: =SUM(H17:AA17) -> 35.882438
C17: 逆变器（元/W) | D17: =分布式光伏电站IRR汇总!$B$9 -> 0.185 | F17: 发电收益现值（Mn RMB） | H17: =H15*$D$38/1000*$D$40+H15*$D$35/1000*(1-$D$40) -> 3.2706535 | I17: =I15*$D$38/1000*$D$40+I15*$D$35/1000*(1-$D$40) -> 3.0429305 | J17: =J15*$D$38/1000*$D$40+J15*$D$35/1000*(1-$D$40) -> 2.8310629 | K17: =K15*$D$38/1000*$D$40+K15*$D$35/1000*(1-$D$40) -> 2.6339468 | L17: =L15*$D$38/1000*$D$40+L15*$D$35/1000*(1-$D$40) -> 2.4505552 | M17: =M15*$D$38/1000*$D$40+M15*$D$35/1000*(1-$D$40) -> 2.2799324 | N17: =N15*$D$38/1000*$D$40+N15*$D$35/1000*(1-$D$40) -> 2.1211895 | O17: =O15*$D$38/1000*$D$40+O15*$D$35/1000*(1-$D$40) -> 1.9734992 | ... AA17: =AA15*$D$38/1000*$D$40+AA15*$D$35/1000*(1-$D$40) -> 0.83009307
C18: 支架（元/W) | D18: =分布式光伏电站IRR汇总!$B$10 -> 0.222 | F18: 所得税现值和（Mn RMB） | G18: =SUM(H19:V19) -> 4.5572036
C19: 电缆（元/W) | D19: =分布式光伏电站IRR汇总!$B$11 -> 0.444 | F19: 所得税现值（Mn RMB） | H19: =(H17-H10-H12)*G5 -> 0.48844142 | I19: =(I17-I10-I12)*G5 -> 0.45304854 | J19: =(J17-J10-J12)*G5 -> 0.42021051 | K19: =(K17-K10-K12)*G5 -> 0.38974352 | L19: =(L17-L10-L12)*G5 -> 0.36147694 | M19: =(M17-M10-M12)*G5 -> 0.3352524 | N19: =(N17-N10-N12)*G5 -> 0.31092287 | O19: =(O17-O10-O12)*G5 -> 0.2883519 | P19: =(P17-P10-P12)*G5 -> 0.26741282 | Q19: =(Q17-Q10-Q12)*G5 -> 0.24798805 | R19: =(R17-R10-R12)*G5 -> 0.22996847 | S19: =(S17-S10-S12)*G5 -> 0.2132528 | T19: =(T17-T10-T12)*G5 -> 0.19774702 | U19: =(U17-U10-U12)*G5 -> 0.18336389 | V19: =(V17-V10-V12)*G5 -> 0.17002241 | W19: =(W17-W10-W12)*G5 -> 0.15764744 | X19: =(X17-X10-X12)*G5 -> 0.14616922 | Y19: =(Y17-Y10-Y12)*G5 -> 0.13552301 | Z19: =(Z17-Z10-Z12)*G5 -> 0.12564874 | AA19: =(AA17-AA10-AA12)*G5 -> 0.11649065
C20: 建安费用（元/W) | D20: =分布式光伏电站IRR汇总!$B$12 -> 0.222 | F20: NPV | G20: =-G8 -> -24.612 | H20: =H17-H19-H12 -> 2.5579131 | I20: =I17-I19-I12 -> 2.3802566 | J20: =J17-J19-J12 -> 2.2149409 | K20: =K17-K19-K12 -> 2.0611085 | L20: =L17-L19-L12 -> 1.9179616 | M20: =M17-M19-M12 -> 1.7847579 | N20: =N17-N19-N12 -> 1.6608067 | O20: =O17-O19-O12 -> 1.5454651 | ... AA20: =AA17-AA19-AA12 -> 0.65158186
C21: 屋顶租赁（元/W) | D21: =分布式光伏电站IRR汇总!$B$13 -> 0.15 | F21: 投资回报率 | G21: =SUM(G20:AA20)/G8 -> 0.14176792
C22: 电网接入（元/W) | D22: =分布式光伏电站IRR汇总!$B$14 -> 0.037
C23: 房顶加固（元/W) | D23: =分布式光伏电站IRR汇总!$B$15 -> 0.259 | F23: 折现率 | G23: 0
C24: 二次设备（元/W) | D24: =分布式光伏电站IRR汇总!$B$16 -> 0.074 | F24: 所得税率 | G24: 0.25
C25: 一次设备（元/W) | D25: =分布式光伏电站IRR汇总!$B$17 -> 0.222 | F25: 光伏项目经济性测算 | H25: 1 | I25: 2 | J25: 3 | K25: 4 | L25: 5 | M25: 6 | N25: 7 | O25: 8 | P25: 9 | Q25: 10 | R25: 11 | S25: 12 | T25: 13 | U25: 14 | V25: 15 | W25: 16 | X25: 17 | Y25: 18 | Z25: 19 | AA25: 20
C26: 其它（元/W) | D26: =分布式光伏电站IRR汇总!$B$18 -> 0.4 | G26: 基准年 | H26: 第1年 | I26: 第2年 | J26: 第3年 | K26: 第4年 | L26: 第5年 | M26: 第6年 | N26: 第7年 | O26: 第8年 | P26: 第9年 | Q26: 第10年 | R26: 第11年 | S26: 第12年 | T26: 第13年 | U26: 第14年 | V26: 第15年 | W26: 第16年 | X26: 第17年 | Y26: 第18年 | Z26: 第19年 | AA26: 第20年
C27: 系统运行效率（%） | D27: =分布式光伏电站IRR汇总!$B$19 -> 0.866 | F27: 初始投资成本（Mn RMB） | G27: =D34 -> 24.612
C28: 系统寿命（年） | D28: =分布式光伏电站IRR汇总!$B$20 -> 20 | F28: 折旧现值和（Mn RMB） | G28: =SUM(H29:AA29) -> 23.3814
C29: 组件光衰率（%）-首年） | D29: =分布式光伏电站IRR汇总!$B$21 -> 0.02 | F29: 折旧现值（Mn RMB） | H29: =D34*(1-D32)/D28/((1+G23)^H25) -> 1.16907 | I29: =D34*(1-D32)/D28/((1+G23)^I25) -> 1.16907 | J29: =D34*(1-D32)/D28/((1+G23)^J25) -> 1.16907 | K29: =D34*(1-D32)/D28/((1+G23)^K25) -> 1.16907 | L29: =D34*(1-D32)/D28/((1+G23)^L25) -> 1.16907 | M29: =D34*(1-D32)/D28/((1+G23)^M25) -> 1.16907 | N29: =D34*(1-D32)/D28/((1+G23)^N25) -> 1.16907 | O29: =D34*(1-D32)/D28/((1+G23)^O25) -> 1.16907 | P29: =D34*(1-D32)/D28/((1+G23)^P25) -> 1.16907 | Q29: =D34*(1-D32)/D28/((1+G23)^Q25) -> 1.16907 | R29: =D34*(1-D32)/D28/((1+G23)^R25) -> 1.16907 | S29: =D34*(1-D32)/D28/((1+G23)^S25) -> 1.16907 | T29: =D34*(1-D32)/D28/((1+G23)^T25) -> 1.16907 | U29: =D34*(1-D32)/D28/((1+G23)^U25) -> 1.16907 | V29: =D34*(1-D32)/D28/((1+G23)^V25) -> 1.16907 | W29: =D34*(1-D32)/D28/((1+G23)^W25) -> 1.16907 | X29: =D34*(1-D32)/D28/((1+G23)^X25) -> 1.16907 | Y29: =D34*(1-D32)/D28/((1+G23)^Y25) -> 1.16907 | Z29: =D34*(1-D32)/D28/((1+G23)^Z25) -> 1.16907 | AA29: =D34*(1-D32)/D28/((1+G23)^AA25) -> 1.16907
C30: 组件光衰率（%）-逐年光衰 | D30: =分布式光伏电站IRR汇总!$B$22 -> 0.0045 | F30: 运行成本现值和（Mn RMB） | G30: =SUM(H31:AA31) -> 4.8
C31: 运维成本（元/W) | D31: =分布式光伏电站IRR汇总!$B$23 -> 0.04 | F31: 运行成本现值（Mn RMB） | H31: =D31*D10/((1+G23)^H25) -> 0.24 | I31: =D31*D10/((1+G23)^I25) -> 0.24 | J31: =D31*D10/((1+G23)^J25) -> 0.24 | K31: =D31*D10/((1+G23)^K25) -> 0.24 | L31: =D31*D10/((1+G23)^L25) -> 0.24 | M31: =D31*D10/((1+G23)^M25) -> 0.24 | N31: =D31*D10/((1+G23)^N25) -> 0.24 | O31: =D31*D10/((1+G23)^O25) -> 0.24 | P31: =D31*D10/((1+G23)^P25) -> 0.24 | Q31: =D31*D10/((1+G23)^Q25) -> 0.24 | R31: =D31*D10/((1+G23)^R25) -> 0.24 | S31: =D31*D10/((1+G23)^S25) -> 0.24 | T31: =D31*D10/((1+G23)^T25) -> 0.24 | U31: =D31*D10/((1+G23)^U25) -> 0.24 | V31: =D31*D10/((1+G23)^V25) -> 0.24 | W31: =D31*D10/((1+G23)^W25) -> 0.24 | X31: =D31*D10/((1+G23)^X25) -> 0.24 | Y31: =D31*D10/((1+G23)^Y25) -> 0.24 | Z31: =D31*D10/((1+G23)^Z25) -> 0.24 | AA31: =D31*D10/((1+G23)^AA25) -> 0.24
C32: 系统残值率（元/W) | D32: =分布式光伏电站IRR汇总!$B$24 -> 0.05 | F32: 固定资产残值现值 (Mn RMB) | AA32: =D31*D34/((1+G23)^AA25) -> 0.98448
C33: 光伏利用小时数（h） | D33: 1163 | F33: 发电电量现值和(MWh) | G33: =SUM(H34:AA34) -> 113512.53
C34: 初始投资成本（Mn RMB） | D34: =D10*D15 -> 24.612 | F34: 发电电量现值(MWh) | H34: =D10*D27*(1-D29)*D33/((1+G23)^H25) -> 5922.089 | I34: =D10*D27*(1-D29)*(1-D30)^(I25-1)*D33/((1+G23)^I25) -> 5895.4396 | J34: =D10*D27*(1-D29)*(1-D30)^(J25-1)*D33/((1+G23)^J25) -> 5868.9102 | K34: =D10*D27*(1-D29)*(1-D30)^(K25-1)*D33/((1+G23)^K25) -> 5842.5001 | L34: =D10*D27*(1-D29)*(1-D30)^(L25-1)*D33/((1+G23)^L25) -> 5816.2088 | M34: =D10*D27*(1-D29)*(1-D30)^(M25-1)*D33/((1+G23)^M25) -> 5790.0359 | N34: =D10*D27*(1-D29)*(1-D30)^(N25-1)*D33/((1+G23)^N25) -> 5763.9807 | O34: =D10*D27*(1-D29)*(1-D30)^(O25-1)*D33/((1+G23)^O25) -> 5738.0428 | P34: =D10*D27*(1-D29)*(1-D30)^(P25-1)*D33/((1+G23)^P25) -> 5712.2216 | Q34: =D10*D27*(1-D29)*(1-D30)^(Q25-1)*D33/((1+G23)^Q25) -> 5686.5166 | R34: =D10*D27*(1-D29)*(1-D30)^(R25-1)*D33/((1+G23)^R25) -> 5660.9273 | S34: =D10*D27*(1-D29)*(1-D30)^(S25-1)*D33/((1+G23)^S25) -> 5635.4531 | T34: =D10*D27*(1-D29)*(1-D30)^(T25-1)*D33/((1+G23)^T25) -> 5610.0936 | U34: =D10*D27*(1-D29)*(1-D30)^(U25-1)*D33/((1+G23)^U25) -> 5584.8482 | V34: =D10*D27*(1-D29)*(1-D30)^(V25-1)*D33/((1+G23)^V25) -> 5559.7163 | W34: =D10*D27*(1-D29)*(1-D30)^(W25-1)*D33/((1+G23)^W25) -> 5534.6976 | X34: =D10*D27*(1-D29)*(1-D30)^(X25-1)*D33/((1+G23)^X25) -> 5509.7915 | Y34: =D10*D27*(1-D29)*(1-D30)^(Y25-1)*D33/((1+G23)^Y25) -> 5484.9974 | Z34: =D10*D27*(1-D29)*(1-D30)^(Z25-1)*D33/((1+G23)^Z25) -> 5460.3149 | AA34: =D10*D27*(1-D29)*(1-D30)^(AA25-1)*D33/((1+G23)^AA25) -> 5435.7435
C35: 标杆上网电价（元/kWh) | D35: 0.3598 | F35: 发电收益现值和（Mn RMB） | G35: =SUM(H36:AA36) -> 67.079094
C36: 工商业电价（元/kWh) | D36: 0.69 | F36: 发电收益现值（Mn RMB） | H36: =H34*$D$38/1000*$D$40+H34*$D$35/1000*(1-$D$40) -> 3.4995993 | I36: =I34*$D$38/1000*$D$40+I34*$D$35/1000*(1-$D$40) -> 3.4838511 | J36: =J34*$D$38/1000*$D$40+J34*$D$35/1000*(1-$D$40) -> 3.4681738 | K36: =K34*$D$38/1000*$D$40+K34*$D$35/1000*(1-$D$40) -> 3.452567 | L36: =L34*$D$38/1000*$D$40+L34*$D$35/1000*(1-$D$40) -> 3.4370304 | M36: =M34*$D$38/1000*$D$40+M34*$D$35/1000*(1-$D$40) -> 3.4215638 | N36: =N34*$D$38/1000*$D$40+N34*$D$35/1000*(1-$D$40) -> 3.4061668 | O36: =O34*$D$38/1000*$D$40+O34*$D$35/1000*(1-$D$40) -> 3.390839 | ... AA36: =AA34*$D$38/1000*$D$40+AA34*$D$35/1000*(1-$D$40) -> 3.2121983
C37: 电价优惠比例（%） | D37: =分布式光伏电站IRR汇总!$B$27 -> 1 | F37: 所得税现值和（Mn RMB） | G37: =SUM(H38:AA38) -> 9.7244234
C38: 工商业电价（元/kWh)：折扣 | D38: =D37*D36 -> 0.69 | F38: 所得税现值（Mn RMB） | H38: =(H36-H29-H31)*G24 -> 0.52263232 | I38: =(I36-I29-I31)*G24 -> 0.51869528 | J38: =(J36-J29-J31)*G24 -> 0.51477594 | K38: =(K36-K29-K31)*G24 -> 0.51087425 | L38: =(L36-L29-L31)*G24 -> 0.50699011 | M38: =(M36-M29-M31)*G24 -> 0.50312345 | N38: =(N36-N29-N31)*G24 -> 0.49927419 | O38: =(O36-O29-O31)*G24 -> 0.49544225 | P38: =(P36-P29-P31)*G24 -> 0.49162756 | Q38: =(Q36-Q29-Q31)*G24 -> 0.48783003 | R38: =(R36-R29-R31)*G24 -> 0.48404959 | S38: =(S36-S29-S31)*G24 -> 0.48028617 | T38: =(T36-T29-T31)*G24 -> 0.47653967 | U38: =(U36-U29-U31)*G24 -> 0.47281004 | V38: =(V36-V29-V31)*G24 -> 0.46909719 | W38: =(W36-W29-W31)*G24 -> 0.46540105 | X38: =(X36-X29-X31)*G24 -> 0.46172154 | Y38: =(Y36-Y29-Y31)*G24 -> 0.45805859 | Z38: =(Z36-Z29-Z31)*G24 -> 0.45441213 | AA38: =(AA36-AA29-AA31)*G24 -> 0.45078207
C39: 补贴 | D39: 0 | F39: NPV | G39: =-G27 -> -24.612 | H39: =H36-H38-H31 -> 2.736967 | I39: =I36-I38-I31 -> 2.7251558 | J39: =J36-J38-J31 -> 2.7133978 | K39: =K36-K38-K31 -> 2.7016927 | L39: =L36-L38-L31 -> 2.6900403 | M39: =M36-M38-M31 -> 2.6784404 | N39: =N36-N38-N31 -> 2.6668926 | O39: =O36-O38-O31 -> 2.6553968 | ... AA39: =AA36-AA38-AA31 -> 2.5214162
C40: 自发自用比例 | D40: 0.7 | F40: IRR | G40: =IRR(G39:AA39) -> 0.088019313

Sheet 自发自用比例=100%（结合储能-自投）
B1: 全国 | C1: 工商业——分布式光伏
C2: 年利用小时数 | D2: =D33 -> 1163
C3: 度电成本（元/kWh)-折现率=0% | D3: =G32/G38*1000 -> 0.24067909
C4: 度电成本（元/kWh)-折现率=7% | D4: =G13/G19*1000 -> 0.44834063
C5: 投资回报率 | D5: =G26 -> 0.19794489
C6: NPV-折现率=7%（Mn RMB） | D6: =SUM(G25:AA25) -> 5.3887862
C7: IRR | D7: =G45 -> 0.092661942
F8: LCOE(LevelizedCost of Electricity,平准发电成本)
C9: 基本假设 | F9: 折现率 | G9: 0.07
C10: 总装机规模（MW） | D10: =分布式光伏电站IRR汇总!$B$2 -> 6 | F10: 所得税率 | G10: 0.25
C11: 单位面积光伏板容量（w/㎡) | D11: =分布式光伏电站IRR汇总!$B$3 -> 120 | F11: 光伏项目经济性测算 | H11: 1 | I11: 2 | J11: 3 | K11: 4 | L11: 5 | M11: 6 | N11: 7 | O11: 8 | P11: 9 | Q11: 10 | R11: 11 | S11: 12 | T11: 13 | U11: 14 | V11: 15 | W11: 16 | X11: 17 | Y11: 18 | Z11: 19 | AA11: 20
C12: 单位面积光伏板占地面积（㎡） | D12: =分布式光伏电站IRR汇总!$B$4 -> 3 | G12: 基准年 | H12: 第1年 | I12: 第2年 | J12: 第3年 | K12: 第4年 | L12: 第5年 | M12: 第6年 | N12: 第7年 | O12: 第8年 | P12: 第9年 | Q12: 第10年 | R12: 第11年 | S12: 第12年 | T12: 第13年 | U12: 第14年 | V12: 第15年 | W12: 第16年 | X12: 第17年 | Y12: 第18年 | Z12: 第19年 | AA12: 第20年
C13: 光伏板制造面积（万㎡） | D13: =分布式光伏电站IRR汇总!$B$5 -> 5 | F13: 初始投资成本（Mn RMB） | G13: =D34+D43 -> 27.223669
C14: 光伏实际占地面积（万㎡） | D14: =分布式光伏电站IRR汇总!$B$6 -> 15 | F14: 折旧现值和（Mn RMB） | G14: =SUM(H15:AA15) -> 12.385144
C15: 项目初始投资成本（元/W) | D15: =分布式光伏电站IRR汇总!$B$7 -> 4.102 | F15: 折旧现值（Mn RMB） | H15: =D34*(1-D32)/D28/((1+G9)^H11) -> 1.0925888 | I15: =D34*(1-D32)/D28/((1+G9)^I11) -> 1.021111 | J15: =D34*(1-D32)/D28/((1+G9)^J11) -> 0.95430936 | K15: =D34*(1-D32)/D28/((1+G9)^K11) -> 0.89187791 | L15: =D34*(1-D32)/D28/((1+G9)^L11) -> 0.83353075 | M15: =D34*(1-D32)/D28/((1+G9)^M11) -> 0.7790007 | N15: =D34*(1-D32)/D28/((1+G9)^N11) -> 0.72803804 | O15: =D34*(1-D32)/D28/((1+G9)^O11) -> 0.68040938 | P15: =D34*(1-D32)/D28/((1+G9)^P11) -> 0.63589662 | Q15: =D34*(1-D32)/D28/((1+G9)^Q11) -> 0.59429591 | R15: =D34*(1-D32)/D28/((1+G9)^R11) -> 0.55541674 | S15: =D34*(1-D32)/D28/((1+G9)^S11) -> 0.51908106 | T15: =D34*(1-D32)/D28/((1+G9)^T11) -> 0.48512249 | U15: =D34*(1-D32)/D28/((1+G9)^U11) -> 0.4533855 | V15: =D34*(1-D32)/D28/((1+G9)^V11) -> 0.42372477 | W15: =D34*(1-D32)/D28/((1+G9)^W11) -> 0.39600446 | X15: =D34*(1-D32)/D28/((1+G9)^X11) -> 0.37009762 | Y15: =D34*(1-D32)/D28/((1+G9)^Y11) -> 0.34588563 | Z15: =D34*(1-D32)/D28/((1+G9)^Z11) -> 0.3232576 | AA15: =D34*(1-D32)/D28/((1+G9)^AA11) -> 0.3021099
C16: 组件（元/W) | D16: =分布式光伏电站IRR汇总!$B$8 -> 1.887 | F16: 运行成本现值和（Mn RMB） | G16: =SUM(H17:AA17) -> 2.5425634
C17: 逆变器（元/W) | D17: =分布式光伏电站IRR汇总!$B$9 -> 0.185 | F17: 运行成本现值（Mn RMB） | H17: =D31*D10/((1+G9)^H11) -> 0.22429907 | I17: =D31*D10/((1+G9)^I11) -> 0.20962529 | J17: =D31*D10/((1+G9)^J11) -> 0.19591149 | K17: =D31*D10/((1+G9)^K11) -> 0.18309485 | L17: =D31*D10/((1+G9)^L11) -> 0.17111668 | M17: =D31*D10/((1+G9)^M11) -> 0.15992213 | N17: =D31*D10/((1+G9)^N11) -> 0.14945994 | O17: =D31*D10/((1+G9)^O11) -> 0.13968219 | P17: =D31*D10/((1+G9)^P11) -> 0.1305441 | Q17: =D31*D10/((1+G9)^Q11) -> 0.12200383 | R17: =D31*D10/((1+G9)^R11) -> 0.11402227 | S17: =D31*D10/((1+G9)^S11) -> 0.10656287 | T17: =D31*D10/((1+G9)^T11) -> 0.099591467 | U17: =D31*D10/((1+G9)^U11) -> 0.093076138 | V17: =D31*D10/((1+G9)^V11) -> 0.086987045 | W17: =D31*D10/((1+G9)^W11) -> 0.081296303 | X17: =D31*D10/((1+G9)^X11) -> 0.075977854 | Y17: =D31*D10/((1+G9)^Y11) -> 0.07100734 | Z17: =D31*D10/((1+G9)^Z11) -> 0.066362 | AA17: =D31*D10/((1+G9)^AA11) -> 0.062020561
C18: 支架（元/W) | D18: =分布式光伏电站IRR汇总!$B$10 -> 0.222 | F18: 固定资产残值现值 (Mn RMB) | AA18: =D31*D34/((1+G9)^AA11) -> 0.25440834
C19: 电缆（元/W) | D19: =分布式光伏电站IRR汇总!$B$11 -> 0.444 | F19: 发电电量现值和(MWh) | G19: =SUM(H20:AA20) -> 60720.95
C20: 建安费用（元/W) | D20: =分布式光伏电站IRR汇总!$B$12 -> 0.222 | F20: 发电电量现值(MWh) | H20: =D10*D27*(1-D29)*D33/((1+G9)^H11) -> 5534.6627 | I20: =D10*D27*(1-D29)*(1-D30)^(I11-1)*D33/((1+G9)^I11) -> 5149.3053 | J20: =D10*D27*(1-D29)*(1-D30)^(J11-1)*D33/((1+G9)^J11) -> 4790.7789 | K20: =D10*D27*(1-D29)*(1-D30)^(K11-1)*D33/((1+G9)^K11) -> 4457.2153 | L20: =D10*D27*(1-D29)*(1-D30)^(L11-1)*D33/((1+G9)^L11) -> 4146.8765 | M20: =D10*D27*(1-D29)*(1-D30)^(M11-1)*D33/((1+G9)^M11) -> 3858.1454 | N20: =D10*D27*(1-D29)*(1-D30)^(N11-1)*D33/((1+G9)^N11) -> 3589.5175 | O20: =D10*D27*(1-D29)*(1-D30)^(O11-1)*D33/((1+G9)^O11) -> 3339.5932 | P20: =D10*D27*(1-D29)*(1-D30)^(P11-1)*D33/((1+G9)^P11) -> 3107.0701 | Q20: =D10*D27*(1-D29)*(1-D30)^(Q11-1)*D33/((1+G9)^Q11) -> 2890.7367 | R20: =D10*D27*(1-D29)*(1-D30)^(R11-1)*D33/((1+G9)^R11) -> 2689.4658 | S20: =D10*D27*(1-D29)*(1-D30)^(S11-1)*D33/((1+G9)^S11) -> 2502.2086 | T20: =D10*D27*(1-D29)*(1-D30)^(T11-1)*D33/((1+G9)^T11) -> 2327.9894 | U20: =D10*D27*(1-D29)*(1-D30)^(U11-1)*D33/((1+G9)^U11) -> 2165.9004 | V20: =D10*D27*(1-D29)*(1-D30)^(V11-1)*D33/((1+G9)^V11) -> 2015.0971 | W20: =D10*D27*(1-D29)*(1-D30)^(W11-1)*D33/((1+G9)^W11) -> 1874.7936 | X20: =D10*D27*(1-D29)*(1-D30)^(X11-1)*D33/((1+G9)^X11) -> 1744.2589 | Y20: =D10*D27*(1-D29)*(1-D30)^(Y11-1)*D33/((1+G9)^Y11) -> 1622.8128 | Z20: =D10*D27*(1-D29)*(1-D30)^(Z11-1)*D33/((1+G9)^Z11) -> 1509.8226 | AA20: =D10*D27*(1-D29)*(1-D30)^(AA11-1)*D33/((1+G9)^AA11) -> 1404.6994
C21: 屋顶租赁（元/W) | D21: =分布式光伏电站IRR汇总!$B$13 -> 0.15 | F21: 发电收益现值和（Mn RMB） | G21: =SUM(H22:AA22) -> 41.897455
C22: 电网接入（元/W) | D22: =分布式光伏电站IRR汇总!$B$14 -> 0.037 | F22: 发电收益现值（Mn RMB） | H22: =H20*$D$38/1000*$D$40+H20*$D$35/1000*(1-$D$40) -> 3.8189172 | I22: =I20*$D$38/1000*$D$40+I20*$D$35/1000*(1-$D$40) -> 3.5530207 | J22: =J20*$D$38/1000*$D$40+J20*$D$35/1000*(1-$D$40) -> 3.3056374 | K22: =K20*$D$38/1000*$D$40+K20*$D$35/1000*(1-$D$40) -> 3.0754786 | L22: =L20*$D$38/1000*$D$40+L20*$D$35/1000*(1-$D$40) -> 2.8613448 | M22: =M20*$D$38/1000*$D$40+M20*$D$35/1000*(1-$D$40) -> 2.6621203 | N22: =N20*$D$38/1000*$D$40+N20*$D$35/1000*(1-$D$40) -> 2.4767671 | O22: =O20*$D$38/1000*$D$40+O20*$D$35/1000*(1-$D$40) -> 2.3043193 | ... AA22: =AA20*$D$38/1000*$D$40+AA20*$D$35/1000*(1-$D$40) -> 0.9692426
C23: 房顶加固（元/W) | D23: =分布式光伏电站IRR汇总!$B$15 -> 0.259 | F23: 所得税现值和（Mn RMB） | G23: =SUM(H24:V24) -> 5.858965
C24: 二次设备（元/W) | D24: =分布式光伏电站IRR汇总!$B$16 -> 0.074 | F24: 所得税现值（Mn RMB） | H24: =(H22-H15-H17)*G10 -> 0.62550735 | I24: =(I22-I15-I17)*G10 -> 0.58057109 | J24: =(J22-J15-J17)*G10 -> 0.53885415 | K24: =(K22-K15-K17)*G10 -> 0.50012645 | L24: =(L22-L15-L17)*G10 -> 0.46417434 | M24: =(M22-M15-M17)*G10 -> 0.43079937 | N24: =(N22-N15-N17)*G10 -> 0.39981727 | O24: =(O22-O15-O17)*G10 -> 0.37105693 | P24: =(P22-P15-P17)*G10 -> 0.34435941 | Q24: =(Q22-Q15-Q17)*G10 -> 0.31957715 | R24: =(R22-R15-R17)*G10 -> 0.29657309 | S24: =(S22-S15-S17)*G10 -> 0.27522 | T24: =(T22-T15-T17)*G10 -> 0.25539968 | U24: =(U22-U15-U17)*G10 -> 0.23700241 | V24: =(V22-V15-V17)*G10 -> 0.21992629 | W24: =(W22-W15-W17)*G10 -> 0.2040767 | X24: =(X22-X15-X17)*G10 -> 0.18936579 | Y24: =(Y22-Y15-Y17)*G10 -> 0.17571197 | Z24: =(Z22-Z15-Z17)*G10 -> 0.1630395 | AA24: =(AA22-AA15-AA17)*G10 -> 0.15127803
C25: 一次设备（元/W) | D25: =分布式光伏电站IRR汇总!$B$17 -> 0.222 | F25: NPV | G25: =-G13 -> -27.223669 | H25: =H22-H24-H17 -> 2.9691108 | I25: =I22-I24-I17 -> 2.7628243 | J25: =J22-J24-J17 -> 2.5708718 | K25: =K22-K24-K17 -> 2.3922573 | L25: =L22-L24-L17 -> 2.2260538 | M25: =M22-M24-M17 -> 2.0713988 | N25: =N22-N24-N17 -> 1.9274899 | O25: =O22-O24-O17 -> 1.7935802 | ... AA25: =AA22-AA24-AA17 -> 0.755944
C26: 其它（元/W) | D26: =分布式光伏电站IRR汇总!$B$18 -> 0.4 | F26: 投资回报率 | G26: =SUM(G25:AA25)/G13 -> 0.19794489
C27: 系统运行效率（%） | D27: =分布式光伏电站IRR汇总!$B$19 -> 0.866
C28: 系统寿命（年） | D28: =分布式光伏电站IRR汇总!$B$20 -> 20 | F28: 折现率 | G28: 0
C29: 组件光衰率（%）-首年） | D29: =分布式光伏电站IRR汇总!$B$21 -> 0.02 | F29: 所得税率 | G29: 0.25
C30: 组件光衰率（%）-逐年光衰 | D30: =分布式光伏电站IRR汇总!$B$22 -> 0.0045 | F30: 光伏项目经济性测算 | H30: 1 | I30: 2 | J30: 3 | K30: 4 | L30: 5 | M30: 6 | N30: 7 | O30: 8 | P30: 9 | Q30: 10 | R30: 11 | S30: 12 | T30: 13 | U30: 14 | V30: 15 | W30: 16 | X30: 17 | Y30: 18 | Z30: 19 | AA30: 20
C31: 运维成本（元/W) | D31: =分布式光伏电站IRR汇总!$B$23 -> 0.04 | G31: 基准年 | H31: 第1年 | I31: 第2年 | J31: 第3年 | K31: 第4年 | L31: 第5年 | M31: 第6年 | N31: 第7年 | O31: 第8年 | P31: 第9年 | Q31: 第10年 | R31: 第11年 | S31: 第12年 | T31: 第13年 | U31: 第14年 | V31: 第15年 | W31: 第16年 | X31: 第17年 | Y31: 第18年 | Z31: 第19年 | AA31: 第20年
C32: 系统残值率（元/W) | D32: =分布式光伏电站IRR汇总!$B$24 -> 0.05 | F32: 初始投资成本（Mn RMB） | G32: =D34+D43 -> 27.223669
C33: 光伏利用小时数（h） | D33: 1163 | F33: 折旧现值和（Mn RMB） | G33: =SUM(H34:AA34) -> 23.3814
C34: 初始投资成本（Mn RMB） | D34: =D10*D15 -> 24.612 | F34: 折旧现值（Mn RMB） | H34: =D34*(1-D32)/D28/((1+G28)^H30) -> 1.16907 | I34: =D34*(1-D32)/D28/((1+G28)^I30) -> 1.16907 | J34: =D34*(1-D32)/D28/((1+G28)^J30) -> 1.16907 | K34: =D34*(1-D32)/D28/((1+G28)^K30) -> 1.16907 | L34: =D34*(1-D32)/D28/((1+G28)^L30) -> 1.16907 | M34: =D34*(1-D32)/D28/((1+G28)^M30) -> 1.16907 | N34: =D34*(1-D32)/D28/((1+G28)^N30) -> 1.16907 | O34: =D34*(1-D32)/D28/((1+G28)^O30) -> 1.16907 | P34: =D34*(1-D32)/D28/((1+G28)^P30) -> 1.16907 | Q34: =D34*(1-D32)/D28/((1+G28)^Q30) -> 1.16907 | R34: =D34*(1-D32)/D28/((1+G28)^R30) -> 1.16907 | S34: =D34*(1-D32)/D28/((1+G28)^S30) -> 1.16907 | T34: =D34*(1-D32)/D28/((1+G28)^T30) -> 1.16907 | U34: =D34*(1-D32)/D28/((1+G28)^U30) -> 1.16907 | V34: =D34*(1-D32)/D28/((1+G28)^V30) -> 1.16907 | W34: =D34*(1-D32)/D28/((1+G28)^W30) -> 1.16907 | X34: =D34*(1-D32)/D28/((1+G28)^X30) -> 1.16907 | Y34: =D34*(1-D32)/D28/((1+G28)^Y30) -> 1.16907 | Z34: =D34*(1-D32)/D28/((1+G28)^Z30) -> 1.16907 | AA34: =D34*(1-D32)/D28/((1+G28)^AA30) -> 1.16907
C35: 标杆上网电价（元/kWh) | D35: 0.3598 | F35: 运行成本现值和（Mn RMB） | G35: =SUM(H36:AA36) -> 4.8
C36: 工商业电价（元/kWh) | D36: 0.69 | F36: 运行成本现值（Mn RMB） | H36: =D31*D10/((1+G28)^H30) -> 0.24 | I36: =D31*D10/((1+G28)^I30) -> 0.24 | J36: =D31*D10/((1+G28)^J30) -> 0.24 | K36: =D31*D10/((1+G28)^K30) -> 0.24 | L36: =D31*D10/((1+G28)^L30) -> 0.24 | M36: =D31*D10/((1+G28)^M30) -> 0.24 | N36: =D31*D10/((1+G28)^N30) -> 0.24 | O36: =D31*D10/((1+G28)^O30) -> 0.24 | P36: =D31*D10/((1+G28)^P30) -> 0.24 | Q36: =D31*D10/((1+G28)^Q30) -> 0.24 | R36: =D31*D10/((1+G28)^R30) -> 0.24 | S36: =D31*D10/((1+G28)^S30) -> 0.24 | T36: =D31*D10/((1+G28)^T30) -> 0.24 | U36: =D31*D10/((1+G28)^U30) -> 0.24 | V36: =D31*D10/((1+G28)^V30) -> 0.24 | W36: =D31*D10/((1+G28)^W30) -> 0.24 | X36: =D31*D10/((1+G28)^X30) -> 0.24 | Y36: =D31*D10/((1+G28)^Y30) -> 0.24 | Z36: =D31*D10/((1+G28)^Z30) -> 0.24 | AA36: =D31*D10/((1+G28)^AA30) -> 0.24
C37: 电价优惠比例（%） | D37: =分布式光伏电站IRR汇总!$B$27 -> 1 | F37: 固定资产残值现值 (Mn RMB) | AA37: =D31*D34/((1+G28)^AA30) -> 0.98448
C38: 工商业电价（元/kWh)：折扣 | D38: =D37*D36 -> 0.69 | F38: 发电电量现值和(MWh) | G38: =SUM(H39:AA39) -> 113111.9
C39: 补贴 | D39: 0 | F39: 发电电量现值(MWh) | H39: =($D$10*$D$27*(1-$D$29)*$D$33/((1+G28)^H30))*70%+($D$10*$D$27*(1-$D$29)*$D$33/((1+G28)^H30))*30%*85% -> 5655.595 | I39: =($D$10*$D$27*(1-$D$29)*$D$33/((1+H28)^I30))*70%+($D$10*$D$27*(1-$D$29)*$D$33/((1+H28)^I30))*30%*85% -> 5655.595 | J39: =($D$10*$D$27*(1-$D$29)*$D$33/((1+I28)^J30))*70%+($D$10*$D$27*(1-$D$29)*$D$33/((1+I28)^J30))*30%*85% -> 5655.595 | K39: =($D$10*$D$27*(1-$D$29)*$D$33/((1+J28)^K30))*70%+($D$10*$D$27*(1-$D$29)*$D$33/((1+J28)^K30))*30%*85% -> 5655.595 | L39: =($D$10*$D$27*(1-$D$29)*$D$33/((1+K28)^L30))*70%+($D$10*$D$27*(1-$D$29)*$D$33/((1+K28)^L30))*30%*85% -> 5655.595 | M39: =($D$10*$D$27*(1-$D$29)*$D$33/((1+L28)^M30))*70%+($D$10*$D$27*(1-$D$29)*$D$33/((1+L28)^M30))*30%*85% -> 5655.595 | N39: =($D$10*$D$27*(1-$D$29)*$D$33/((1+M28)^N30))*70%+($D$10*$D$27*(1-$D$29)*$D$33/((1+M28)^N30))*30%*85% -> 5655.595 | O39: =($D$10*$D$27*(1-$D$29)*$D$33/((1+N28)^O30))*70%+($D$10*$D$27*(1-$D$29)*$D$33/((1+N28)^O30))*30%*85% -> 5655.595 | ... AA39: =($D$10*$D$27*(1-$D$29)*$D$33/((1+Z28)^AA30))*70%+($D$10*$D$27*(1-$D$29)*$D$33/((1+Z28)^AA30))*30%*85% -> 5655.595
C40: 自发自用比例 | D40: 1 | F40: 发电收益现值和（Mn RMB） | G40: =SUM(H41:AA41) -> 78.047211
...

Sheet 自发自用比例=100%（结合储能-合同能源管理收益）
B1: 全国 | C1: 工商业——分布式光伏
C2: 年利用小时数 | D2: =D33 -> 1163
C3: 度电成本（元/kWh)-折现率=0% | D3: =G32/G38*1000 -> 0.21682188
C4: 度电成本（元/kWh)-折现率=7% | D4: =G13/G19*1000 -> 0.40532963
C5: 投资回报率 | D5: =G26 -> -0.094040169
C6: NPV-折现率=7%（Mn RMB） | D6: =SUM(G25:AA25) -> -2.3145166
C7: IRR | D7: =G45 -> #VALUE!
F8: LCOE(LevelizedCost of Electricity,平准发电成本)
C9: 基本假设 | F9: 折现率 | G9: 0.07
C10: 总装机规模（MW） | D10: =分布式光伏电站IRR汇总!$B$2 -> 6 | F10: 所得税率 | G10: 0.25
C11: 单位面积光伏板容量（w/㎡) | D11: =分布式光伏电站IRR汇总!$B$3 -> 120 | F11: 光伏项目经济性测算 | H11: 1 | I11: 2 | J11: 3 | K11: 4 | L11: 5 | M11: 6 | N11: 7 | O11: 8 | P11: 9 | Q11: 10 | R11: 11 | S11: 12 | T11: 13 | U11: 14 | V11: 15 | W11: 16 | X11: 17 | Y11: 18 | Z11: 19 | AA11: 20
C12: 单位面积光伏板占地面积（㎡） | D12: =分布式光伏电站IRR汇总!$B$4 -> 3 | G12: 基准年 | H12: 第1年 | I12: 第2年 | J12: 第3年 | K12: 第4年 | L12: 第5年 | M12: 第6年 | N12: 第7年 | O12: 第8年 | P12: 第9年 | Q12: 第10年 | R12: 第11年 | S12: 第12年 | T12: 第13年 | U12: 第14年 | V12: 第15年 | W12: 第16年 | X12: 第17年 | Y12: 第18年 | Z12: 第19年 | AA12: 第20年
C13: 光伏板制造面积（万㎡） | D13: =分布式光伏电站IRR汇总!$B$5 -> 5 | F13: 初始投资成本（Mn RMB） | G13: =D34 -> 24.612
C14: 光伏实际占地面积（万㎡） | D14: =分布式光伏电站IRR汇总!$B$6 -> 15 | F14: 折旧现值和（Mn RMB） | G14: =SUM(H15:AA15) -> 12.385144
C15: 项目初始投资成本（元/W) | D15: =分布式光伏电站IRR汇总!$B$7 -> 4.102 | F15: 折旧现值（Mn RMB） | H15: =D34*(1-D32)/D28/((1+G9)^H11) -> 1.0925888 | I15: =D34*(1-D32)/D28/((1+G9)^I11) -> 1.021111 | J15: =D34*(1-D32)/D28/((1+G9)^J11) -> 0.95430936 | K15: =D34*(1-D32)/D28/((1+G9)^K11) -> 0.89187791 | L15: =D34*(1-D32)/D28/((1+G9)^L11) -> 0.83353075 | M15: =D34*(1-D32)/D28/((1+G9)^M11) -> 0.7790007 | N15: =D34*(1-D32)/D28/((1+G9)^N11) -> 0.72803804 | O15: =D34*(1-D32)/D28/((1+G9)^O11) -> 0.68040938 | P15: =D34*(1-D32)/D28/((1+G9)^P11) -> 0.63589662 | Q15: =D34*(1-D32)/D28/((1+G9)^Q11) -> 0.59429591 | R15: =D34*(1-D32)/D28/((1+G9)^R11) -> 0.55541674 | S15: =D34*(1-D32)/D28/((1+G9)^S11) -> 0.51908106 | T15: =D34*(1-D32)/D28/((1+G9)^T11) -> 0.48512249 | U15: =D34*(1-D32)/D28/((1+G9)^U11) -> 0.4533855 | V15: =D34*(1-D32)/D28/((1+G9)^V11) -> 0.42372477 | W15: =D34*(1-D32)/D28/((1+G9)^W11) -> 0.39600446 | X15: =D34*(1-D32)/D28/((1+G9)^X11) -> 0.37009762 | Y15: =D34*(1-D32)/D28/((1+G9)^Y11) -> 0.34588563 | Z15: =D34*(1-D32)/D28/((1+G9)^Z11) -> 0.3232576 | AA15: =D34*(1-D32)/D28/((1+G9)^AA11) -> 0.3021099
C16: 组件（元/W) | D16: =分布式光伏电站IRR汇总!$B$8 -> 1.887 | F16: 运行成本现值和（Mn RMB） | G16: =SUM(H17:AA17) -> 2.5425634
C17: 逆变器（元/W) | D17: =分布式光伏电站IRR汇总!$B$9 -> 0.185 | F17: 运行成本现值（Mn RMB） | H17: =D31*D10/((1+G9)^H11) -> 0.22429907 | I17: =D31*D10/((1+G9)^I11) -> 0.20962529 | J17: =D31*D10/((1+G9)^J11) -> 0.19591149 | K17: =D31*D10/((1+G9)^K11) -> 0.18309485 | L17: =D31*D10/((1+G9)^L11) -> 0.17111668 | M17: =D31*D10/((1+G9)^M11) -> 0.15992213 | N17: =D31*D10/((1+G9)^N11) -> 0.14945994 | O17: =D31*D10/((1+G9)^O11) -> 0.13968219 | P17: =D31*D10/((1+G9)^P11) -> 0.1305441 | Q17: =D31*D10/((1+G9)^Q11) -> 0.12200383 | R17: =D31*D10/((1+G9)^R11) -> 0.11402227 | S17: =D31*D10/((1+G9)^S11) -> 0.10656287 | T17: =D31*D10/((1+G9)^T11) -> 0.099591467 | U17: =D31*D10/((1+G9)^U11) -> 0.093076138 | V17: =D31*D10/((1+G9)^V11) -> 0.086987045 | W17: =D31*D10/((1+G9)^W11) -> 0.081296303 | X17: =D31*D10/((1+G9)^X11) -> 0.075977854 | Y17: =D31*D10/((1+G9)^Y11) -> 0.07100734 | Z17: =D31*D10/((1+G9)^Z11) -> 0.066362 | AA17: =D31*D10/((1+G9)^AA11) -> 0.062020561
C18: 支架（元/W) | D18: =分布式光伏电站IRR汇总!$B$10 -> 0.222 | F18: 固定资产残值现值 (Mn RMB) | AA18: =D31*D34/((1+G9)^AA11) -> 0.25440834
C19: 电缆（元/W) | D19: =分布式光伏电站IRR汇总!$B$11 -> 0.444 | F19: 发电电量现值和(MWh) | G19: =SUM(H20:AA20) -> 60720.95
C20: 建安费用（元/W) | D20: =分布式光伏电站IRR汇总!$B$12 -> 0.222 | F20: 发电电量现值(MWh) | H20: =D10*D27*(1-D29)*D33/((1+G9)^H11) -> 5534.6627 | I20: =D10*D27*(1-D29)*(1-D30)^(I11-1)*D33/((1+G9)^I11) -> 5149.3053 | J20: =D10*D27*(1-D29)*(1-D30)^(J11-1)*D33/((1+G9)^J11) -> 4790.7789 | K20: =D10*D27*(1-D29)*(1-D30)^(K11-1)*D33/((1+G9)^K11) -> 4457.2153 | L20: =D10*D27*(1-D29)*(1-D30)^(L11-1)*D33/((1+G9)^L11) -> 4146.8765 | M20: =D10*D27*(1-D29)*(1-D30)^(M11-1)*D33/((1+G9)^M11) -> 3858.1454 | N20: =D10*D27*(1-D29)*(1-D30)^(N11-1)*D33/((1+G9)^N11) -> 3589.5175 | O20: =D10*D27*(1-D29)*(1-D30)^(O11-1)*D33/((1+G9)^O11) -> 3339.5932 | P20: =D10*D27*(1-D29)*(1-D30)^(P11-1)*D33/((1+G9)^P11) -> 3107.0701 | Q20: =D10*D27*(1-D29)*(1-D30)^(Q11-1)*D33/((1+G9)^Q11) -> 2890.7367 | R20: =D10*D27*(1-D29)*(1-D30)^(R11-1)*D33/((1+G9)^R11) -> 2689.4658 | S20: =D10*D27*(1-D29)*(1-D30)^(S11-1)*D33/((1+G9)^S11) -> 2502.2086 | T20: =D10*D27*(1-D29)*(1-D30)^(T11-1)*D33/((1+G9)^T11) -> 2327.9894 | U20: =D10*D27*(1-D29)*(1-D30)^(U11-1)*D33/((1+G9)^U11) -> 2165.9004 | V20: =D10*D27*(1-D29)*(1-D30)^(V11-1)*D33/((1+G9)^V11) -> 2015.0971 | W20: =D10*D27*(1-D29)*(1-D30)^(W11-1)*D33/((1+G9)^W11) -> 1874.7936 | X20: =D10*D27*(1-D29)*(1-D30)^(X11-1)*D33/((1+G9)^X11) -> 1744.2589 | Y20: =D10*D27*(1-D29)*(1-D30)^(Y11-1)*D33/((1+G9)^Y11) -> 1622.8128 | Z20: =D10*D27*(1-D29)*(1-D30)^(Z11-1)*D33/((1+G9)^Z11) -> 1509.8226 | AA20: =D10*D27*(1-D29)*(1-D30)^(AA11-1)*D33/((1+G9)^AA11) -> 1404.6994
C21: 屋顶租赁（元/W) | D21: =分布式光伏电站IRR汇总!$B$13 -> 0.15 | F21: 发电收益现值和（Mn RMB） | G21: =SUM(H22:AA22) -> 35.882438
C22: 电网接入（元/W) | D22: =分布式光伏电站IRR汇总!$B$14 -> 0.037 | F22: 发电收益现值（Mn RMB） | H22: =H20*$D$38/1000*$D$40+H20*$D$35/1000*(1-$D$40) -> 3.2706535 | I22: =I20*$D$38/1000*$D$40+I20*$D$35/1000*(1-$D$40) -> 3.0429305 | J22: =J20*$D$38/1000*$D$40+J20*$D$35/1000*(1-$D$40) -> 2.8310629 | K22: =K20*$D$38/1000*$D$40+K20*$D$35/1000*(1-$D$40) -> 2.6339468 | L22: =L20*$D$38/1000*$D$40+L20*$D$35/1000*(1-$D$40) -> 2.4505552 | M22: =M20*$D$38/1000*$D$40+M20*$D$35/1000*(1-$D$40) -> 2.2799324 | N22: =N20*$D$38/1000*$D$40+N20*$D$35/1000*(1-$D$40) -> 2.1211895 | O22: =O20*$D$38/1000*$D$40+O20*$D$35/1000*(1-$D$40) -> 1.9734992 | ... AA22: =AA20*$D$38/1000*$D$40+AA20*$D$35/1000*(1-$D$40) -> 0.83009307
C23: 房顶加固（元/W) | D23: =分布式光伏电站IRR汇总!$B$15 -> 0.259 | F23: 所得税现值和（Mn RMB） | G23: =SUM(H24:V24) -> 4.5572036
C24: 二次设备（元/W) | D24: =分布式光伏电站IRR汇总!$B$16 -> 0.074 | F24: 所得税现值（Mn RMB） | H24: =(H22-H15-H17)*G10 -> 0.48844142 | I24: =(I22-I15-I17)*G10 -> 0.45304854 | J24: =(J22-J15-J17)*G10 -> 0.42021051 | K24: =(K22-K15-K17)*G10 -> 0.38974352 | L24: =(L22-L15-L17)*G10 -> 0.36147694 | M24: =(M22-M15-M17)*G10 -> 0.3352524 | N24: =(N22-N15-N17)*G10 -> 0.31092287 | O24: =(O22-O15-O17)*G10 -> 0.2883519 | P24: =(P22-P15-P17)*G10 -> 0.26741282 | Q24: =(Q22-Q15-Q17)*G10 -> 0.24798805 | R24: =(R22-R15-R17)*G10 -> 0.22996847 | S24: =(S22-S15-S17)*G10 -> 0.2132528 | T24: =(T22-T15-T17)*G10 -> 0.19774702 | U24: =(U22-U15-U17)*G10 -> 0.18336389 | V24: =(V22-V15-V17)*G10 -> 0.17002241 | W24: =(W22-W15-W17)*G10 -> 0.15764744 | X24: =(X22-X15-X17)*G10 -> 0.14616922 | Y24: =(Y22-Y15-Y17)*G10 -> 0.13552301 | Z24: =(Z22-Z15-Z17)*G10 -> 0.12564874 | AA24: =(AA22-AA15-AA17)*G10 -> 0.11649065
C25: 一次设备（元/W) | D25: =分布式光伏电站IRR汇总!$B$17 -> 0.222 | F25: NPV | G25: =-G13 -> -24.612 | H25: =H22-H24-H17-'自发自用比例=100%（结合储能-自投）'!$D$44 -> 2.2677276 | I25: =I22-I24-I17-'自发自用比例=100%（结合储能-自投）'!$D$44 -> 2.0900712 | J25: =J22-J24-J17-'自发自用比例=100%（结合储能-自投）'!$D$44 -> 1.9247554 | K25: =K22-K24-K17-'自发自用比例=100%（结合储能-自投）'!$D$44 -> 1.770923 | L25: =L22-L24-L17-'自发自用比例=100%（结合储能-自投）'!$D$44 -> 1.6277761 | M25: =M22-M24-M17-'自发自用比例=100%（结合储能-自投）'!$D$44 -> 1.4945725 | N25: =N22-N24-N17-'自发自用比例=100%（结合储能-自投）'!$D$44 -> 1.3706212 | O25: =O22-O24-O17-'自发自用比例=100%（结合储能-自投）'!$D$44 -> 1.2552797 | ... AA25: =AA22-AA24-AA17-'自发自用比例=100%（结合储能-自投）'!$D$44 -> 0.36139642
C26: 其它（元/W) | D26: =分布式光伏电站IRR汇总!$B$18 -> 0.4 | F26: 投资回报率 | G26: =SUM(G25:AA25)/G13 -> -0.094040169
C27: 系统运行效率（%） | D27: =分布式光伏电站IRR汇总!$B$19 -> 0.866
C28: 系统寿命（年） | D28: =分布式光伏电站IRR汇总!$B$20 -> 20 | F28: 折现率 | G28: 0
C29: 组件光衰率（%）-首年） | D29: =分布式光伏电站IRR汇总!$B$21 -> 0.02 | F29: 所得税率 | G29: 0.25
C30: 组件光衰率（%）-逐年光衰 | D30: =分布式光伏电站IRR汇总!$B$22 -> 0.0045 | F30: 光伏项目经济性测算 | H30: 1 | I30: 2 | J30: 3 | K30: 4 | L30: 5 | M30: 6 | N30: 7 | O30: 8 | P30: 9 | Q30: 10 | R30: 11 | S30: 12 | T30: 13 | U30: 14 | V30: 15 | W30: 16 | X30: 17 | Y30: 18 | Z30: 19 | AA30: 20
C31: 运维成本（元/W) | D31: =分布式光伏电站IRR汇总!$B$23 -> 0.04 | G31: 基准年 | H31: 第1年 | I31: 第2年 | J31: 第3年 | K31: 第4年 | L31: 第5年 | M31: 第6年 | N31: 第7年 | O31: 第8年 | P31: 第9年 | Q31: 第10年 | R31: 第11年 | S31: 第12年 | T31: 第13年 | U31: 第14年 | V31: 第15年 | W31: 第16年 | X31: 第17年 | Y31: 第18年 | Z31: 第19年 | AA31: 第20年
C32: 系统残值率（元/W) | D32: =分布式光伏电站IRR汇总!$B$24 -> 0.05 | F32: 初始投资成本（Mn RMB） | G32: =D34 -> 24.612
C33: 光伏利用小时数（h） | D33: 1163 | F33: 折旧现值和（Mn RMB） | G33: =SUM(H34:AA34) -> 23.3814
C34: 初始投资成本（Mn RMB） | D34: =D10*D15 -> 24.612 | F34: 折旧现值（Mn RMB） | H34: =D34*(1-D32)/D28/((1+G28)^H30) -> 1.16907 | I34: =D34*(1-D32)/D28/((1+G28)^I30) -> 1.16907 | J34: =D34*(1-D32)/D28/((1+G28)^J30) -> 1.16907 | K34: =D34*(1-D32)/D28/((1+G28)^K30) -> 1.16907 | L34: =D34*(1-D32)/D28/((1+G28)^L30) -> 1.16907 | M34: =D34*(1-D32)/D28/((1+G28)^M30) -> 1.16907 | N34: =D34*(1-D32)/D28/((1+G28)^N30) -> 1.16907 | O34: =D34*(1-D32)/D28/((1+G28)^O30) -> 1.16907 | P34: =D34*(1-D32)/D28/((1+G28)^P30) -> 1.16907 | Q34: =D34*(1-D32)/D28/((1+G28)^Q30) -> 1.16907 | R34: =D34*(1-D32)/D28/((1+G28)^R30) -> 1.16907 | S34: =D34*(1-D32)/D28/((1+G28)^S30) -> 1.16907 | T34: =D34*(1-D32)/D28/((1+G28)^T30) -> 1.16907 | U34: =D34*(1-D32)/D28/((1+G28)^U30) -> 1.16907 | V34: =D34*(1-D32)/D28/((1+G28)^V30) -> 1.16907 | W34: =D34*(1-D32)/D28/((1+G28)^W30) -> 1.16907 | X34: =D34*(1-D32)/D28/((1+G28)^X30) -> 1.16907 | Y34: =D34*(1-D32)/D28/((1+G28)^Y30) -> 1.16907 | Z34: =D34*(1-D32)/D28/((1+G28)^Z30) -> 1.16907 | AA34: =D34*(1-D32)/D28/((1+G28)^AA30) -> 1.16907
C35: 标杆上网电价（元/kWh) | D35: 0.3598 | F35: 运行成本现值和（Mn RMB） | G35: =SUM(H36:AA36) -> 4.8
C36: 工商业电价（元/kWh) | D36: 0.69 | F36: 运行成本现值（Mn RMB） | H36: =D31*D10/((1+G28)^H30) -> 0.24 | I36: =D31*D10/((1+G28)^I30) -> 0.24 | J36: =D31*D10/((1+G28)^J30) -> 0.24 | K36: =D31*D10/((1+G28)^K30) -> 0.24 | L36: =D31*D10/((1+G28)^L30) -> 0.24 | M36: =D31*D10/((1+G28)^M30) -> 0.24 | N36: =D31*D10/((1+G28)^N30) -> 0.24 | O36: =D31*D10/((1+G28)^O30) -> 0.24 | P36: =D31*D10/((1+G28)^P30) -> 0.24 | Q36: =D31*D10/((1+G28)^Q30) -> 0.24 | R36: =D31*D10/((1+G28)^R30) -> 0.24 | S36: =D31*D10/((1+G28)^S30) -> 0.24 | T36: =D31*D10/((1+G28)^T30) -> 0.24 | U36: =D31*D10/((1+G28)^U30) -> 0.24 | V36: =D31*D10/((1+G28)^V30) -> 0.24 | W36: =D31*D10/((1+G28)^W30) -> 0.24 | X36: =D31*D10/((1+G28)^X30) -> 0.24 | Y36: =D31*D10/((1+G28)^Y30) -> 0.24 | Z36: =D31*D10/((1+G28)^Z30) -> 0.24 | AA36: =D31*D10/((1+G28)^AA30) -> 0.24
C37: 电价优惠比例（%） | D37: =分布式光伏电站IRR汇总!$B$27 -> 1 | F37: 固定资产残值现值 (Mn RMB) | AA37: =D31*D34/((1+G28)^AA30) -> 0.98448
C38: 工商业电价（元/kWh)：折扣 | D38: =D37*D36 -> 0.69 | F38: 发电电量现值和(MWh) | G38: =SUM(H39:AA39) -> 113512.53
C39: 补贴 | D39: 0 | F39: 发电电量现值(MWh) | H39: =D10*D27*(1-D29)*D33/((1+G28)^H30) -> 5922.089 | I39: =D10*D27*(1-D29)*(1-D30)^(I30-1)*D33/((1+G28)^I30) -> 5895.4396 | J39: =D10*D27*(1-D29)*(1-D30)^(J30-1)*D33/((1+G28)^J30) -> 5868.9102 | K39: =D10*D27*(1-D29)*(1-D30)^(K30-1)*D33/((1+G28)^K30) -> 5842.5001 | L39: =D10*D27*(1-D29)*(1-D30)^(L30-1)*D33/((1+G28)^L30) -> 5816.2088 | M39: =D10*D27*(1-D29)*(1-D30)^(M30-1)*D33/((1+G28)^M30) -> 5790.0359 | N39: =D10*D27*(1-D29)*(1-D30)^(N30-1)*D33/((1+G28)^N30) -> 5763.9807 | O39: =D10*D27*(1-D29)*(1-D30)^(O30-1)*D33/((1+G28)^O30) -> 5738.0428 | P39: =D10*D27*(1-D29)*(1-D30)^(P30-1)*D33/((1+G28)^P30) -> 5712.2216 | Q39: =D10*D27*(1-D29)*(1-D30)^(Q30-1)*D33/((1+G28)^Q30) -> 5686.5166 | R39: =D10*D27*(1-D29)*(1-D30)^(R30-1)*D33/((1+G28)^R30) -> 5660.9273 | S39: =D10*D27*(1-D29)*(1-D30)^(S30-1)*D33/((1+G28)^S30) -> 5635.4531 | T39: =D10*D27*(1-D29)*(1-D30)^(T30-1)*D33/((1+G28)^T30) -> 5610.0936 | U39: =D10*D27*(1-D29)*(1-D30)^(U30-1)*D33/((1+G28)^U30) -> 5584.8482 | V39: =D10*D27*(1-D29)*(1-D30)^(V30-1)*D33/((1+G28)^V30) -> 5559.7163 | W39: =D10*D27*(1-D29)*(1-D30)^(W30-1)*D33/((1+G28)^W30) -> 5534.6976 | X39: =D10*D27*(1-D29)*(1-D30)^(X30-1)*D33/((1+G28)^X30) -> 5509.7915 | Y39: =D10*D27*(1-D29)*(1-D30)^(Y30-1)*D33/((1+G28)^Y30) -> 5484.9974 | Z39: =D10*D27*(1-D29)*(1-D30)^(Z30-1)*D33/((1+G28)^Z30) -> 5460.3149 | AA39: =D10*D27*(1-D29)*(1-D30)^(AA30-1)*D33/((1+G28)^AA30) -> 5435.7435
C40: 自发自用比例 | D40: 0.7 | F40: 发电收益现值和（Mn RMB） | G40: =SUM(H41:AA41) -> 67.079094
...

Sheet 储能经济模型
B1: 自变量 | C1: *表后用户侧储能主要通过现货形式进行峰谷套利，收益部分由峰负荷时的用户分摊
B2: 支出项 | C2: 关键假定：
B3: 收入项 | C3: 1）电池充放电循环次数~6525次
C4: 2）PCS成本：0.3元/W；电池充放电循环次数~6525次；容量型储能电站运维费用：0.1%；PCS效率：98%；线损：98%；系统使用天数：350天；充放循环次数（1次为1充1放）(次/天）：2次
A5: 更新处：标绿色的单元格 | C5: 3）两充两放（一谷一峰，一平一峰）
A6: Base | D6: 计算结果
A7: 储能电站:两充两放（一谷一峰，一平一峰） | D7: LCOS（元/kWh) | E7: =E38 -> 0.44080801
A8: 基本数据 | D8: 投资回报率 | E8: =E43 -> -0.11238786
A9: PCS(KW） | B9: 1200 | D9: NPV(折现率=7%） | E9: =SUM(E42:N42) -> -0.84852837
A10: PCS成本（元/kW) | B10: 300 | D10: IRR | E10: =Q43 -> 0.04260586
A11: ESS(KWh) | B11: 4800 | D11: 折现率 | E11: 0.07 | P11: 折现率 | Q11: 0
A12: ESS成本（元/kWh) | B12: 1400 | D12: 所得税率 | E12: 0.25 | P12: 所得税率 | Q12: 0.25
A13: PCS效率 | B13: 0.98 | D13: 增值税率 | E13: 0 | F13: 暂不考虑 | P13: 增值税率 | Q13: 0 | R13: 暂不考虑
A14: 线损 | B14: 0.98 | D14: 储能系统经济效益估算表（元） | P14: 储能系统经济效益估算表（元）
A15: 峰价（元/KWh) | B15: 0.991 | D15: 储能平准化成本LCOS（Levelized Cost of Storage） | F15: 1 | G15: 2 | H15: 3 | I15: 4 | J15: 5 | K15: 6 | L15: 7 | M15: 8 | N15: 9 | P15: 储能平准化成本LCOS（Levelized Cost of Storage） | R15: 1 | S15: 2 | T15: 3 | U15: 4 | V15: 5 | W15: 6 | X15: 7 | Y15: 8 | Z15: 9
A16: 平价（元/KWh) | B16: 0.597 | E16: 基准年 | F16: 第1年 | G16: 第2年 | H16: 第3年 | I16: 第4年 | J16: 第5年 | K16: 第6年 | L16: 第7年 | M16: 第8年 | N16: 第9年 | Q16: 基准年 | R16: 第1年 | S16: 第2年 | T16: 第3年 | U16: 第4年 | V16: 第5年 | W16: 第6年 | X16: 第7年 | Y16: 第8年 | Z16: 第9年
A17: 谷价（元/KWh) | B17: 0.289 | D17: 初始投资成本（Mn RMB） | E17: =B37/1000000 -> 7.55 | P17: 初始投资成本（Mn RMB） | Q17: =B37/1000000 -> 7.55
A18: 系统年使用天数 (天) | B18: 350 | C18: =B15-B17 -> 0.702 | D18: 折旧现值和（Mn RMB） | E18: =SUM(F19:N19) -> 4.9334808 | P18: 折旧现值和（Mn RMB） | Q18: =SUM(R19:Z19) -> 6.8150029
A19: DOD% | B19: 0.95 | D19: 折旧现值（Mn RMB） | F19: =($B$33+$B$34+$B$24)*(1-$B$27)/$B$32/1000000/(1+$E$11)^F15 -> 0.70768463 | G19: =($B$33+$B$34+$B$24)*(1-$B$27)/$B$32/1000000/(1+$E$11)^G15 -> 0.6613875 | H19: =($B$33+$B$34+$B$24)*(1-$B$27)/$B$32/1000000/(1+$E$11)^H15 -> 0.61811916 | I19: =($B$33+$B$34+$B$24)*(1-$B$27)/$B$32/1000000/(1+$E$11)^I15 -> 0.57768146 | J19: =($B$33+$B$34+$B$24)*(1-$B$27)/$B$32/1000000/(1+$E$11)^J15 -> 0.53988921 | K19: =($B$33+$B$34+$B$24)*(1-$B$27)/$B$32/1000000/(1+$E$11)^K15 -> 0.50456936 | L19: =($B$33+$B$34+$B$24)*(1-$B$27)/$B$32/1000000/(1+$E$11)^L15 -> 0.47156015 | M19: =($B$33+$B$34+$B$24)*(1-$B$27)/$B$32/1000000/(1+$E$11)^M15 -> 0.44071042 | N19: =($B$33+$B$34+$B$24)*(1-$B$27)/$B$32/1000000/(1+$E$11)^N15 -> 0.4118789 | P19: 折旧现值（Mn RMB） | R19: =($B$33+$B$34+$B$24)*(1-$B$27)/$B$32/1000000/(1+$Q$11)^R15 -> 0.75722255 | S19: =($B$33+$B$34+$B$24)*(1-$B$27)/$B$32/1000000/(1+$Q$11)^S15 -> 0.75722255 | T19: =($B$33+$B$34+$B$24)*(1-$B$27)/$B$32/1000000/(1+$Q$11)^T15 -> 0.75722255 | U19: =($B$33+$B$34+$B$24)*(1-$B$27)/$B$32/1000000/(1+$Q$11)^U15 -> 0.75722255 | V19: =($B$33+$B$34+$B$24)*(1-$B$27)/$B$32/1000000/(1+$Q$11)^V15 -> 0.75722255 | W19: =($B$33+$B$34+$B$24)*(1-$B$27)/$B$32/1000000/(1+$Q$11)^W15 -> 0.75722255 | X19: =($B$33+$B$34+$B$24)*(1-$B$27)/$B$32/1000000/(1+$Q$11)^X15 -> 0.75722255 | Y19: =($B$33+$B$34+$B$24)*(1-$B$27)/$B$32/1000000/(1+$Q$11)^Y15 -> 0.75722255 | Z19: =($B$33+$B$34+$B$24)*(1-$B$27)/$B$32/1000000/(1+$Q$11)^Z15 -> 0.75722255
A20: 单次循环衰减率 | B20: 4.68e-05 | D20: 运行成本现值和（Mn RMB） | E20: =SUM(F21:N21) -> 0.049190003 | P20: 运行成本现值和（Mn RMB） | Q20: =SUM(R21:Z21) -> 0.06795
A21: 系统报废终止标准 | B21: 0.7 | D21: 运行成本现值（Mn RMB） | F21: =($B$26*$E$17)/((1+$E$11)^F15) -> 0.0070560748 | G21: =($B$26*$E$17)/((1+$E$11)^G15) -> 0.0065944624 | H21: =($B$26*$E$17)/((1+$E$11)^H15) -> 0.006163049 | I21: =($B$26*$E$17)/((1+$E$11)^I15) -> 0.0057598589 | J21: =($B$26*$E$17)/((1+$E$11)^J15) -> 0.0053830457 | K21: =($B$26*$E$17)/((1+$E$11)^K15) -> 0.0050308838 | L21: =($B$26*$E$17)/((1+$E$11)^L15) -> 0.0047017606 | M21: =($B$26*$E$17)/((1+$E$11)^M15) -> 0.0043941687 | N21: =($B$26*$E$17)/((1+$E$11)^N15) -> 0.0041066998 | P21: 运行成本现值（Mn RMB） | R21: =($B$26*$Q$17)/((1+$Q$11)^R15) -> 0.00755 | S21: =($B$26*$Q$17)/((1+$Q$11)^S15) -> 0.00755 | T21: =($B$26*$Q$17)/((1+$Q$11)^T15) -> 0.00755 | U21: =($B$26*$Q$17)/((1+$Q$11)^U15) -> 0.00755 | V21: =($B$26*$Q$17)/((1+$Q$11)^V15) -> 0.00755 | W21: =($B$26*$Q$17)/((1+$Q$11)^W15) -> 0.00755 | X21: =($B$26*$Q$17)/((1+$Q$11)^X15) -> 0.00755 | Y21: =($B$26*$Q$17)/((1+$Q$11)^Y15) -> 0.00755 | Z21: =($B$26*$Q$17)/((1+$Q$11)^Z15) -> 0.00755
A22: 土建成本(元/Wh) | B22: 0.015 | D22: 固定资产残值现值 (Mn RMB) | N22: =(B33+B34)*B27/((1+E11)^N15)/1000000 -> 0.19255254 | P22: 固定资产残值现值 (Mn RMB) | Z22: =(B33+B34)*B27/((1+Q11)^Z15)/1000000 -> 0.354
A23: 土建残值率（%） | B23: 0 | D23: 充电电量现值和(KWh) | E23: =SUM(F24:N24) -> 20148870 | P23: 充电电量现值和(KWh) | Q23: =SUM(R24:Z24) -> 27429842
A24: 其它设备投资费用（升压变等） | B24: 350000 | D24: 充电电量现值(KWh) | F24: =$B$11*$B$28*$B$18/$B$29*($B$19*(1-$B$20)^((F15-1)*$B$18*$B$28))/$B$13/$B$14/((1+$E$11)^F15) -> 3235606.7 | G24: =$B$11*$B$28*$B$18/$B$29*($B$19*(1-$B$20)^((G15-1)*$B$18*$B$28))/$B$13/$B$14/((1+$E$11)^G15) -> 2926470.3 | H24: =$B$11*$B$28*$B$18/$B$29*($B$19*(1-$B$20)^((H15-1)*$B$18*$B$28))/$B$13/$B$14/((1+$E$11)^H15) -> 2646869.5 | I24: =$B$11*$B$28*$B$18/$B$29*($B$19*(1-$B$20)^((I15-1)*$B$18*$B$28))/$B$13/$B$14/((1+$E$11)^I15) -> 2393982.3 | J24: =$B$11*$B$28*$B$18/$B$29*($B$19*(1-$B$20)^((J15-1)*$B$18*$B$28))/$B$13/$B$14/((1+$E$11)^J15) -> 2165256.4 | K24: =$B$11*$B$28*$B$18/$B$29*($B$19*(1-$B$20)^((K15-1)*$B$18*$B$28))/$B$13/$B$14/((1+$E$11)^K15) -> 1958383.5 | L24: =$B$11*$B$28*$B$18/$B$29*($B$19*(1-$B$20)^((L15-1)*$B$18*$B$28))/$B$13/$B$14/((1+$E$11)^L15) -> 1771275.6 | M24: =$B$11*$B$28*$B$18/$B$29*($B$19*(1-$B$20)^((M15-1)*$B$18*$B$28))/$B$13/$B$14/((1+$E$11)^M15) -> 1602044.4 | N24: =$B$11*$B$28*$B$18/$B$29*($B$19*(1-$B$20)^((N15-1)*$B$18*$B$28))/$B$13/$B$14/((1+$E$11)^N15) -> 1448981.8 | P24: 充电电量现值(KWh) | R24: =$B$11*$B$28*$B$18/$B$29*($B$19*(1-$B$20)^((R15-1)*$B$18*$B$28))/$B$13/$B$14/((1+$Q$11)^R15) -> 3462099.1 | S24: =$B$11*$B$28*$B$18/$B$29*($B$19*(1-$B$20)^((S15-1)*$B$18*$B$28))/$B$13/$B$14/((1+$Q$11)^S15) -> 3350515.9 | T24: =$B$11*$B$28*$B$18/$B$29*($B$19*(1-$B$20)^((T15-1)*$B$18*$B$28))/$B$13/$B$14/((1+$Q$11)^T15) -> 3242528.9 | U24: =$B$11*$B$28*$B$18/$B$29*($B$19*(1-$B$20)^((U15-1)*$B$18*$B$28))/$B$13/$B$14/((1+$Q$11)^U15) -> 3138022.4 | V24: =$B$11*$B$28*$B$18/$B$29*($B$19*(1-$B$20)^((V15-1)*$B$18*$B$28))/$B$13/$B$14/((1+$Q$11)^V15) -> 3036884.1 | W24: =$B$11*$B$28*$B$18/$B$29*($B$19*(1-$B$20)^((W15-1)*$B$18*$B$28))/$B$13/$B$14/((1+$Q$11)^W15) -> 2939005.5 | X24: =$B$11*$B$28*$B$18/$B$29*($B$19*(1-$B$20)^((X15-1)*$B$18*$B$28))/$B$13/$B$14/((1+$Q$11)^X15) -> 2844281.5 | Y24: =$B$11*$B$28*$B$18/$B$29*($B$19*(1-$B$20)^((Y15-1)*$B$18*$B$28))/$B$13/$B$14/((1+$Q$11)^Y15) -> 2752610.5 | Z24: =$B$11*$B$28*$B$18/$B$29*($B$19*(1-$B$20)^((Z15-1)*$B$18*$B$28))/$B$13/$B$14/((1+$Q$11)^Z15) -> 2663894
A25: 其它成本：入网检测费、项目管理费等（元/Wh） | B25: 0.01 | D25: 放电电量现值和(KWh) | E25: =SUM(F26:N26) -> 17127638 | P25: 放电电量现值和(KWh) | Q25: =SUM(R26:Z26) -> 23316860
A26: 容量型储能电站运维费用 | B26: 0.001 | D26: 放电电量现值(KWh) | F26: =$B$11*$B$28*$B$18*$B$29*($B$19*(1-$B$20)^((F15-1)*$B$18*$B$28))*$B$13*$B$14/((1+$E$11)^F15) -> 2750442 | G26: =$B$11*$B$28*$B$18*$B$29*($B$19*(1-$B$20)^((G15-1)*$B$18*$B$28))*$B$13*$B$14/((1+$E$11)^G15) -> 2487659.2 | H26: =$B$11*$B$28*$B$18*$B$29*($B$19*(1-$B$20)^((H15-1)*$B$18*$B$28))*$B$13*$B$14/((1+$E$11)^H15) -> 2249983.3 | I26: =$B$11*$B$28*$B$18*$B$29*($B$19*(1-$B$20)^((I15-1)*$B$18*$B$28))*$B$13*$B$14/((1+$E$11)^I15) -> 2035015.4 | J26: =$B$11*$B$28*$B$18*$B$29*($B$19*(1-$B$20)^((J15-1)*$B$18*$B$28))*$B$13*$B$14/((1+$E$11)^J15) -> 1840585.9 | K26: =$B$11*$B$28*$B$18*$B$29*($B$19*(1-$B$20)^((K15-1)*$B$18*$B$28))*$B$13*$B$14/((1+$E$11)^K15) -> 1664732.7 | L26: =$B$11*$B$28*$B$18*$B$29*($B$19*(1-$B$20)^((L15-1)*$B$18*$B$28))*$B$13*$B$14/((1+$E$11)^L15) -> 1505680.8 | M26: =$B$11*$B$28*$B$18*$B$29*($B$19*(1-$B$20)^((M15-1)*$B$18*$B$28))*$B$13*$B$14/((1+$E$11)^M15) -> 1361825 | N26: =$B$11*$B$28*$B$18*$B$29*($B$19*(1-$B$20)^((N15-1)*$B$18*$B$28))*$B$13*$B$14/((1+$E$11)^N15) -> 1231713.5 | P26: 放电电量现值(KWh) | R26: =$B$11*$B$28*$B$18*$B$29*($B$19*(1-$B$20)^((R15-1)*$B$18*$B$28))*$B$13*$B$14/((1+$Q$11)^R15) -> 2942972.9 | S26: =$B$11*$B$28*$B$18*$B$29*($B$19*(1-$B$20)^((S15-1)*$B$18*$B$28))*$B$13*$B$14/((1+$Q$11)^S15) -> 2848121.1 | T26: =$B$11*$B$28*$B$18*$B$29*($B$19*(1-$B$20)^((T15-1)*$B$18*$B$28))*$B$13*$B$14/((1+$Q$11)^T15) -> 2756326.3 | U26: =$B$11*$B$28*$B$18*$B$29*($B$19*(1-$B$20)^((U15-1)*$B$18*$B$28))*$B$13*$B$14/((1+$Q$11)^U15) -> 2667490 | V26: =$B$11*$B$28*$B$18*$B$29*($B$19*(1-$B$20)^((V15-1)*$B$18*$B$28))*$B$13*$B$14/((1+$Q$11)^V15) -> 2581517 | W26: =$B$11*$B$28*$B$18*$B$29*($B$19*(1-$B$20)^((W15-1)*$B$18*$B$28))*$B$13*$B$14/((1+$Q$11)^W15) -> 2498314.8 | X26: =$B$11*$B$28*$B$18*$B$29*($B$19*(1-$B$20)^((X15-1)*$B$18*$B$28))*$B$13*$B$14/((1+$Q$11)^X15) -> 2417794.3 | Y26: =$B$11*$B$28*$B$18*$B$29*($B$19*(1-$B$20)^((Y15-1)*$B$18*$B$28))*$B$13*$B$14/((1+$Q$11)^Y15) -> 2339868.9 | Z26: =$B$11*$B$28*$B$18*$B$29*($B$19*(1-$B$20)^((Z15-1)*$B$18*$B$28))*$B$13*$B$14/((1+$Q$11)^Z15) -> 2264455.1
A27: 储能系统残值 | B27: 0.05 | D27: 充电成本现值和（Mn RMB） | E27: =SUM(F28:N28) -> 8.9259495 | P27: 充电成本现值和（Mn RMB） | Q27: =SUM(R28:Z28) -> 12.15142
A28: 充放循环次数（1次为1充1放）(次/天） | B28: 2 | D28: 充电成本现值（Mn RMB） | F28: =($B$17+$B$16)*F24/2/1000000 -> 1.4333738 | G28: =($B$17+$B$16)*G24/2/1000000 -> 1.2964263 | H28: =($B$17+$B$16)*H24/2/1000000 -> 1.1725632 | I28: =($B$17+$B$16)*I24/2/1000000 -> 1.0605341 | J28: =($B$17+$B$16)*J24/2/1000000 -> 0.95920858 | K28: =($B$17+$B$16)*K24/2/1000000 -> 0.86756387 | L28: =($B$17+$B$16)*L24/2/1000000 -> 0.78467508 | M28: =($B$17+$B$16)*M24/2/1000000 -> 0.70970565 | N28: =($B$17+$B$16)*N24/2/1000000 -> 0.64189895 | P28: 充电成本现值（Mn RMB） | R28: =($B$17+$B$16)*R24/2/1000000 -> 1.5337099 | S28: =($B$17+$B$16)*S24/2/1000000 -> 1.4842785 | T28: =($B$17+$B$16)*T24/2/1000000 -> 1.4364403 | U28: =($B$17+$B$16)*U24/2/1000000 -> 1.3901439 | V28: =($B$17+$B$16)*V24/2/1000000 -> 1.3453397 | W28: =($B$17+$B$16)*W24/2/1000000 -> 1.3019794 | X28: =($B$17+$B$16)*X24/2/1000000 -> 1.2600167 | Y28: =($B$17+$B$16)*Y24/2/1000000 -> 1.2194064 | Z28: =($B$17+$B$16)*Z24/2/1000000 -> 1.180105
A29: 充放电效率RTE（%） | B29: 0.96 | D29: 放电收益现值和（Mn RMB） | E29: =SUM(F30:N30) -> 16.973489 | P29: 放电收益现值和（Mn RMB） | Q29: =SUM(R30:Z30) -> 23.107009
A30: 用户分成比例（%） | B30: 0.1 | D30: 放电收益现值（Mn RMB） | F30: =F26*$B$15/1000000 -> 2.725688 | G30: =G26*$B$15/1000000 -> 2.4652703 | H30: =H26*$B$15/1000000 -> 2.2297334 | I30: =I26*$B$15/1000000 -> 2.0167002 | J30: =J26*$B$15/1000000 -> 1.8240207 | K30: =K26*$B$15/1000000 -> 1.6497501 | L30: =L26*$B$15/1000000 -> 1.4921296 | M30: =M26*$B$15/1000000 -> 1.3495686 | N30: =N26*$B$15/1000000 -> 1.2206281 | P30: 放电收益现值（Mn RMB） | R30: =R26*$B$15/1000000 -> 2.9164862 | S30: =S26*$B$15/1000000 -> 2.822488 | T30: =T26*$B$15/1000000 -> 2.7315193 | U30: =U26*$B$15/1000000 -> 2.6434826 | V30: =V26*$B$15/1000000 -> 2.5582833 | W30: =W26*$B$15/1000000 -> 2.47583 | X30: =X26*$B$15/1000000 -> 2.3960341 | Y30: =Y26*$B$15/1000000 -> 2.3188101 | Z30: =Z26*$B$15/1000000 -> 2.244075
A31: 充放循环总次数（次数） | B31: =LOG(B21/B19,(1-B20)) -> 6525.0962 | D31: 所得税现值和（Mn RMB） | E31: =SUM(F32:N32) -> 0.76621718 | P31: 所得税现值和（Mn RMB） | Q31: =SUM(R32:Z32) -> 1.0181589
A32: 系统寿命（年） | B32: =B31/B28/B18 -> 9.321566 | D32: 所得税现值（Mn RMB） | F32: =(F30-F28-F21-F19)*$E$12 -> 0.14439339 | G32: =(G30-G28-G21-G19)*$E$12 -> 0.1252155 | H32: =(H30-H28-H21-H19)*$E$12 -> 0.10822202 | I32: =(I30-I28-I21-I19)*$E$12 -> 0.093181197 | J32: =(J30-J28-J21-J19)*$E$12 -> 0.079884955 | K32: =(K30-K28-K21-K19)*$E$12 -> 0.068146489 | L32: =(L30-L28-L21-L19)*$E$12 -> 0.057798163 | M32: =(M30-M28-M21-M19)*$E$12 -> 0.048689586 | N32: =(N30-N28-N21-N19)*$E$12 -> 0.040685888 | P32: 所得税现值（Mn RMB） | R32: =(R30-R28-R21-R19)*$Q$12 -> 0.15450093 | S32: =(S30-S28-S21-S19)*$Q$12 -> 0.14335923 | T32: =(T30-T28-T21-T19)*$Q$12 -> 0.13257662 | U32: =(U30-U28-U21-U19)*$Q$12 -> 0.12214154 | V32: =(V30-V28-V21-V19)*$Q$12 -> 0.11204278 | W32: =(W30-W28-W21-W19)*$Q$12 -> 0.1022695 | X32: =(X30-X28-X21-X19)*$Q$12 -> 0.092811219 | Y32: =(Y30-Y28-Y21-Y19)*$Q$12 -> 0.083657775 | Z32: =(Z30-Z28-Z21-Z19)*$Q$12 -> 0.074799345
A33: PCS总成本（元） | B33: =B10*B9 -> 360000 | D33: 增值税现值和（Mn RMB） | E33: =SUM(F34:N34) -> 0 | P33: 增值税现值和（Mn RMB） | Q33: =SUM(R34:Z34) -> 0
A34: ESS总成本（元） | B34: =B11*B12 -> 6720000 | D34: 增值税现值（Mn RMB） | F34: =(F30-F28)*$E$13 -> 0 | G34: =(G30-G28)*$E$13 -> 0 | H34: =(H30-H28)*$E$13 -> 0 | I34: =(I30-I28)*$E$13 -> 0 | J34: =(J30-J28)*$E$13 -> 0 | K34: =(K30-K28)*$E$13 -> 0 | L34: =(L30-L28)*$E$13 -> 0 | M34: =(M30-M28)*$E$13 -> 0 | N34: =(N30-N28)*$E$13 -> 0 | P34: 增值税现值（Mn RMB） | R34: =(R30-R28)*$Q$13 -> 0 | S34: =(S30-S28)*$Q$13 -> 0 | T34: =(T30-T28)*$Q$13 -> 0 | U34: =(U30-U28)*$Q$13 -> 0 | V34: =(V30-V28)*$Q$13 -> 0 | W34: =(W30-W28)*$Q$13 -> 0 | X34: =(X30-X28)*$Q$13 -> 0 | Y34: =(Y30-Y28)*$Q$13 -> 0 | Z34: =(Z30-Z28)*$Q$13 -> 0
