Workbook

Sheet 理论市场规模（供参考）
C2: 2021+ | D2: 2016 | E2: 2017 | F2: 2018 | G2: 2019 | H2: 2020 | I2: 2021 | J2: 2022F | K2: 2023F | L2: 2024F | M2: 2025F
B3: 理论市场空间Total(GW) | C3: =C26+C52+C78+C105 -> 167.87413 | D3: =D26+D52+D78+D105 -> 0 | E3: =E26+E52+E78+E105 -> 0 | F3: =F26+F52+F78+F105 -> 0 | G3: =G26+G52+G78+G105 -> 0 | H3: =H26+H52+H78+H105 -> 0 | I3: =I26+I52+I78+I105 -> 167.87413 | J3: =J26+J52+J78+J105 -> 172.73927 | ... M3: =M26+M52+M78+M105 -> 195.13804
B4: 储能总功率（GW）累计 | D4: =E4-E5 -> 0.39348035 | E4: =F4-F5 -> 0.46458035 | F4: =G4-G5 -> 0.75788035 | G4: =H4-H5 -> 1.0357804 | H4: =I4-I5 -> 1.3638804 | I4: =11.4/(1+58.8%)^4 -> 1.7926804 | J4: =I4*(1+58.8%) -> 2.8467764 | K4: =J4*(1+58.8%) -> 4.5206809 | L4: =K4*(1+58.8%) -> 7.1788413 | M4: 11.4
B5: 储能总功率（GW）新增 | D5: 0.0543 | E5: 0.0711 | F5: 0.2933 | G5: 0.2779 | H5: 0.3281 | I5: 0.4288 | J5: =J4-I4 -> 1.054096 | K5: =K4-J4 -> 1.6739045 | L5: =L4-K4 -> 2.6581604 | M5: =M4-L4 -> 4.2211587
B6: EPC成本（元/Wh) | D6: 2.2 | E6: 2.2 | F6: 2.2 | G6: 2.2 | H6: 2.2 | I6: 2.2 | J6: =(POWER($M$112/$I$112,1/4))*I6 -> 2.0603303 | K6: =(POWER($M$112/$I$112,1/4))*J6 -> 1.9295276 | L6: =(POWER($M$112/$I$112,1/4))*K6 -> 1.8070292 | M6: =I6/(1+30%) -> 1.6923077
B7: 储能系统配置（h） | C7: 4 | D7: 4 | E7: 4 | F7: 4 | G7: 4 | H7: 4 | I7: 4 | J7: 4 | K7: 4 | L7: 4 | M7: 4
B8: 市场投资金额（Mn RMB） | D8: =D6*D5*D7*1000 -> 477.84 | E8: =E6*E5*E7*1000 -> 625.68 | F8: =F6*F5*F7*1000 -> 2581.04 | G8: =G6*G5*G7*1000 -> 2445.52 | H8: =H6*H5*H7*1000 -> 2887.28 | I8: =I6*I5*I7*1000 -> 3773.44 | J8: =J6*J5*J7*1000 -> 8687.144 | K8: =K6*K5*K7*1000 -> 12919.38 | ... M8: =M6*M5*M7*1000 -> 28573.997
B9: 市场投资金额（B n RMB） | D9: =D8/1000 -> 0.47784 | E9: =E8/1000 -> 0.62568 | F9: =F8/1000 -> 2.58104 | G9: =G8/1000 -> 2.44552 | H9: =H8/1000 -> 2.88728 | I9: =I8/1000 -> 3.77344 | J9: =J8/1000 -> 8.687144 | K9: =K8/1000 -> 12.91938 | ... M9: =M8/1000 -> 28.573997
B10: 储能累计渗透率 | D10: =D4/$C$3 -> 0.0023439011 | E10: =E4/$C$3 -> 0.0027674327 | F10: =F4/$C$3 -> 0.004514575 | G10: =G4/$C$3 -> 0.006169982 | H10: =H4/$C$3 -> 0.0081244225 | I10: =I4/I3 -> 0.010678717 | J10: =J4/J3 -> 0.016480193 | K10: =K4/K3 -> 0.02529857 | L10: =L4/L3 -> 0.038589672 | M10: =M4/M3 -> 0.058420184
B11: 储能增长率 | M11: =POWER(M4/I4,1/4)-1 -> 0.588
C16: 2021+ | D16: 2016 | E16: 2017 | F16: 2018 | G16: 2019 | H16: 2020 | I16: 2021 | J16: 2022F | K16: 2023F | L16: 2024F | M16: 2025F
B17: 工业用户2021年用电量（亿kWh） | C17: 44550 | I17: 44550 | J17: =(POWER($M$17/$I$17,1/4))*I17 -> 44407.341 | K17: =(POWER($M$17/$I$17,1/4))*J17 -> 44265.138 | L17: =(POWER($M$17/$I$17,1/4))*K17 -> 44123.391 | M17: =32549.1367341099+11432.9613196877 -> 43982.098
B18: 工厂年工作天数（日） | C18: 300 | I18: 300 | J18: 300 | K18: 300 | L18: 300 | M18: 300
B19: 工厂日工作小时数（h） | C19: 24 | I19: 24 | J19: 24 | K19: 24 | L19: 24 | M19: 24
B20: 工业用户2021年总运行负荷（亿kw） | C20: =C17/C18/C19 -> 6.1875 | I20: =I17/I18/I19 -> 6.1875 | J20: =J17/J18/J19 -> 6.1676862 | K20: =K17/K18/K19 -> 6.1479359 | L20: =L17/L18/L19 -> 6.1282488 | M20: =M17/M18/M19 -> 6.1086247
B21: 工业用户总负荷运行比例（%） | C21: 0.7 | I21: 0.7 | J21: 0.7 | K21: 0.7 | L21: 0.7 | M21: 0.7
B22: 工业用户2021年总负荷（亿kw） | C22: =C20/C21 -> 8.8392857 | I22: =I20/I21 -> 8.8392857 | J22: =J20/J21 -> 8.8109803 | K22: =K20/K21 -> 8.7827655 | L22: =L20/L21 -> 8.7546411 | M22: =M20/M21 -> 8.7266068
B23: 变压器总余量（亿kw） | C23: =C22-C20 -> 2.6517857 | I23: =I22-I20 -> 2.6517857 | J23: =J22-J20 -> 2.6432941 | K23: =K22-K20 -> 2.6348297 | L23: =L22-L20 -> 2.6263923 | M23: =M22-M20 -> 2.617982
B24: 储能功率占比（%） | C24: 0.5 | I24: 0.5 | J24: 0.5 | K24: 0.5 | L24: 0.5 | M24: 0.5
B25: 储能总功率（亿kw） | C25: =C24*C23 -> 1.3258929 | I25: =I24*I23 -> 1.3258929 | J25: =J24*J23 -> 1.321647 | K25: =K24*K23 -> 1.3174148 | L25: =L24*L23 -> 1.3131962 | M25: =M24*M23 -> 1.308991
B26: 储能总功率（GW） | C26: =C25*100000000/1000000 -> 132.58929 | I26: =I25*100000000/1000000 -> 132.58929 | J26: =J25*100000000/1000000 -> 132.1647 | K26: =K25*100000000/1000000 -> 131.74148 | L26: =L25*100000000/1000000 -> 131.31962 | M26: =M25*100000000/1000000 -> 130.8991
B27: 储能系统配置（h） | C27: 4 | I27: 4 | J27: 4 | K27: 4 | L27: 4 | M27: 4
B28: 储能实际总容量（GWh） | C28: =C27*C26 -> 530.35714 | I28: =I27*I26 -> 530.35714 | J28: =J27*J26 -> 528.65882 | K28: =K27*K26 -> 526.96593 | L28: =L27*L26 -> 525.27847 | M28: =M27*M26 -> 523.59641
B29: 峰谷价差（元/kWh） | C29: 0.7 | I29: 0.7 | J29: 0.7 | K29: 0.7 | L29: 0.7 | M29: 0.7
B30: 储能充放电效率（%） | C30: 0.85 | I30: 0.85 | J30: 0.85 | K30: 0.85 | L30: 0.85 | M30: 0.85
B31: 储能充放电次数（次/日） | C31: 2 | I31: 2.2 | J31: =(POWER($M$112/$I$112,1/4))*I31 -> 2.0603303 | K31: =(POWER($M$112/$I$112,1/4))*J31 -> 1.9295276 | L31: =(POWER($M$112/$I$112,1/4))*K31 -> 1.8070292 | M31: =I31/(1+30%) -> 1.6923077
B32: 储能理论市场年最大盈利空间（Mn RMB/年） | C32: =C28*C31*C29*C30*C18 -> 189337.5 | I32: =I28*I31*I29*I30*I18 -> 208271.25 | J32: =J28*J31*J29*J30*J18 -> 194424.3 | K32: =K28*K31*K29*K30*K18 -> 181497.97 | L32: =L28*L31*L29*L30*L18 -> 169431.04 | M32: =M28*M31*M29*M30*M18 -> 158166.39
B33: EPC成本（元/Wh) | C33: 2.2
B34: 储能投资理论市场累计最大规模（Mn RMB） | C34: =C28*1000*C33 -> 1166785.7
B35: 投资回收周期（年） | C35: =C34/C32 -> 6.162465
B36: 储能总功率（GW）累计 | I36: =I26/I3*I4 -> 1.4158835 | J36: =J26/J3*J4 -> 2.1780998 | K36: =K26/K3*K4 -> 3.3328712 | L36: =L26/L3*L4 -> 5.0675809 | M36: =M26/M3*M4 -> 7.6471496
B37: 储能总功率（GW）新增 | I37: =I26/I3*I5 -> 0.33867211 | J37: =J26/J3*J5 -> 0.80650044 | K37: =K26/K3*K5 -> 1.2340858 | L37: =L26/L3*L5 -> 1.876409 | M37: =M26/M3*M5 -> 2.8315642
B38: 储能累计渗透率
B39: 储能增长率
C42: 2021+ | I42: 2021 | J42: 2022F | K42: 2023F | L42: 2024F | M42: 2025F
B43: 商建用户2021年用电量（亿kWh） | C43: 5190 | I43: 5190 | J43: =(POWER($M$43/$I$43,1/4))*I43 -> 5703.6056 | K43: =(POWER($M$43/$I$43,1/4))*J43 -> 6268.038 | L43: =(POWER($M$43/$I$43,1/4))*K43 -> 6888.3269 | M43: 7570
B44: 商建年工作天数（日） | C44: 365 | I44: 365 | J44: 365 | K44: 365 | L44: 365 | M44: 365
B45: 商建日工作小时数（h） | C45: 12 | I45: 12 | J45: 12 | K45: 12 | L45: 12 | M45: 12
B46: 商建用户2021年总运行负荷（亿kw） | C46: =C43/C44/C45 -> 1.1849315 | I46: =I43/I44/I45 -> 1.1849315 | J46: =J43/J44/J45 -> 1.3021931 | K46: =K43/K44/K45 -> 1.4310589 | L46: =L43/L44/L45 -> 1.5726774 | M46: =M43/M44/M45 -> 1.7283105
B47: 商建用户总负荷运行比例（%） | C47: 0.7 | I47: 0.7 | J47: 0.7 | K47: 0.7 | L47: 0.7 | M47: 0.7
...

Sheet 全国装机
B2: 电化学储能装机规模 - 累计（GW）
C3: 2016 | D3: 2017 | E3: 2018 | F3: 2019 | G3: 2020 | H3: 2021 | I3: 2022F | J3: 2023F | K3: 2024F | L3: 2025F
B4: 全国 | C4: 0.243 | D4: 0.3898 | E4: 1.1 | F4: 1.7096 | G4: 3.269 | H4: =SUM(H5:H6) -> 6.7748843 | I4: =SUM(I5:I6) -> 10.871361 | J4: =SUM(J5:J6) -> 16.284781 | K4: =SUM(K5:K6) -> 23.044782 | L4: =SUM(L5:L6) -> 30.606158
B5: 表前 | C5: =C4-C6 -> 0.18798457 | D5: =D4-D6 -> 0.29654782 | E5: =E4-E6 -> 0.8896324 | F5: =F4-F6 -> 1.2695659 | G5: =G4-G6 -> 2.576527 | H5: 5.78 | I5: =H5*1.6 -> 9.248 | J5: =I5*1.45 -> 13.4096 | K5: =J5*1.38 -> 18.505248 | L5: 24
B6: 表后 | C6: ='01Bottom-Up'!C7 -> 0.055015432 | D6: ='01Bottom-Up'!D7 -> 0.093252183 | E6: ='01Bottom-Up'!E7 -> 0.2103676 | F6: ='01Bottom-Up'!F7 -> 0.44003412 | G6: ='01Bottom-Up'!G7 -> 0.692473 | H6: ='01Bottom-Up'!H7 -> 0.99488431 | I6: ='01Bottom-Up'!I7 -> 1.6233614 | J6: ='01Bottom-Up'!J7 -> 2.8751813 | ... L6: ='01Bottom-Up'!L7 -> 6.606158
B8: 电化学储能装机规模 - 新增（GW）
C9: 2016 | D9: 2017 | E9: 2018 | F9: 2019 | G9: 2020 | H9: 2021 | I9: 2022F | J9: 2023F | K9: 2024F | L9: 2025F
B10: 全国 | C10: 0.1 | D10: =D4-C4 -> 0.1468 | E10: =E4-D4 -> 0.7102 | F10: =F4-E4 -> 0.6096 | G10: =G4-F4 -> 1.5594 | H10: =H4-G4 -> 3.5058843 | I10: =I4-H4 -> 4.0964771 | J10: =J4-I4 -> 5.4134199 | K10: =K4-J4 -> 6.7600006 | L10: =L4-K4 -> 7.561376
B11: 表前 | C11: =C10-C12 -> 0.0849 | D11: =D10-D12 -> 0.10856325 | E11: =E10-E12 -> 0.59308459 | F11: =F10-F12 -> 0.37993348 | G11: =G10-G12 -> 1.3069611 | H11: =H10-H12 -> 3.203473 | I11: =I10-I12 -> 3.468 | J11: =J10-J12 -> 4.1616 | ... L11: =L10-L12 -> 5.494752
B12: 表后 | C12: ='01 Bottom-Up旧版本'!C8 -> 0.0151 | D12: =D6-C6 -> 0.038236751 | E12: =E6-D6 -> 0.11711541 | F12: =F6-E6 -> 0.22966652 | G12: =G6-F6 -> 0.25243888 | H12: =H6-G6 -> 0.3024113 | I12: =I6-H6 -> 0.6284771 | J12: =J6-I6 -> 1.2518199 | K12: =K6-J6 -> 1.6643526 | L12: =L6-K6 -> 2.066624
B15: 光伏装机规模 - 新增（GW）
C16: 2016 | D16: 2017 | E16: 2018 | F16: 2019 | G16: 2020 | H16: 2021 | I16: 2022F | J16: 2023F | K16: 2024F | L16: 2025F
B17: 全国 | C17: 34.54 | D17: 53.06 | E17: 44.26 | F17: 30.1 | G17: 48.2 | H17: 54.88
B18: 集中式 | C18: =C17-C19 -> 30.31 | D18: =D17-D19 -> 33.62 | E18: =E17-E19 -> 23.3 | F18: =F17-F19 -> 17.91 | G18: =G17-G19 -> 32.68 | H18: 25.6
B19: 分布式 | C19: 4.23 | D19: 19.44 | E19: 20.96 | F19: 12.19 | G19: 15.52 | H19: =H17-H18 -> 29.28 | I19: =H19*(1+25%) -> 36.6 | J19: =I19*(1+22%) -> 44.652 | K19: =J19*(1+18%) -> 52.68936 | L19: =K19*(1+14%) -> 60.06587
B20: Source:国家能源局
G21: 配储比 | H21: 0.1 | I21: 0.1 | J21: 0.1 | K21: 0.1 | L21: 0.1
G22: 渗透率 | H22: 0.1 | I22: 0.16 | J22: 0.28 | K22: 0.32 | L22: 0.35
G23: 储能装机量 | H23: =H21*H22*H19 -> 0.2928 | I23: =I21*I22*I19 -> 0.5856 | J23: =J21*J22*J19 -> 1.250256 | K23: =K21*K22*K19 -> 1.6860595 | L23: =L21*L22*L19 -> 2.1023055

Sheet Bottom-Up分行业_Min
C2: 2016 | D2: 2017 | E2: 2018 | F2: 2019 | G2: 2020 | H2: 2021 | I2: 2022F | J2: 2023F | K2: 2024F | L2: 2025F
B3: 理论市场空间Total(GW) | C3: =C28+C46+C64 -> 140.47788 | D3: =D28+D46+D64 -> 140.47788 | E3: =E28+E46+E64 -> 140.47788 | F3: =F28+F46+F64 -> 140.47788 | G3: =G28+G46+G64 -> 140.47788 | H3: =H28+H46+H64 -> 145.24558 | I3: =I28+I46+I64 -> 150.53527 | J3: =J28+J46+J64 -> 156.4209 | ... L3: =L28+L46+L64 -> 170.34428
A4: Best | B4: 储能总功率（GW）累计-协会公布 | C4: =D4-D5 -> 0.39348035 | D4: =E4-E5 -> 0.46458035 | E4: =F4-F5 -> 0.75788035 | F4: =G4-G5 -> 1.0357804 | G4: =H4-H5 -> 1.3638804 | H4: =11.4/(1+58.8%)^4 -> 1.7926804 | I4: =H4*(1+58.8%) -> 2.8467764 | J4: =I4*(1+58.8%) -> 4.5206809 | K4: =J4*(1+58.8%) -> 7.1788413 | L4: 11.4
A5: Best | B5: 储能总功率（GW）新增-协会公布 | C5: 0.0543 | D5: 0.0711 | E5: 0.2933 | F5: 0.2779 | G5: 0.3281 | H5: 0.4288 | I5: =I4-H4 -> 1.054096 | J5: =J4-I4 -> 1.6739045 | K5: =K4-J4 -> 2.6581604 | L5: =L4-K4 -> 4.2211587
A6: Base | B6: 储能总功率（GW）累计-Bottom-Up | C6: =C32+C50+C68 -> 0.13428571 | D6: =D32+D50+D68 -> 0.20204779 | E6: =E32+E50+E68 -> 0.46000348 | F6: =F32+F50+F68 -> 0.80091989 | G6: =G32+G50+G68 -> 1.0391402 | H6: =H32+H50+H68 -> 1.3655641 | I6: =I32+I50+I68 -> 2.155117 | J6: =J32+J50+J68 -> 3.4223744 | ... L6: =L32+L50+L68 -> 7.6030193
A7: Base | B7: 储能总功率（GW）新增-Bottom-Up | C7: =C30+C48+C66 -> 0.05 | D7: =D30+D48+D66 -> 0.067762074 | E7: =E30+E48+E66 -> 0.25795569 | F7: =F30+F48+F66 -> 0.34091641 | G7: =G30+G48+G66 -> 0.23822028 | H7: =H30+H48+H66 -> 0.30539689 | I7: =I30+I48+I66 -> 0.7631471 | J7: =J30+J48+J66 -> 1.2302049 | ... L7: =L30+L48+L66 -> 2.1909325
B8: EPC成本（元/Wh) | C8: 2.2 | D8: 2.2 | E8: 2.2 | F8: 2.2 | G8: 2.2 | H8: 2.2 | I8: =(POWER($L$8/$H$8,1/4))*H8 -> 2.0603303 | J8: =(POWER($L$8/$H$8,1/4))*I8 -> 1.9295276 | K8: =(POWER($L$8/$H$8,1/4))*J8 -> 1.8070292 | L8: =H8/(1+30%) -> 1.6923077
B9: 储能系统配置（h） | C9: 4 | D9: 4 | E9: 4 | F9: 4 | G9: 4 | H9: 4 | I9: 4 | J9: 4 | K9: 4 | L9: 4
B10: 市场投资金额（Mn RMB） | C10: =C8*C5*C9*1000 -> 477.84 | D10: =D8*D5*D9*1000 -> 625.68 | E10: =E8*E5*E9*1000 -> 2581.04 | F10: =F8*F5*F9*1000 -> 2445.52 | G10: =G8*G5*G9*1000 -> 2887.28 | H10: =H8*H5*H9*1000 -> 3773.44 | I10: =I8*I5*I9*1000 -> 8687.144 | J10: =J8*J5*J9*1000 -> 12919.38 | ... L10: =L8*L5*L9*1000 -> 28573.997
B11: 市场投资金额（Bn RMB）-协会公布 | C11: =C10/1000 -> 0.47784 | D11: =D10/1000 -> 0.62568 | E11: =E10/1000 -> 2.58104 | F11: =F10/1000 -> 2.44552 | G11: =G10/1000 -> 2.88728 | H11: =H10/1000 -> 3.77344 | I11: =I10/1000 -> 8.687144 | J11: =J10/1000 -> 12.91938 | ... L11: =L10/1000 -> 28.573997
B12: 市场投资金额（Bn RMB）-Bottom-Up | C12: =C9*C8*C7 -> 0.44 | D12: =D9*D8*D7 -> 0.59630625 | E12: =E9*E8*E7 -> 2.2700101 | F12: =F9*F8*F7 -> 3.0000644 | G12: =G9*G8*G7 -> 2.0963384 | H12: =H9*H8*H7 -> 2.6874926 | I12: =I9*I8*I7 -> 6.2893403 | J12: =J9*J8*J7 -> 9.4948575 | ... L12: =L9*L8*L7 -> 14.830928
B13: 储能累计渗透率 | C13: =C6/C3 -> 0.00095592072 | D13: =D6/D3 -> 0.001438289 | E13: =E6/E3 -> 0.0032745617 | F13: =F6/F3 -> 0.0057013951 | G13: =G6/G3 -> 0.0073971801 | H13: =H6/H3 -> 0.0094017602 | I13: =I6/I3 -> 0.01431636 | J13: =J6/J3 -> 0.021879266 | ... L13: =L6/L3 -> 0.044633253
B14: 储能增长率 | L14: =POWER(L4/H4,1/4)-1 -> 0.588
A17: Tier1 | B17: 包括有色、钢铁、化工、非金属矿、石油加工、纺织、造纸、食品、制药 | G17: 重工业+轻工业用户整体用电量CAGR
C19: 2016 | D19: 2017 | E19: 2018 | F19: 2019 | G19: 2020 | H19: 2021 | I19: 2022F | J19: 2023F | K19: 2024F | L19: 2025F
B20: 行业年总用电量（亿kWh） | C20: 26543 | D20: 26543 | E20: 26543 | F20: 26543 | G20: 26543 | H20: =G20*(1-0.3%) -> 26463.371 | I20: =H20*(1-0.3%) -> 26383.981 | J20: =I20*(1-0.3%) -> 26304.829 | K20: =J20*(1-0.3%) -> 26225.914 | L20: =K20*(1-0.3%) -> 26147.237
B21: 工厂年工作天数（日） | C21: 300 | D21: 300 | E21: 300 | F21: 300 | G21: 300 | H21: 300 | I21: 300 | J21: 300 | K21: 300 | L21: 300
B22: 工厂日工作小时数（h） | C22: 24 | D22: 24 | E22: 24 | F22: 24 | G22: 24 | H22: 24 | I22: 24 | J22: 24 | K22: 24 | L22: 24
B23: 工业用户2021年总运行负荷（亿kw） | C23: =C20/C21/C22 -> 3.6865278 | D23: =D20/D21/D22 -> 3.6865278 | E23: =E20/E21/E22 -> 3.6865278 | F23: =F20/F21/F22 -> 3.6865278 | G23: =G20/G21/G22 -> 3.6865278 | H23: =H20/H21/H22 -> 3.6754682 | I23: =I20/I21/I22 -> 3.6644418 | J23: =J20/J21/J22 -> 3.6534485 | ... L23: =L20/L21/L22 -> 3.6315607
B24: 工业用户总负荷运行比例（%） | C24: 0.7 | D24: 0.7 | E24: 0.7 | F24: 0.7 | G24: 0.7 | H24: 0.7 | I24: 0.7 | J24: 0.7 | K24: 0.7 | L24: 0.7
B25: 工业用户2021年总负荷（亿kw） | C25: =C23/C24 -> 5.2664683 | D25: =D23/D24 -> 5.2664683 | E25: =E23/E24 -> 5.2664683 | F25: =F23/F24 -> 5.2664683 | G25: =G23/G24 -> 5.2664683 | H25: =H23/H24 -> 5.2506688 | I25: =I23/I24 -> 5.2349168 | J25: =J23/J24 -> 5.2192121 | ... L25: =L23/L24 -> 5.1879438
B26: 变压器总余量（亿kw） | C26: =C25-C23 -> 1.5799405 | D26: =D25-D23 -> 1.5799405 | E26: =E25-E23 -> 1.5799405 | F26: =F25-F23 -> 1.5799405 | G26: =G25-G23 -> 1.5799405 | H26: =H25-H23 -> 1.5752007 | I26: =I25-I23 -> 1.5704751 | J26: =J25-J23 -> 1.5657636 | ... L26: =L25-L23 -> 1.5563831
B27: 储能功率占比（%） | C27: 0.5 | D27: 0.5 | E27: 0.5 | F27: 0.5 | G27: 0.5 | H27: 0.5 | I27: 0.5 | J27: 0.5 | K27: 0.5 | L27: 0.5
B28: 储能理论市场总功率（GW） | C28: =C27*C26*100000000/1000000 -> 78.997024 | D28: =D27*D26*100000000/1000000 -> 78.997024 | E28: =E27*E26*100000000/1000000 -> 78.997024 | F28: =F27*F26*100000000/1000000 -> 78.997024 | G28: =G27*G26*100000000/1000000 -> 78.997024 | H28: =H27*H26*100000000/1000000 -> 78.760033 | I28: =I27*I26*100000000/1000000 -> 78.523753 | J28: =J27*J26*100000000/1000000 -> 78.288181 | ... L28: =L27*L26*100000000/1000000 -> 77.819157
B29: 储能累计渗透率 | C29: 0.001 | D29: 0.0015 | E29: 0.003 | F29: 0.0066 | G29: 0.0089 | H29: 0.012 | I29: 0.02 | J29: 0.033 | K29: 0.053 | L29: 0.078
B30: 储能总功率（GW）新增 | C30: 0.03 | D30: =(D29-C29)*D28 -> 0.039498512 | E30: =(E29-D29)*E28 -> 0.11849554 | F30: =(F29-E29)*F28 -> 0.28438929 | G30: =(G29-F29)*G28 -> 0.18169315 | H30: =(H29-G29)*H28 -> 0.2441561 | I30: =(I29-H29)*I28 -> 0.62819002 | J30: =(J29-I29)*J28 -> 1.0177464 | K30: =(K29-J29)*K28 -> 1.5610663 | L30: =(L29-K29)*L28 -> 1.9454789
B31: 新增总功率市场占比 | C31: =C30/(C30+C48+C66) -> 0.6 | D31: =D30/(D30+D48+D66) -> 0.58289999 | E31: =E30/(E30+E48+E66) -> 0.45936391 | F31: =F30/(F30+F48+F66) -> 0.83419066 | G31: =G30/(G30+G48+G66) -> 0.7627107 | H31: =H30/(H30+H48+H66) -> 0.79947147 | I31: =I30/(I30+I48+I66) -> 0.82315719 | J31: =J30/(J30+J48+J66) -> 0.82729824 | ... L31: =L30/(L30+L48+L66) -> 0.88796843
B32: 储能总功率（GW）累计 | C32: =C29*C28 -> 0.078997024 | D32: =D29*D28 -> 0.11849554 | E32: =E29*E28 -> 0.23699107 | F32: =F29*F28 -> 0.52138036 | G32: =G29*G28 -> 0.70307351 | H32: =H29*H28 -> 0.94512039 | I32: =I29*I28 -> 1.5704751 | J32: =J29*J28 -> 2.58351 | ... L32: =L29*L28 -> 6.0698942
B33: 累计总功率市场占比 | C33: =C32/(C32+C50+C69) -> 0.58827571 | D33: =D32/(D32+D50+D69) -> 0.57945933 | E33: =E32/(E32+E50+E69) -> 0.51276328 | F33: =F32/(F32+F50+F69) -> 0.65035201 | G33: =G32/(G32+G50+G69) -> 0.67669792 | H33: =H32/(H32+H50+H69) -> 0.69312793 | I33: =I32/(I32+I50+I69) -> 0.73202019 | J33: =J32/(J32+J50+J69) -> 0.76006133 | ... L33: =L32/(L32+L50+L69) -> 0.80574419
A35: Tier2 | B35: 包括一般制造业、商业建筑、充电桩 | G35: 商建+充电桩+轻工业用户整体用电量CAGR
C37: 2016 | D37: 2017 | E37: 2018 | F37: 2019 | G37: 2020 | H37: 2021 | I37: 2022F | J37: 2023F | K37: 2024F | L37: 2025F
B38: 行业年总用电量（亿kWh） | C38: 18577 | D38: 18577 | E38: 18577 | F38: 18577 | G38: 18577 | H38: =G38*(1+6.7%) -> 19821.659 | I38: =H38*(1+6.7%) -> 21149.71 | J38: =I38*(1+6.7%) -> 22566.741 | K38: =J38*(1+6.7%) -> 24078.712 | L38: =K38*(1+6.7%) -> 25691.986
B39: 工厂年工作天数（日） | C39: 300 | D39: 300 | E39: 300 | F39: 300 | G39: 300 | H39: 300 | I39: 300 | J39: 300 | K39: 300 | L39: 300
B40: 工厂日工作小时数（h） | C40: 24 | D40: 24 | E40: 24 | F40: 24 | G40: 24 | H40: 24 | I40: 24 | J40: 24 | K40: 24 | L40: 24
B41: 工业用户2021年总运行负荷（亿kw） | C41: =C38/C39/C40 -> 2.5801389 | D41: =D38/D39/D40 -> 2.5801389 | E41: =E38/E39/E40 -> 2.5801389 | F41: =F38/F39/F40 -> 2.5801389 | G41: =G38/G39/G40 -> 2.5801389 | H41: =H38/H39/H40 -> 2.7530082 | I41: =I38/I39/I40 -> 2.9374597 | J41: =J38/J39/J40 -> 3.1342695 | ... L41: =L38/L39/L40 -> 3.5683314
B42: 工业用户总负荷运行比例（%） | C42: 0.7 | D42: 0.7 | E42: 0.7 | F42: 0.7 | G42: 0.7 | H42: 0.7 | I42: 0.7 | J42: 0.7 | K42: 0.7 | L42: 0.7
B43: 工业用户2021年总负荷（亿kw） | C43: =C41/C42 -> 3.6859127 | D43: =D41/D42 -> 3.6859127 | E43: =E41/E42 -> 3.6859127 | F43: =F41/F42 -> 3.6859127 | G43: =G41/G42 -> 3.6859127 | H43: =H41/H42 -> 3.9328688 | I43: =I41/I42 -> 4.1963711 | J43: =J41/J42 -> 4.4775279 | ... L43: =L41/L42 -> 5.0976163
B44: 变压器总余量（亿kw） | C44: =C43-C41 -> 1.1057738 | D44: =D43-D41 -> 1.1057738 | E44: =E43-E41 -> 1.1057738 | F44: =F43-F41 -> 1.1057738 | G44: =G43-G41 -> 1.1057738 | H44: =H43-H41 -> 1.1798607 | I44: =I43-I41 -> 1.2589113 | J44: =J43-J41 -> 1.3432584 | ... L44: =L43-L41 -> 1.5292849
B45: 储能功率占比（%） | C45: 0.5 | D45: 0.5 | E45: 0.5 | F45: 0.5 | G45: 0.5 | H45: 0.5 | I45: 0.5 | J45: 0.5 | K45: 0.5 | L45: 0.5
B46: 储能理论市场总功率（GW） | C46: =C45*C44*100000000/1000000 -> 55.28869 | D46: =D45*D44*100000000/1000000 -> 55.28869 | E46: =E45*E44*100000000/1000000 -> 55.28869 | F46: =F45*F44*100000000/1000000 -> 55.28869 | G46: =G45*G44*100000000/1000000 -> 55.28869 | H46: =H45*H44*100000000/1000000 -> 58.993033 | I46: =I45*I44*100000000/1000000 -> 62.945566 | J46: =J45*J44*100000000/1000000 -> 67.162919 | ... L46: =L45*L44*100000000/1000000 -> 76.464244
...

Sheet 01 Bottom-Up旧版本
B2: 用户侧储能市场规模汇总
C3: 2016 | D3: 2017 | E3: 2018 | F3: 2019 | G3: 2020 | H3: 2021 | I3: 2022F | J3: 2023F | K3: 2024F | L3: 2025F
B4: 理论市场空间Total(GW) | C4: =C29+C65+C83 -> 52.846619 | D4: =D29+D65+D83 -> 53.221014 | E4: =E29+E65+E83 -> 53.768206 | F4: =F29+F65+F83 -> 54.139828 | G4: =G29+G65+G83 -> 55.07821 | H4: =H29+H65+H83 -> 56.618417 | I4: =I29+I65+I83 -> 57.951214 | J4: =J29+J65+J83 -> 59.68345 | ... L4: =L29+L65+L83 -> 64.940909
A5: Best | B5: 储能总功率（GW）累计-协会公布 | C5: =D5-D6 -> 0.39348035 | D5: =E5-E6 -> 0.46458035 | E5: =F5-F6 -> 0.75788035 | F5: =G5-G6 -> 1.0357804 | G5: =H5-H6 -> 1.3638804 | H5: =11.4/(1+58.8%)^4 -> 1.7926804 | I5: =H5*(1+58.8%) -> 2.8467764 | J5: =I5*(1+58.8%) -> 4.5206809 | K5: =J5*(1+58.8%) -> 7.1788413 | L5: 11.4
A6: Best | B6: 储能总功率（GW）新增-协会公布 | C6: 0.0543 | D6: 0.0711 | E6: 0.2933 | F6: 0.2779 | G6: 0.3281 | H6: 0.4288 | I6: =I5-H5 -> 1.054096 | J6: =J5-I5 -> 1.6739045 | K6: =K5-J5 -> 2.6581604 | L6: =L5-K5 -> 4.2211587
A7: Base | B7: 储能总功率（GW）累计-Bottom-Up | C7: =C33+C51+C69+C87+C105 -> 0.055015432 | D7: =D33+D51+D69+D87+D105 -> 0.093252183 | E7: =E33+E51+E69+E87+E105 -> 0.2103676 | F7: =F33+F51+F69+F87+F105 -> 0.44003412 | G7: =G33+G51+G69+G87+G105 -> 0.692473 | H7: =H33+H51+H69+H87+H105 -> 0.99488431 | I7: =I33+I51+I69+I87+I105 -> 1.6233614 | J7: =J33+J51+J69+J87+J105 -> 2.8751813 | ... L7: =L33+L51+L69+L87+L105 -> 6.606158
A8: Base | B8: 储能总功率（GW）新增-Bottom-Up | C8: =C31+C49+C67+C85+C103 -> 0.0151 | D8: =D31+D49+D67+D85+D103 -> 0.037614741 | E8: =E31+E49+E67+E85+E103 -> 0.11485387 | F8: =F31+F49+F67+F85+F103 -> 0.22333041 | G8: =G31+G49+G67+G85+G103 -> 0.23359282 | H8: =H31+H49+H67+H85+H103 -> 0.2691307 | I8: =I31+I49+I67+I85+I103 -> 0.58511656 | J8: =J31+J49+J67+J85+J103 -> 1.175406 | ... L8: =L31+L49+L67+L85+L103 -> 1.8232185
B9: EPC成本（元/Wh) | C9: 2.2 | D9: 2.2 | E9: 2.2 | F9: 2.2 | G9: 2.2 | H9: 2.2 | I9: =$H$9*0.9 -> 1.98 | J9: =$H$9*0.82 -> 1.804 | K9: =$H$9*0.79 -> 1.738 | L9: =H9*(1-30%) -> 1.54
B10: 储能系统配置（h） | C10: 3 | D10: 3 | E10: 3 | F10: 3 | G10: 3 | H10: 3 | I10: 3 | J10: 3 | K10: 3 | L10: 3
B11: 市场投资金额（Mn RMB） | C11: =C9*C6*C10*1000 -> 358.38 | D11: =D9*D6*D10*1000 -> 469.26 | E11: =E9*E6*E10*1000 -> 1935.78 | F11: =F9*F6*F10*1000 -> 1834.14 | G11: =G9*G6*G10*1000 -> 2165.46 | H11: =H9*H6*H10*1000 -> 2830.08 | I11: =I9*I6*I10*1000 -> 6261.3305 | J11: =J9*J6*J10*1000 -> 9059.1713 | ... L11: =L9*L6*L10*1000 -> 19501.753
B12: 市场投资金额（Bn RMB）-协会公布 | C12: =C11/1000 -> 0.35838 | D12: =D11/1000 -> 0.46926 | E12: =E11/1000 -> 1.93578 | F12: =F11/1000 -> 1.83414 | G12: =G11/1000 -> 2.16546 | H12: =H11/1000 -> 2.83008 | I12: =I11/1000 -> 6.2613305 | J12: =J11/1000 -> 9.0591713 | ... L12: =L11/1000 -> 19.501753
A13: Base | B13: 市场投资金额（Bn RMB）-Bottom-Up | C13: =C10*C9*C8 -> 0.09966 | D13: =D10*D9*D8 -> 0.24825729 | E13: =E10*E9*E8 -> 0.75803551 | F13: =F10*F9*F8 -> 1.4739807 | G13: =G10*G9*G8 -> 1.5417126 | H13: =H10*H9*H8 -> 1.7762626 | I13: =I10*I9*I8 -> 3.4755924 | J13: =J10*J9*J8 -> 6.3612975 | ... L13: =L10*L9*L8 -> 8.4232694
B14: 储能累计渗透率 | C14: =C7/C4 -> 0.0010410398 | D14: =D7/D4 -> 0.0017521685 | E14: =E7/E4 -> 0.0039124905 | F14: =F7/F4 -> 0.008127734 | G14: =G7/G4 -> 0.01257254 | H14: =H7/H4 -> 0.017571744 | I14: =I7/I4 -> 0.028012552 | J14: =J7/J4 -> 0.048173845 | ... L14: =L7/L4 -> 0.10172568
B15: 储能增长率 | L15: =POWER(L5/H5,1/4)-1 -> 0.588
G18: 20-25CAGR | H18: ='用电量-各行业汇总'!I9 -> -0.002
B19: A类客户-Tier1：大型高耗能行业（重工业）
C20: 2016 | D20: 2017 | E20: 2018 | F20: 2019 | G20: 2020 | H20: 2021 | I20: 2022F | J20: 2023F | K20: 2024F | L20: 2025F
B21: 行业年总用电量（亿kWh） | C21: =D21*(1-$H18) -> 33140.393 | D21: =E21*(1-$H18) -> 33074.245 | E21: =F21*(1-$H18) -> 33008.228 | F21: =G21*(1-$H18) -> 32942.343 | G21: ='用电量-各行业汇总'!D9 -> 32876.59 | H21: =G21*(1+$H18) -> 32810.837 | I21: =H21*(1+$H18) -> 32745.215 | J21: =I21*(1+$H18) -> 32679.725 | K21: =J21*(1+$H18) -> 32614.365 | L21: ='用电量-各行业汇总'!G9*10 -> 32549.137
B22: 年工作天数（日） | C22: 360 | D22: 360 | E22: 360 | F22: 360 | G22: 360 | H22: 360 | I22: 360 | J22: 360 | K22: 360 | L22: 360
B23: 日工作小时数（h） | C23: 24 | D23: 24 | E23: 24 | F23: 24 | G23: 24 | H23: 24 | I23: 24 | J23: 24 | K23: 24 | L23: 24
B24: 2021年总运行负荷（亿kw） | C24: =C21/C22/C23 -> 3.8356936 | D24: =D21/D22/D23 -> 3.8280376 | E24: =E21/E22/E23 -> 3.8203968 | F24: =F21/F22/F23 -> 3.8127712 | G24: =G21/G22/G23 -> 3.8051609 | H24: =H21/H22/H23 -> 3.7975506 | I24: =I21/I22/I23 -> 3.7899555 | J24: =J21/J22/J23 -> 3.7823756 | ... L24: =L21/L22/L23 -> 3.7672612
B25: 总负荷运行比例（%） | C25: 0.7 | D25: 0.7 | E25: 0.7 | F25: 0.7 | G25: 0.7 | H25: 0.7 | I25: 0.7 | J25: 0.7 | K25: 0.7 | L25: 0.7
B26: 2021年总负荷（亿kw） | C26: =C24/C25 -> 5.4795623 | D26: =D24/D25 -> 5.4686251 | E26: =E24/E25 -> 5.4577097 | F26: =F24/F25 -> 5.446816 | G26: =G24/G25 -> 5.4359441 | H26: =H24/H25 -> 5.4250723 | I26: =I24/I25 -> 5.4142221 | J26: =J24/J25 -> 5.4033937 | ... L26: =L24/L25 -> 5.3818017
B27: 变压器总余量（亿kw） | C27: =C26-C24 -> 1.6438687 | D27: =D26-D24 -> 1.6405875 | E27: =E26-E24 -> 1.6373129 | F27: =F26-F24 -> 1.6340448 | G27: =G26-G24 -> 1.6307832 | H27: =H26-H24 -> 1.6275217 | I27: =I26-I24 -> 1.6242666 | J27: =J26-J24 -> 1.6210181 | ... L27: =L26-L24 -> 1.6145405
B28: 储能功率占比（%） | C28: 0.3 | D28: 0.3 | E28: 0.3 | F28: 0.3 | G28: 0.3 | H28: 0.3 | I28: 0.3 | J28: 0.3 | K28: 0.3 | L28: 0.3
B29: 储能理论市场总功率（GW） | C29: =C28*C27*100000000/1000000 -> 49.316061 | D29: =D28*D27*100000000/1000000 -> 49.217626 | E29: =E28*E27*100000000/1000000 -> 49.119387 | F29: =F28*F27*100000000/1000000 -> 49.021344 | G29: =G28*G27*100000000/1000000 -> 48.923497 | H29: =H28*H27*100000000/1000000 -> 48.82565 | I29: =I28*I27*100000000/1000000 -> 48.727999 | J29: =J28*J27*100000000/1000000 -> 48.630543 | ... L29: =L28*L27*100000000/1000000 -> 48.436215
B30: 储能累计渗透率 | C30: 0.001 | D30: 0.0015 | E30: 0.003 | F30: 0.0059 | G30: 0.0089 | H30: 0.0124 | I30: 0.0193 | J30: 0.033 | K30: 0.0505 | L30: 0.071
B31: 储能总功率（GW）新增 | C31: 0.01 | D31: =(D30-C30)*D29 -> 0.024608813 | E31: =(E30-D30)*E29 -> 0.073679081 | F31: =(F30-E30)*F29 -> 0.1421619 | G31: =(G30-F30)*G29 -> 0.14677049 | H31: =(H30-G30)*H29 -> 0.17088978 | I31: =(I30-H30)*I29 -> 0.33622319 | J31: =(J30-I30)*J29 -> 0.66623844 | K31: =(K30-J30)*K29 -> 0.84933243 | L31: =(L30-K30)*L29 -> 0.99294242
B32: 新增总功率市场占比 | C32: =C31/C$8 -> 0.66225166 | D32: =D31/D$8 -> 0.65423321 | E32: =E31/E$8 -> 0.64150284 | F32: =F31/F$8 -> 0.63655414 | G32: =G31/G$8 -> 0.62831765 | H32: =H31/H$8 -> 0.63496947 | I32: =I31/I$8 -> 0.574626 | J32: =J31/J$8 -> 0.56681557 | ... L32: =L31/L$8 -> 0.54460967
B33: 储能总功率（GW）累计 | C33: =C30*C29 -> 0.049316061 | D33: =D30*D29 -> 0.073826439 | E33: =E30*E29 -> 0.14735816 | F33: =F30*F29 -> 0.28922593 | G33: =G30*G29 -> 0.43541913 | H33: =H30*H29 -> 0.60543806 | I33: =I30*I29 -> 0.94045038 | J33: =J30*J29 -> 1.6048079 | ... L33: =L30*L29 -> 3.4389713
B34: 累计总功率市场占比 | C34: =C33/C$7 -> 0.89640414 | D34: =D33/D$7 -> 0.7916859 | E34: =E33/E$7 -> 0.70047937 | F34: =F33/F$7 -> 0.65728069 | G34: =G33/G$7 -> 0.62878859 | H34: =H33/H$7 -> 0.60855122 | I34: =I33/I$7 -> 0.57932287 | J34: =J33/J$7 -> 0.55815886 | ... L34: =L33/L$7 -> 0.52057055
G36: 20-25CAGR | H36: =POWER(L39/G39,1/5)-1 -> 0.095014176
B37: A类客户-Tier2&3：商建、一般制造业（含除纺织造纸外所有轻工业）
C38: 2016 | D38: 2017 | E38: 2018 | F38: 2019 | G38: 2020 | H38: 2021 | I38: 2022F | J38: 2023F | K38: 2024F | L38: 2025F
B39: 行业年总用电量（亿kWh） | C39: =D39*(1-$H36) -> 6345.6777 | D39: =E39*(1-$H36) -> 7011.9084 | E39: =F39*(1-$H36) -> 7748.0864 | F39: =G39*(1-$H36) -> 8561.5556 | G39: ='用电量-各行业汇总'!D12+'用电量-各行业汇总'!D10-'01 Bottom-Up旧版本'!G75 -> 9460.4306 | H39: =G39*(1+$H36) -> 10359.306 | I39: =H39*(1+$H36) -> 11343.586 | J39: =I39*(1+$H36) -> 12421.388 | K39: =J39*(1+$H36) -> 13601.596 | L39: ='用电量-各行业汇总'!G12*10+'用电量-各行业汇总'!G10*10-'01 Bottom-Up旧版本'!L75 -> 14893.94
B40: 年工作天数（日） | C40: 300 | D40: 300 | E40: 300 | F40: 300 | G40: 300 | H40: 300 | I40: 300 | J40: 300 | K40: 300 | L40: 300
B41: 日工作小时数（h） | C41: 10 | D41: 10 | E41: 10 | F41: 10 | G41: 10 | H41: 10 | I41: 10 | J41: 10 | K41: 10 | L41: 10
B42: 2021年总运行负荷（亿kw） | C42: =C39/C40/C41 -> 2.1152259 | D42: =D39/D40/D41 -> 2.3373028 | E42: =E39/E40/E41 -> 2.5826955 | F42: =F39/F40/F41 -> 2.8538519 | G42: =G39/G40/G41 -> 3.1534769 | H42: =H39/H40/H41 -> 3.4531019 | I42: =I39/I40/I41 -> 3.7811955 | J42: =J39/J40/J41 -> 4.1404627 | ... L42: =L39/L40/L41 -> 4.9646468
B43: 总负荷运行比例（%） | C43: 0.7 | D43: 0.7 | E43: 0.7 | F43: 0.7 | G43: 0.7 | H43: 0.7 | I43: 0.7 | J43: 0.7 | K43: 0.7 | L43: 0.7
B44: 2021年总负荷（亿kw） | C44: =C42/C43 -> 3.0217513 | D44: =D42/D43 -> 3.339004 | E44: =E42/E43 -> 3.689565 | F44: =F42/F43 -> 4.0769312 | G44: =G42/G43 -> 4.5049669 | H44: =H42/H43 -> 4.9330027 | I44: =I42/I43 -> 5.4017078 | J44: =J42/J43 -> 5.9149467 | ... L44: =L42/L43 -> 7.0923526
...

Sheet 用电量-各行业汇总
B1: xxx | C1: M2访谈数据/Assumption
B2: xxx | C2: 引用数据
B3: xxx | C3: 计算所得数据
B5: 行业用电量 | E5: =F7/E7-1 -> 0.10520073
C6: 用电量 | D6: 2020年用电量(亿 kWh） | E6: 2020年用电量(Bn kWh) | F6: 2021年用电量(Bn kWh) | G6: 2025F用电量(Bn kWh) | H6: 2030F用电量(Bn kWh) | I6: CAGR（2020-2025F） | J6: CAGR（2025-2030F） | K6: CAGR（2021-2030F） | L6: 单位建筑面积用电量：单位：kWh/平方米*年；单个数据中心用电量:单位：kWh/个*年；单个充电桩用电量：单位：kWh/个*年 | M6: CR5_2021 | N6: 以有色、钢铁、化工、建材、金属制品五个高耗能CR5的企业耗电量合计占重工业耗电量比重
C7: 全社会用电量 | D7: =[1]建筑!C13 -> 75214.391 | E7: =D7/10 -> 7521.4391 | F7: =[2]交易!D6/10 -> 8312.7 | G7: 10090 | H7: 12240 | I7: =POWER(G7/E7,1/5)-1 -> 0.060518 | J7: =POWER(H7/G7,1/5)-1 -> 0.039388842 | K7: =POWER(H7/F7,1/9)-1 -> 0.043929174 | L7: NA | M7: NA | N7: 以纺织、3C、服装、食品、服装五个高耗能CR5的企业耗电量合计占重工业耗电量比重
C8: Total （工商业、不含交通运输、电力热力生产等） | D8: =SUM(D9:D14) -> 55729.44 | E8: =SUM(E9:E14) -> 5572.944 | F8: =E8*(1+$E$5) -> 6159.2218 | G8: =SUM(G9:G14) -> 6812.5543 | H8: =SUM(H9:H14) -> 8239.5935 | I8: =POWER(G8/E8,1/5)-1 -> 0.040986408 | J8: =POWER(H8/G8,1/5)-1 -> 0.038769434 | K8: =POWER(H8/F8,1/9)-1 -> 0.032861801 | L8: NA | M8: NA
C9: 重工业 | D9: =[1]工业!D3 -> 32876.59 | E9: =D9/10 -> 3287.659 | F9: =E9*(1+$E$5) -> 3633.5231 | G9: =E9*(1+I9)^5 -> 3254.9137 | H9: =G9*(1+J9)^5 -> 3238.6716 | I9: -0.002 | J9: -0.001 | K9: =POWER(H9/F9,1/9)-1 -> -0.01270082 | L9: NA | M9: =911/E9 -> 0.27709686
C10: 轻工业 | D10: =[1]工业!D37 -> 7430.6404 | E10: =D10/10 -> 743.06404 | F10: =E10*(1+$E$5) -> 821.23492 | G10: =E10*(1+I10)^5 -> 1143.2961 | H10: =G10*(1+J10)^5 -> 1529.9881 | I10: 0.09 | J10: 0.06 | K10: =POWER(H10/F10,1/9)-1 -> 0.071579797 | L10: NA | M10: =215/E10 -> 0.28934249
C11: 公共建筑 | D11: =[1]建筑!C9 -> 8562.3805 | E11: =D11/10 -> 856.23805 | F11: =E11*(1+$E$5) -> 946.31491 | G11: =E11*(1+I11)^5 -> 1092.8008 | H11: =G11*(1+J11)^5 -> 1394.7216 | I11: 0.05 | J11: 0.05 | K11: =POWER(H11/F11,1/9)-1 -> 0.044039355 | L11: =[1]建筑!C11 -> 90.666667 | M11: NA
C12: 商业建筑 | D12: =[1]建筑!C6 -> 4700.4293 | E12: =D12/10 -> 470.04293 | F12: =E12*(1+$E$5) -> 519.49179 | G12: =E12*(1+I12)^5 -> 757.00884 | H12: =G12*(1+J12)^5 -> 1013.0486 | I12: 0.1 | J12: 0.06 | K12: =POWER(H12/F12,1/9)-1 -> 0.077030382 | L12: =[1]建筑!C8 -> 136 | M12: 0.15
C13: 数据中心 | D13: 2043 | E13: =D13/10 -> 204.3 | F13: =E13*(1+$E$5) -> 225.79251 | G13: =E13*(1+I13)^5 -> 487.53205 | H13: =G13*(1+J13)^5 -> 785.17525 | I13: 0.19 | J13: 0.1 | K13: =POWER(H13/F13,1/9)-1 -> 0.14852294 | L13: =D13*100000000/74000 -> 2760810.8 | M13: 0.716
C14: 电动出行 (充换电) | D14: 116.4 | E14: =D14/10 -> 11.64 | F14: ='[1]测算_荷（电动出行）'!C20 -> 21.79429 | G14: =F14*(1+I14)^4 -> 77.002785 | H14: =G14*(1+J14)^5 -> 277.98839 | I14: ='[1]测算_荷（电动出行）'!C23 -> 0.37101096 | J14: ='[1]测算_荷（电动出行）'!C24 -> 0.29271874 | K14: ='[1]测算_荷（电动出行）'!C25 -> 0.32694759 | L14: =D14*100000000/1539000 -> 7563.3528 | M14: 0.79
F15: =F10+F9 -> 4454.7581 | G15: =G10+G9 -> 4398.2098 | H15: =POWER(G15/F15,1/4)-1 -> -0.0031886943
B16: 市场规模 | F16: =F13 -> 225.79251 | G16: =G13 -> 487.53205 | H16: =POWER(G16/F16,1/4)-1 -> 0.21219758
C17: 基本假设：用电单价（1元/kWh) | E17: 1
C18: 市场规模 | D18: 2020年市场规模(亿 RMB） | E18: 2020年市场规模(Bn RMB） | F18: 2021年市场规模(Bn RMB） | G18: 2025F市场规模(Bn RMB） | H18: 2030F市场规模(Bn RMB） | I18: CR5_2021
C19: 用电单价（元/kwh） | F19: 1 | G19: 1 | H19: 1
C20: 全社会用电量 | D20: =D7*$E$17 -> 75214.391 | E20: =E7*$E$17 -> 7521.4391 | F20: =F7*F19 -> 8312.7 | G20: 10090 | H20: 12240 | I20: NA
C21: Total （工商业、不含交通运输、电力热力生产等） | D21: =D8*$E$17 -> 55729.44 | E21: =E8*$E$17 -> 5572.944 | F21: =F8*$E$17 -> 6159.2218 | G21: =SUM(G22:G27) -> 6812.5543 | H21: =SUM(H22:H27) -> 8239.5935 | I21: NA
C22: 重工业 | D22: =#REF!*$E$17 -> #REF! | E22: =E9*$E$17 -> 3287.659 | F22: =F9*$E$17 -> 3633.5231 | G22: =G9*$E$17 -> 3254.9137 | H22: =H9*$E$17 -> 3238.6716 | I22: =911/E22 -> 0.27709686
C23: 轻工业 | D23: =D9*$E$17 -> 32876.59 | E23: =E10*$E$17 -> 743.06404 | F23: =F10*$E$17 -> 821.23492 | G23: =G10*$E$17 -> 1143.2961 | H23: =H10*$E$17 -> 1529.9881 | I23: =215/E23 -> 0.28934249
C24: 公共建筑 | D24: =D10*$E$17 -> 7430.6404 | E24: =E11*$E$17 -> 856.23805 | F24: =F11*$E$17 -> 946.31491 | G24: =G11*$E$17 -> 1092.8008 | H24: =H11*$E$17 -> 1394.7216 | I24: =(H24/E24)^(1/10)-1 -> 0.05
C25: 商业建筑 | D25: =D11*$E$17 -> 8562.3805 | E25: =E12*$E$17 -> 470.04293 | F25: =F12*$E$17 -> 519.49179 | G25: =G12*$E$17 -> 757.00884 | H25: =H12*$E$17 -> 1013.0486 | I25: 0.15
C26: 数据中心 | D26: =D12*$E$17 -> 4700.4293 | E26: =E13*$E$17 -> 204.3 | F26: =F13*$E$17 -> 225.79251 | G26: =G13*$E$17 -> 487.53205 | H26: =H13*$E$17 -> 785.17525 | I26: 0.716
C27: 电动出行 (充换电) | D27: =D14*$E$17 -> 116.4 | E27: =E14*$E$17 -> 11.64 | F27: =F14*$E$17 -> 21.79429 | G27: =G14*$E$17 -> 77.002785 | H27: =H14*$E$17 -> 277.98839 | I27: 0.79

Sheet 用电量-工业
A1: 类别 | D1: 纵轴：市场潜力
D2: 市场规模（单位：亿千瓦时）
A3: 行业 | B3: 重工业 | C3: Total | D3: =D4+D8+D11+D16+SUM(D21:D36) -> 32876.59
C4: 有色金属冶炼及压延加工业 | D4: 6642.6004
C5: 其中:铝冶炼 | D5: 5266.8985
C6: 铅锌冶炼 | D6: 184.0725
C7: 稀有稀土金属冶炼 | D7: 80.8843
C8: 黑色金属矿冶炼及压延加工业 | D8: 5949.9543
C9: 其中:__钢铁 | D9: 4206.8146
C10: __ 铁合金冶炼 | D10: 1644.3819
C11: 化学原料和化学制品制造业 | D11: 4783.9282
C12: 其中:__氯碱 | D12: 559.1446
C13: __电石 | D13: 897.2083
C14: __黄磷 | D14: 121.8996
C15: __肥料制造 | D15: 723.1773
... C36: 其它采矿活动 | D36: 161.7055
B37: 轻工业 | C37: Total | D37: =SUM(D38:D52) -> 7430.6404
C38: 纺织业 | D38: 1546.1442
C39: 计算机、通信和其他电子设备制造业 | D39: 1825.0708
C40: 造纸和纸制品业 | D40: 798.2513
C41: 农副食品加工 | D41: 693.8324
C42: 其他制造业 | D42: 552.6412
C43: 纺织服装、服饰业 | D43: 326.2436
C44: 食品制造业 | D44: 411.1613
C45: 木材加工和木、竹、藤、棕、草制品业 | D45: 356.0435
C46: 皮革、毛皮、羽毛及其制品和制鞋业 | D46: 200.0444
C47: 文教、工美、体育和娱乐用品制造业 | D47: 154.0847
C48: 家具制造业 | D48: 169.9242
C49: 酒、饮料及精制茶制造业 | D49: 149.265
... C52: 烟草制品业 | D52: 37.1766

Sheet 01Bottom-Up
B2: 用户侧储能市场规模汇总
C3: 2016 | D3: 2017 | E3: 2018 | F3: 2019 | G3: 2020 | H3: 2021 | I3: 2022F | J3: 2023F | K3: 2024F | L3: 2025F
B4: 理论市场空间Total(GW) | C4: =C29+C65+C83 -> 52.846619 | D4: =D29+D65+D83 -> 53.221014 | E4: =E29+E65+E83 -> 53.768206 | F4: =F29+F65+F83 -> 54.139828 | G4: =G29+G65+G83 -> 55.07821 | H4: =H29+H65+H83 -> 56.618417 | I4: =I29+I65+I83 -> 57.951214 | J4: =J29+J65+J83 -> 59.68345 | ... L4: =L29+L65+L83 -> 64.940909
A5: Best | B5: 储能总功率（GW）累计-协会公布 | C5: =D5-D6 -> 0.39348035 | D5: =E5-E6 -> 0.46458035 | E5: =F5-F6 -> 0.75788035 | F5: =G5-G6 -> 1.0357804 | G5: =H5-H6 -> 1.3638804 | H5: =11.4/(1+58.8%)^4 -> 1.7926804 | I5: =H5*(1+58.8%) -> 2.8467764 | J5: =I5*(1+58.8%) -> 4.5206809 | K5: =J5*(1+58.8%) -> 7.1788413 | L5: 11.4
A6: Best | B6: 储能总功率（GW）新增-协会公布 | C6: 0.0543 | D6: 0.0711 | E6: 0.2933 | F6: 0.2779 | G6: 0.3281 | H6: 0.4288 | I6: =I5-H5 -> 1.054096 | J6: =J5-I5 -> 1.6739045 | K6: =K5-J5 -> 2.6581604 | L6: =L5-K5 -> 4.2211587
A7: Base | B7: 储能总功率（GW）累计-Bottom-Up | C7: =C31+C49+C67+C85+C103 -> 0.055015432 | D7: =D31+D49+D67+D85+D103 -> 0.093252183 | E7: =E31+E49+E67+E85+E103 -> 0.2103676 | F7: =F31+F49+F67+F85+F103 -> 0.44003412 | G7: =G31+G49+G67+G85+G103 -> 0.692473 | H7: =H31+H49+H67+H85+H103 -> 0.99488431 | I7: =I31+I49+I67+I85+I103 -> 1.6233614 | J7: =J31+J49+J67+J85+J103 -> 2.8751813 | ... L7: =L31+L49+L67+L85+L103 -> 6.606158
A8: Base | B8: 储能总功率（GW）新增-Bottom-Up | C8: =SUM(C33,C51,C69,C87,C105) -> 0.0201 | D8: =D7-C7 -> 0.038236751 | E8: =E7-D7 -> 0.11711541 | F8: =F7-E7 -> 0.22966652 | G8: =G7-F7 -> 0.25243888 | H8: =H7-G7 -> 0.3024113 | I8: =I7-H7 -> 0.6284771 | J8: =J7-I7 -> 1.2518199 | K8: =K7-J7 -> 1.6643526 | L8: =L7-K7 -> 2.066624
B9: EPC成本（元/Wh) | C9: 2.2 | D9: 2.2 | E9: 2.2 | F9: 2.2 | G9: 2.2 | H9: 2.2 | I9: =$H$9*0.9 -> 1.98 | J9: =$H$9*0.82 -> 1.804 | K9: =$H$9*0.79 -> 1.738 | L9: =H9*(1-30%) -> 1.54
B10: 储能系统配置（h） | C10: 3 | D10: 3 | E10: 3 | F10: 3 | G10: 3 | H10: 3 | I10: 3 | J10: 3 | K10: 3 | L10: 3
B11: 市场投资金额（Mn RMB） | C11: =C9*C6*C10*1000 -> 358.38 | D11: =D9*D6*D10*1000 -> 469.26 | E11: =E9*E6*E10*1000 -> 1935.78 | F11: =F9*F6*F10*1000 -> 1834.14 | G11: =G9*G6*G10*1000 -> 2165.46 | H11: =H9*H6*H10*1000 -> 2830.08 | I11: =I9*I6*I10*1000 -> 6261.3305 | J11: =J9*J6*J10*1000 -> 9059.1713 | ... L11: =L9*L6*L10*1000 -> 19501.753
B12: 市场投资金额（Bn RMB）-协会公布 | C12: =C11/1000 -> 0.35838 | D12: =D11/1000 -> 0.46926 | E12: =E11/1000 -> 1.93578 | F12: =F11/1000 -> 1.83414 | G12: =G11/1000 -> 2.16546 | H12: =H11/1000 -> 2.83008 | I12: =I11/1000 -> 6.2613305 | J12: =J11/1000 -> 9.0591713 | ... L12: =L11/1000 -> 19.501753
A13: Base | B13: 市场投资金额（Bn RMB）-Bottom-Up | C13: - | D13: =D10*D9*D8 -> 0.25236256 | E13: =E10*E9*E8 -> 0.77296173 | F13: =F10*F9*F8 -> 1.5157991 | G13: =G10*G9*G8 -> 1.6660966 | H13: =H10*H9*H8 -> 1.9959146 | I13: =I10*I9*I8 -> 3.7331539 | J13: =J10*J9*J8 -> 6.7748492 | K13: =K10*K9*K8 -> 8.6779346 | L13: =L10*L9*L8 -> 9.5478031
B14: 储能累计渗透率 | C14: =C7/C4 -> 0.0010410398 | D14: =D7/D4 -> 0.0017521685 | E14: =E7/E4 -> 0.0039124905 | F14: =F7/F4 -> 0.008127734 | G14: =G7/G4 -> 0.01257254 | H14: =H7/H4 -> 0.017571744 | I14: =I7/I4 -> 0.028012552 | J14: =J7/J4 -> 0.048173845 | ... L14: =L7/L4 -> 0.10172568
B15: 储能增长率 | L15: =POWER(L5/H5,1/4)-1 -> 0.588
G18: 20-25CAGR | H18: ='用电量-各行业汇总'!I9 -> -0.002
B19: A类客户-Tier1：大型高耗能行业（重工业）
C20: 2016 | D20: 2017 | E20: 2018 | F20: 2019 | G20: 2020 | H20: 2021 | I20: 2022F | J20: 2023F | K20: 2024F | L20: 2025F
B21: 行业年总用电量（亿kWh） | C21: =D21*(1-$H18) -> 33140.393 | D21: =E21*(1-$H18) -> 33074.245 | E21: =F21*(1-$H18) -> 33008.228 | F21: =G21*(1-$H18) -> 32942.343 | G21: ='用电量-各行业汇总'!D9 -> 32876.59 | H21: =G21*(1+$H18) -> 32810.837 | I21: =H21*(1+$H18) -> 32745.215 | J21: =I21*(1+$H18) -> 32679.725 | K21: =J21*(1+$H18) -> 32614.365 | L21: ='用电量-各行业汇总'!G9*10 -> 32549.137
B22: 年工作天数（日） | C22: 360 | D22: 360 | E22: 360 | F22: 360 | G22: 360 | H22: 360 | I22: 360 | J22: 360 | K22: 360 | L22: 360
B23: 日工作小时数（h） | C23: 24 | D23: 24 | E23: 24 | F23: 24 | G23: 24 | H23: 24 | I23: 24 | J23: 24 | K23: 24 | L23: 24
B24: 2021年总运行负荷（亿kw） | C24: =C21/C22/C23 -> 3.8356936 | D24: =D21/D22/D23 -> 3.8280376 | E24: =E21/E22/E23 -> 3.8203968 | F24: =F21/F22/F23 -> 3.8127712 | G24: =G21/G22/G23 -> 3.8051609 | H24: =H21/H22/H23 -> 3.7975506 | I24: =I21/I22/I23 -> 3.7899555 | J24: =J21/J22/J23 -> 3.7823756 | ... L24: =L21/L22/L23 -> 3.7672612
B25: 总负荷运行比例（%） | C25: 0.7 | D25: 0.7 | E25: 0.7 | F25: 0.7 | G25: 0.7 | H25: 0.7 | I25: 0.7 | J25: 0.7 | K25: 0.7 | L25: 0.7
B26: 2021年总负荷（亿kw） | C26: =C24/C25 -> 5.4795623 | D26: =D24/D25 -> 5.4686251 | E26: =E24/E25 -> 5.4577097 | F26: =F24/F25 -> 5.446816 | G26: =G24/G25 -> 5.4359441 | H26: =H24/H25 -> 5.4250723 | I26: =I24/I25 -> 5.4142221 | J26: =J24/J25 -> 5.4033937 | ... L26: =L24/L25 -> 5.3818017
B27: 变压器总余量（亿kw） | C27: =C26-C24 -> 1.6438687 | D27: =D26-D24 -> 1.6405875 | E27: =E26-E24 -> 1.6373129 | F27: =F26-F24 -> 1.6340448 | G27: =G26-G24 -> 1.6307832 | H27: =H26-H24 -> 1.6275217 | I27: =I26-I24 -> 1.6242666 | J27: =J26-J24 -> 1.6210181 | ... L27: =L26-L24 -> 1.6145405
B28: 储能功率占比（%） | C28: 0.3 | D28: 0.3 | E28: 0.3 | F28: 0.3 | G28: 0.3 | H28: 0.3 | I28: 0.3 | J28: 0.3 | K28: 0.3 | L28: 0.3
B29: 储能理论市场总功率（GW） | C29: =C28*C27*100000000/1000000 -> 49.316061 | D29: =D28*D27*100000000/1000000 -> 49.217626 | E29: =E28*E27*100000000/1000000 -> 49.119387 | F29: =F28*F27*100000000/1000000 -> 49.021344 | G29: =G28*G27*100000000/1000000 -> 48.923497 | H29: =H28*H27*100000000/1000000 -> 48.82565 | I29: =I28*I27*100000000/1000000 -> 48.727999 | J29: =J28*J27*100000000/1000000 -> 48.630543 | ... L29: =L28*L27*100000000/1000000 -> 48.436215
B30: 储能累计渗透率 | C30: 0.001 | D30: 0.0015 | E30: 0.003 | F30: 0.0059 | G30: 0.0089 | H30: 0.0124 | I30: 0.0193 | J30: 0.033 | K30: 0.0505 | L30: 0.071
B31: 储能总功率（GW）累计 | C31: =C30*C29 -> 0.049316061 | D31: =D30*D29 -> 0.073826439 | E31: =E30*E29 -> 0.14735816 | F31: =F30*F29 -> 0.28922593 | G31: =G30*G29 -> 0.43541913 | H31: =H30*H29 -> 0.60543806 | I31: =I30*I29 -> 0.94045038 | J31: =J30*J29 -> 1.6048079 | ... L31: =L30*L29 -> 3.4389713
B32: 累计总功率市场占比 | C32: =C31/C$7 -> 0.89640414 | D32: =D31/D$7 -> 0.7916859 | E32: =E31/E$7 -> 0.70047937 | F32: =F31/F$7 -> 0.65728069 | G32: =G31/G$7 -> 0.62878859 | H32: =H31/H$7 -> 0.60855122 | I32: =I31/I$7 -> 0.57932287 | J32: =J31/J$7 -> 0.55815886 | ... L32: =L31/L$7 -> 0.52057055
B33: 储能总功率（GW）新增 | C33: 0.01 | D33: =D31-C31 -> 0.024510378 | E33: =E31-D31 -> 0.073531722 | F33: =F31-E31 -> 0.14186777 | G33: =G31-F31 -> 0.14619319 | H33: =H31-G31 -> 0.17001894 | I33: =I31-H31 -> 0.33501232 | J33: =J31-I31 -> 0.66435754 | K33: =K31-J31 -> 0.84612282 | L33: =L31-K31 -> 0.98804055
B34: 新增总功率市场占比 | C34: - | D34: =D33/D$8 -> 0.64101622 | E34: =E33/E$8 -> 0.62785692 | F34: =F33/F$8 -> 0.61771201 | G34: =G33/G$8 -> 0.57912312 | H34: =H33/H$8 -> 0.56221092 | I34: =I33/I$8 -> 0.53305414 | J34: =J33/J$8 -> 0.53071336 | K34: =K33/K$8 -> 0.50837954 | L34: =L33/L$8 -> 0.478094
C35: -
G36: 20-25CAGR | H36: =POWER(L39/G39,1/5)-1 -> 0.095014176
B37: A类客户-Tier2&3：商建、一般制造业（含除纺织造纸外所有轻工业）
C38: 2016 | D38: 2017 | E38: 2018 | F38: 2019 | G38: 2020 | H38: 2021 | I38: 2022F | J38: 2023F | K38: 2024F | L38: 2025F
B39: 行业年总用电量（亿kWh） | C39: =D39*(1-$H36) -> 6345.6777 | D39: =E39*(1-$H36) -> 7011.9084 | E39: =F39*(1-$H36) -> 7748.0864 | F39: =G39*(1-$H36) -> 8561.5556 | G39: ='用电量-各行业汇总'!D12+'用电量-各行业汇总'!D10-'01Bottom-Up'!G75 -> 9460.4306 | H39: =G39*(1+$H36) -> 10359.306 | I39: =H39*(1+$H36) -> 11343.586 | J39: =I39*(1+$H36) -> 12421.388 | K39: =J39*(1+$H36) -> 13601.596 | L39: ='用电量-各行业汇总'!G12*10+'用电量-各行业汇总'!G10*10-'01Bottom-Up'!L75 -> 14893.94
B40: 年工作天数（日） | C40: 300 | D40: 300 | E40: 300 | F40: 300 | G40: 300 | H40: 300 | I40: 300 | J40: 300 | K40: 300 | L40: 300
B41: 日工作小时数（h） | C41: 10 | D41: 10 | E41: 10 | F41: 10 | G41: 10 | H41: 10 | I41: 10 | J41: 10 | K41: 10 | L41: 10
B42: 2021年总运行负荷（亿kw） | C42: =C39/C40/C41 -> 2.1152259 | D42: =D39/D40/D41 -> 2.3373028 | E42: =E39/E40/E41 -> 2.5826955 | F42: =F39/F40/F41 -> 2.8538519 | G42: =G39/G40/G41 -> 3.1534769 | H42: =H39/H40/H41 -> 3.4531019 | I42: =I39/I40/I41 -> 3.7811955 | J42: =J39/J40/J41 -> 4.1404627 | ... L42: =L39/L40/L41 -> 4.9646468
B43: 总负荷运行比例（%） | C43: 0.7 | D43: 0.7 | E43: 0.7 | F43: 0.7 | G43: 0.7 | H43: 0.7 | I43: 0.7 | J43: 0.7 | K43: 0.7 | L43: 0.7
...

Sheet 02Top-Down
B1: xxx | C1: 引用数据
B2: xxx | C2: 假设/访谈数据
B3: xxx | C3: 计算数据
B6: 汇总
B7: No. | C7: 企业名称 | D7: 2021年总营收（元） | E7: 2021年储能系统集成营收 | F7: 2021年储能系统集成营收占比（%） | G7: 2021年储能业务毛利率 | H7: 2021年储能新增装机（MWh） | I7: >>>Comments
B8: 1 | C8: 海博思创 | D8: 1000000000 | E8: 1000000000 | F8: =E8/D8 -> 1 | G8: 0.2 | H8: 1300 | I8: 略小于协会公布数字
B9: 4 | C9: 采日能源 | D9: 1000000000 | E9: 1000000000 | F9: =E9/D9 -> 1 | G9: <5% | H9: 400 | I9: 远大于协会公布数字；部分参与储能业务的子公司财务信息未并表；储能业务实际营收近10亿元
B10: 2 | C10: 科华数能 | D10: 800000000 | E10: 250000000 | F10: =E10/D10 -> 0.3125 | G10: 0.24 | H10: 250 | I10: 部分子公司未并表；储能业务（含交流侧系统集成）实际总营收近8亿元，其中直流侧占比~30%
B11: 6 | C11: 库博能源 | D11: 150000000 | E11: 150000000 | F11: =E11/D11 -> 1 | G11: 0.25 | H11: 150 | I11: /
B12: 3 | C12: 奇点能源 | D12: 23000000 | E12: 23000000 | F12: =E12/D12 -> 1 | G12: 0.2 | H12: 15 | I12: /
B13: 5 | C13: 智光储能 | D13: 122620000 | E13: 122620000 | F13: =E13/D13 -> 1 | G13: 0.51 | H13: 80 | I13: /
B14: 7 | C14: 储能在线 | D14: 1500000 | E14: 1500000 | F14: =E14/D14 -> 1 | G14: 0.07 | H14: 1 | I14: 尚未实现规模化投产，仅有样品试制装配线；目前业务营收主要来自于储能系统集成设备及储能液冷组件销售
B15: 8 | C15: 南京四象 | D15: 5120000 | E15: 5120000 | F15: =E15/D15 -> 1 | G15: 0.09 | H15: 3 | I15: /
H16: ↓：按照功率计算
B17: 9 | C17: 盛弘股份 | D17: 1.0213849e+09 | E17: 110000000 | F17: =E17/D17 -> 0.10769691 | G17: 0.3616 | H17: 170 | I17: 储能相关业务以PCS等设备供应及交流侧系统集成为主
B18: 10 | C18: 美克生 | D18: 100000000 | E18: 1000000 | F18: =E18/D18 -> 0.01 | G18: <0% | H18: 300 | I18: 按照PSS运维系统接入量功率计算；公司实际主营为电动出行-小动力电池供应
B19: 注：由于存在往年回款和应收账款情况，年营业收入数据与新增装机数据无简单逻辑关系
B22: 用户侧 | F22: ↓：根据Bottom-Up测算数据，八家访谈企业共占据用户侧市场份额约60%
B23: No. | C23: 企业名称 | D23: 2021年用户侧新增装机（MWh） | E23: 用户侧装机占比（%） | F23: 用户侧市场份额（%） | G23: KSF/GTM | I23: 战略布局/未来展望
B24: 1 | C24: 海博思创 | D24: 70 | E24: =D24/H8 -> 0.053846154 | F24: =D24/('[3]用户侧市场测算-分行业'!$H$8*3*1000) -> 0.086698893 | G24: KSF: 1. 定位聚焦，专注系统集成环节；2. 上游控制力强、质量高、供应链稳定；3. 集成端能力已形成壁垒；4.表前资源丰富 | I24: 战略布局：1. 强化源网侧资源；2. 开发用户侧优质客户；3. 登陆资本市场；4. 对新兴电池技术保持观望
B25: 4 | C25: 采日能源 | D25: 80 | E25: =D25/H9 -> 0.2 | F25: =D25/('[3]用户侧市场测算-分行业'!$H$8*3*1000) -> 0.099084449 | G25: KSF: 1. 市场进入路线清晰；2. 供应链管理能力强；3. 表后优质客户开发能力强 | I25: 战略布局：1. 有限参与表后市场；2. 储能即服务
B26: 2 | C26: 科华数能 | D26: 10 | E26: =D26/H10 -> 0.04 | F26: =D26/('[3]用户侧市场测算-分行业'!$H$8*3*1000) -> 0.012385556 | G26: KSF:1. 交流侧带动直流侧 | I26: 战略布局：1. 新能源业务协同发展；2. 扩大表前业务体量为首要目标；3. 有限参与表后市场；4. 在数据中心细分场景以观察为主
B27: 6 | C27: 库博能源 | D27: 130 | E27: =D27/H11 -> 0.86666667 | F27: =D27/('[3]用户侧市场测算-分行业'!$H$8*3*1000) -> 0.16101223 | G27: KSF: 1. 供应链稳定、成本低；2. 业务开放程度高；3. 自身定位前后一贯、发力持续 | I27: 战略布局：1. 未来持续深耕用户侧储能市场
B28: 3 | C28: 奇点能源 | D28: 15 | E28: =D28/H12 -> 1 | F28: =D28/('[3]用户侧市场测算-分行业'!$H$8*3*1000) -> 0.018578334 | G28: KSF: 1. 内置能力齐全、产品标准化程度搞；2. 具备一定政府公关能力；3. 利用综合能源服务公司获取用户侧资源 | I28: 战略布局：1. 探索源网侧机会；2. 保持分布式技术路线
B29: 5 | C29: 智光储能 | D29: 15 | E29: =D29/H13 -> 0.1875 | F29: =D29/('[3]用户侧市场测算-分行业'!$H$8*3*1000) -> 0.018578334 | G29: KSF: 1. 技术积累丰富；2.善于利用公司所在地区资源优势 | I29: 战略布局：1. 提高用户侧产品标准化水平；2. 进一步推广高压级联型储能技术方案
B30: 7 | C30: 储能在线 | D30: 1 | E30: =D30/H14 -> 1 | F30: =D30/('[3]用户侧市场测算-分行业'!$H$8*3*1000) -> 0.0012385556 | G30: / | I30: 战略布局：1. 未来发力细分为商业建筑与特殊安全需求场合用户；2. 将寻求更多资本支持与项目资源
B31: 8 | C31: 南京四象 | D31: 3 | E31: =D31/H15 -> 1 | F31: =D31/('[3]用户侧市场测算-分行业'!$H$8*3*1000) -> 0.0037156668 | G31: / | I31: 未来展望：公司核心团队近期有所调整，在分布式储能标准化的路线坚持上有所变化；未来为追求扩大装机规模，将寻求定制化大型储能项目机会
D32: ↓：按照功率计算
B33: 9 | C33: 盛弘股份 | D33: 60 | E33: =D33/H17 -> 0.35294118 | F33: =D33/('[3]用户侧市场测算-分行业'!$H$8*2*1000) -> 0.11147001 | G33: KSF: 1. 自身生态定位明确，核心业务增长稳定 | I33: 战略布局：1. 保证交流侧相对优势，避免向上下游过度延伸
B34: 10 | C34: 美克生 | D34: 50 | E34: =D34/H18 -> 0.16666667 | F34: =D34/('[3]用户侧市场测算-分行业'!$H$8*2*1000) -> 0.092891671 | G34: / | I34: 未来展望：目前公司正在积极开发“绿电来OS”平台，现有PSS可作为功能模块置入；未来可通过模块开发来实现部分VPP的功能；PSS本身具有与储能系统集成商合作、通过Spec-In方式成为生态玩家的可能性；但该参与方式取决于高层想法
B35: 注：用户侧市场份额按照Bottom-up测算方法所得数据、0.5C充放倍率计算

Sheet 03分布式配储
B2: 待明确问题：1、哪；2、配比比例；3、强配储能目的；4、落地情况；5、发展趋势
B4: 备注：截至目前，全国共7地对分布式配储提出明确要求
B5: 序号 | C5: 省份 | D5: 区域 | E5: 分布式配储比例 | F5: 时长 | G5: 配储目的 | H5: 时间 | I5: 发布方 | J5: 要求 | K5: 是否有补贴 | L5: 规模 | M5: 政策 | N5: 来源
B6: =ROW()-5 -> 1 | C6: 浙江 | D6: 诸暨 | E6: 0.1 | G6: 提高光伏发电电网消纳能力 | H6: 44713 | I6: 市政府 | J6: 实施整市推进分布式光伏规模化开发四大工程，分布式光伏开发的同时，按不低于光伏装机容量10%的要求总体配套建设光伏储能设施容量。 | K6: 新增新型储能设施补贴。“十四五”期间，为提高光伏发电电网消纳能力，在我市建设新型储能设施的，市财政按每千瓦时200元给予储能设施投资单位一次性补贴。允许新型储能设施投资企业按市场化运营方式向光伏投资企业租售储能容量，租售的储能容量可计算在光伏投资企业光伏装机容量10%的总体配套储能容量中。 | L6: 第一阶段：部分推进。2022年底，年度新增分布式光伏电站200兆瓦以上，全市累计并网总规模达到350兆瓦以上，新批储能容量达到20兆瓦/40兆瓦时以上。 第二阶段：全面推进。2023年起，在全市范围深入推广，2025年底前完成全市分布式光伏电站总规模达到500兆瓦及以上，新批储能容量达到30兆瓦/60兆瓦时及以上。 | M6: 《诸暨市整市推进分布式光伏规模化开发工作方案》 | N6: https://mp.weixin.qq.com/s/8oWb4RhGS3hP3uHfLVBToA
B7: =ROW()-5 -> 2 | C7: 浙江 | D7: 永康 | E7: 0.1 | G7: 主动削峰填谷，优化区域电网负荷 | H7: 44682 | I7: 市发改局 | J7: 积极推进用户侧储能建设。鼓励非户用分布式光伏电站按照发电装机容量10%建设储能设施，充分利用目录分时电价机制，主动削峰填谷，优化区域电网负荷需求。推动储能应用与电网协同发展，充分发挥灵活、可调性储能资源在新型电力系统中的平衡作用 | K7: 设立专项资金，对2022年1月1日至2024年12月31日期间建成的屋顶分布式光伏发电项目、非居民用户侧储能项目给予财政补助； 对非居民用户侧储能项目（年利用小时数不低于600小时），按照储能设施的功率给予补助，补助标准按150元、120元、100元/千瓦逐年退坡（省补助标准：调峰项目按200元、180元、170元/千瓦退坡，补助期三年），已享受省级补助的项目不再重复补助 | M7: 《永康市整市屋顶分布式光伏开发试点实施方案》 公开征求意见的公告 | N7: https://news.bjx.com.cn/html/20220517/1225686.shtml
B8: =ROW()-5 -> 3 | C8: 浙江 | D8: 绍兴市 柯桥区 | E8: 0.1 | F8: 2 | G8: 为电力系统提供一定的容量支撑和调节能力 | H8: 44531 | I8: 区发改局 | J8: 建议非户用分布式光伏电站全生命周期内，按照发电装机容量的10%建设储能设施，储能设施存储时长需在2小时及以上，为电力系统提供一定的容量支撑和调节能力 | K8: 2021-2025年在柯桥区建设非户用分布式光伏项目配套储能设施的，在项目通过柯桥供电分局验收后，对项目业主按每千瓦时储能能力100元发放一次性补助。 | M8: 《关于柯桥区整区屋顶分布式光伏开发试点实施方案的公示》 | N8: http://www.kq.gov.cn/art/2021/12/16/art_1229404720_3900987.html
B9: =ROW()-5 -> 4 | C9: 山东 | D9: 枣庄市 | E9: 15%-30% | F9: 2-4 | H9: 44501 | I9: 市能源局 | J9: 规定分布式光伏项目按照装机容量的15%-30%、时长2-4小时配置储能设施，或者租赁同等容量的共享储能设施； | K9: N/A | M9: 《枣庄市分布式光伏建设规范（试行）》 | N9: https://news.solarbe.com/202201/20/350226.html
B10: =ROW()-5 -> 5 | C10: 江苏 | D10: 昆山 | E10: 0.08 | F10: N/A | H10: 44743 | I10: 市政府 | J10: 鼓励装机容量2兆瓦及以上的分布式光伏发电项目，按照不低于装机容量8%的比例配建储能系统，储能系统作为分布式光伏发电项目组成部分一并办理备案 | K10: N/A | M10: 《加快推进分布式光伏发电项目开发建设的工作意见》 | N10: https://mp.weixin.qq.com/s/7s6b0h0guii6ukIo6ik-xQ
B11: =ROW()-5 -> 6 | C11: 江苏 | D11: 苏州 | E11: 0.08 | H11: 44682 | I11: 市政府 | J11: 2MW以上的分布式光伏，按不低于装机容量的8%配置储能，鼓励装机容量2兆瓦以上的光伏项目，按照不低于装机容量8%的比例配建储能系统。 | K11: N/A | M11: 《关于加快推进全市光伏发电开发利用的工作意见》 | N11: https://www.suzhou.gov.cn/szsrmzf/szyw/202205/f31cc437106344738a7b87d40a09acdd.shtml
B12: =ROW()-5 -> 7 | C12: 河北 | D12: 全省 | H12: 44621 | I12: 省能源局 | J12: 屋顶分布式光伏项目逐步按照“光伏+储能”方式开发建设，可选择自建、共建或租赁等方式灵活开展配套储能建设，配套储能装置应满足10年（5000次循环）以上工作寿命，系统容量10年衰减率不超过 20%。 | M12: 《屋顶分布式光伏建设指导规范（试行）》 | N12: https://new.qq.com/omn/20220326/20220326A003DB00.html | O12: http://nyj.zaozhuang.gov.cn/zcfg/xny/202201/t20220114_1378879.html

Sheet 03 Cross-Check 现货电量
C1: =C4/C3 -> 0 | D1: =D4/D3 -> 1.5702301 | E1: =E4/E3 -> 5.4416749
B2: 用户侧储能市场规模
C3: 2021 | D3: 2025 | E3: 2030
B4: 现货交易电量（亿千瓦时） | D4: 3179.716 | E4: 11046.6
B5: 峰谷电量占20%（亿千瓦时） | D5: =20%*D4 -> 635.9432 | E5: =20%*E4 -> 2209.32
B6: 峰谷差价 | D6: 0.4 | E6: 0.6
B7: 储能套利市场盈利空间（M RMB) | D7: =D5*D6*100 -> 25437.728 | E7: =E5*E6*100 -> 132559.2
B8: 用户侧储能应用渗透率 | D8: 0.15 | E8: 0.2
B9: 营收(m rnb) | C9: 490 | D9: =3241.45805825243 -> 3241.4581 | E9: 15014.796
B10: 用户侧储能年平均充电时长度（h） | D10: 721 | E10: 721 | F10: 用户侧一个标准的储能配置：1. 装机容量：4800kWh；2. 年充电量：3462099kWh（一年350天，每天两充两放)；3. 平均年充电时长=3462099/4800=721小时
B11: 用户侧储能系统的累计装机容量（kwh） | D11: =D5*D8*100000000/D10 -> 13230441 | E11: =E5*E8*100000000/E10 -> 61284882
B12: 储能电池容量时长 | D12: 2 | E12: 2
B13: 储能电池装机累计装机规模(MW) | C13: 1000 | D13: =D11/D12/1000 -> 6615.2205 | E13: =E11/E12/1000 -> 30642.441
E15: =30/200 -> 0.15
C20: 2021 | D20: 2025 | E20: 2030
B21: 装机容量（MWh） | C21: 1000
B32: 安徽省35kv一般工商业用户电价
B33: 峰价（元/KWh) | C33: 1.06
B34: 平价（元/KWh) | C34: 0.67
B35: 谷价（元/KWh) | C35: 0.36
B36: 基于用户侧两充两放（一平一峰、一谷一峰）Base模型，计算出年均放电量*峰谷价差
